2019-01-09 14:15:51.944348
2019-01-10 12:46:18.416300
2019-01-10 12:49:49.399874
2019-01-10 12:54:25.051163
Traceback (most recent call last):
  File "/Library/Frameworks/Python.framework/Versions/3.6/lib/python3.6/site-packages/urllib3/connection.py", line 141, in _new_conn
    (self.host, self.port), self.timeout, **extra_kw)
  File "/Library/Frameworks/Python.framework/Versions/3.6/lib/python3.6/site-packages/urllib3/util/connection.py", line 60, in create_connection
    for res in socket.getaddrinfo(host, port, family, socket.SOCK_STREAM):
  File "/Library/Frameworks/Python.framework/Versions/3.6/lib/python3.6/socket.py", line 745, in getaddrinfo
    for res in _socket.getaddrinfo(host, port, family, type, proto, flags):
socket.gaierror: [Errno 8] nodename nor servname provided, or not known

During handling of the above exception, another exception occurred:

Traceback (most recent call last):
  File "/Library/Frameworks/Python.framework/Versions/3.6/lib/python3.6/site-packages/urllib3/connectionpool.py", line 601, in urlopen
    chunked=chunked)
  File "/Library/Frameworks/Python.framework/Versions/3.6/lib/python3.6/site-packages/urllib3/connectionpool.py", line 346, in _make_request
    self._validate_conn(conn)
  File "/Library/Frameworks/Python.framework/Versions/3.6/lib/python3.6/site-packages/urllib3/connectionpool.py", line 850, in _validate_conn
    conn.connect()
  File "/Library/Frameworks/Python.framework/Versions/3.6/lib/python3.6/site-packages/urllib3/connection.py", line 284, in connect
    conn = self._new_conn()
  File "/Library/Frameworks/Python.framework/Versions/3.6/lib/python3.6/site-packages/urllib3/connection.py", line 150, in _new_conn
    self, "Failed to establish a new connection: %s" % e)
urllib3.exceptions.NewConnectionError: <urllib3.connection.VerifiedHTTPSConnection object at 0x10e64b7f0>: Failed to establish a new connection: [Errno 8] nodename nor servname provided, or not known

During handling of the above exception, another exception occurred:

Traceback (most recent call last):
  File "/Library/Frameworks/Python.framework/Versions/3.6/lib/python3.6/site-packages/requests/adapters.py", line 440, in send
    timeout=timeout
  File "/Library/Frameworks/Python.framework/Versions/3.6/lib/python3.6/site-packages/urllib3/connectionpool.py", line 639, in urlopen
    _stacktrace=sys.exc_info()[2])
  File "/Library/Frameworks/Python.framework/Versions/3.6/lib/python3.6/site-packages/urllib3/util/retry.py", line 388, in increment
    raise MaxRetryError(_pool, url, error or ResponseError(cause))
urllib3.exceptions.MaxRetryError: HTTPSConnectionPool(host='api.dropboxapi.com', port=443): Max retries exceeded with url: /2/users/get_current_account (Caused by NewConnectionError('<urllib3.connection.VerifiedHTTPSConnection object at 0x10e64b7f0>: Failed to establish a new connection: [Errno 8] nodename nor servname provided, or not known',))

During handling of the above exception, another exception occurred:

Traceback (most recent call last):
  File "/Users/hepting/Sites/dhhepting.github.io/script/sharemedia.py", line 53, in <module>
    dbx.users_get_current_account()
  File "/Library/Frameworks/Python.framework/Versions/3.6/lib/python3.6/site-packages/dropbox/base.py", line 4301, in users_get_current_account
    None,
  File "/Library/Frameworks/Python.framework/Versions/3.6/lib/python3.6/site-packages/dropbox/dropbox.py", line 272, in request
    timeout=timeout)
  File "/Library/Frameworks/Python.framework/Versions/3.6/lib/python3.6/site-packages/dropbox/dropbox.py", line 363, in request_json_string_with_retry
    timeout=timeout)
  File "/Library/Frameworks/Python.framework/Versions/3.6/lib/python3.6/site-packages/dropbox/dropbox.py", line 447, in request_json_string
    timeout=timeout,
  File "/Library/Frameworks/Python.framework/Versions/3.6/lib/python3.6/site-packages/requests/sessions.py", line 555, in post
    return self.request('POST', url, data=data, json=json, **kwargs)
  File "/Library/Frameworks/Python.framework/Versions/3.6/lib/python3.6/site-packages/requests/sessions.py", line 508, in request
    resp = self.send(prep, **send_kwargs)
  File "/Library/Frameworks/Python.framework/Versions/3.6/lib/python3.6/site-packages/requests/sessions.py", line 618, in send
    r = adapter.send(request, **kwargs)
  File "/Library/Frameworks/Python.framework/Versions/3.6/lib/python3.6/site-packages/requests/adapters.py", line 508, in send
    raise ConnectionError(e, request=request)
requests.exceptions.ConnectionError: HTTPSConnectionPool(host='api.dropboxapi.com', port=443): Max retries exceeded with url: /2/users/get_current_account (Caused by NewConnectionError('<urllib3.connection.VerifiedHTTPSConnection object at 0x10e64b7f0>: Failed to establish a new connection: [Errno 8] nodename nor servname provided, or not known',))
2019-01-10 12:56:14.839163
2019-01-14 00:03:32.645806
2019-01-14 00:05:11.112143
2019-01-14 00:05:24.325439
2019-01-14 00:10:59.796218
2019-01-14 23:45:55.751115
2019-01-14 23:46:11.034947
2019-01-17 12:46:41.248620
2019-01-17 12:47:12.876528
2019-01-17 14:07:09.685086
2019-01-18 13:54:11.124701
2019-01-18 13:56:28.987150
2019-01-21 11:03:03.091744
Traceback (most recent call last):
  File "/Library/Frameworks/Python.framework/Versions/3.6/lib/python3.6/site-packages/urllib3/connection.py", line 141, in _new_conn
    (self.host, self.port), self.timeout, **extra_kw)
  File "/Library/Frameworks/Python.framework/Versions/3.6/lib/python3.6/site-packages/urllib3/util/connection.py", line 60, in create_connection
    for res in socket.getaddrinfo(host, port, family, socket.SOCK_STREAM):
  File "/Library/Frameworks/Python.framework/Versions/3.6/lib/python3.6/socket.py", line 745, in getaddrinfo
    for res in _socket.getaddrinfo(host, port, family, type, proto, flags):
socket.gaierror: [Errno 8] nodename nor servname provided, or not known

During handling of the above exception, another exception occurred:

Traceback (most recent call last):
  File "/Library/Frameworks/Python.framework/Versions/3.6/lib/python3.6/site-packages/urllib3/connectionpool.py", line 601, in urlopen
    chunked=chunked)
  File "/Library/Frameworks/Python.framework/Versions/3.6/lib/python3.6/site-packages/urllib3/connectionpool.py", line 346, in _make_request
    self._validate_conn(conn)
  File "/Library/Frameworks/Python.framework/Versions/3.6/lib/python3.6/site-packages/urllib3/connectionpool.py", line 850, in _validate_conn
    conn.connect()
  File "/Library/Frameworks/Python.framework/Versions/3.6/lib/python3.6/site-packages/urllib3/connection.py", line 284, in connect
    conn = self._new_conn()
  File "/Library/Frameworks/Python.framework/Versions/3.6/lib/python3.6/site-packages/urllib3/connection.py", line 150, in _new_conn
    self, "Failed to establish a new connection: %s" % e)
urllib3.exceptions.NewConnectionError: <urllib3.connection.VerifiedHTTPSConnection object at 0x10e535940>: Failed to establish a new connection: [Errno 8] nodename nor servname provided, or not known

During handling of the above exception, another exception occurred:

Traceback (most recent call last):
  File "/Library/Frameworks/Python.framework/Versions/3.6/lib/python3.6/site-packages/requests/adapters.py", line 440, in send
    timeout=timeout
  File "/Library/Frameworks/Python.framework/Versions/3.6/lib/python3.6/site-packages/urllib3/connectionpool.py", line 639, in urlopen
    _stacktrace=sys.exc_info()[2])
  File "/Library/Frameworks/Python.framework/Versions/3.6/lib/python3.6/site-packages/urllib3/util/retry.py", line 388, in increment
    raise MaxRetryError(_pool, url, error or ResponseError(cause))
urllib3.exceptions.MaxRetryError: HTTPSConnectionPool(host='api.dropboxapi.com', port=443): Max retries exceeded with url: /2/users/get_current_account (Caused by NewConnectionError('<urllib3.connection.VerifiedHTTPSConnection object at 0x10e535940>: Failed to establish a new connection: [Errno 8] nodename nor servname provided, or not known',))

During handling of the above exception, another exception occurred:

Traceback (most recent call last):
  File "/Users/hepting/Sites/dhhepting.github.io/script/sharemedia.py", line 53, in <module>
    dbx.users_get_current_account()
  File "/Library/Frameworks/Python.framework/Versions/3.6/lib/python3.6/site-packages/dropbox/base.py", line 4301, in users_get_current_account
    None,
  File "/Library/Frameworks/Python.framework/Versions/3.6/lib/python3.6/site-packages/dropbox/dropbox.py", line 272, in request
    timeout=timeout)
  File "/Library/Frameworks/Python.framework/Versions/3.6/lib/python3.6/site-packages/dropbox/dropbox.py", line 363, in request_json_string_with_retry
    timeout=timeout)
  File "/Library/Frameworks/Python.framework/Versions/3.6/lib/python3.6/site-packages/dropbox/dropbox.py", line 447, in request_json_string
    timeout=timeout,
  File "/Library/Frameworks/Python.framework/Versions/3.6/lib/python3.6/site-packages/requests/sessions.py", line 555, in post
    return self.request('POST', url, data=data, json=json, **kwargs)
  File "/Library/Frameworks/Python.framework/Versions/3.6/lib/python3.6/site-packages/requests/sessions.py", line 508, in request
    resp = self.send(prep, **send_kwargs)
  File "/Library/Frameworks/Python.framework/Versions/3.6/lib/python3.6/site-packages/requests/sessions.py", line 618, in send
    r = adapter.send(request, **kwargs)
  File "/Library/Frameworks/Python.framework/Versions/3.6/lib/python3.6/site-packages/requests/adapters.py", line 508, in send
    raise ConnectionError(e, request=request)
requests.exceptions.ConnectionError: HTTPSConnectionPool(host='api.dropboxapi.com', port=443): Max retries exceeded with url: /2/users/get_current_account (Caused by NewConnectionError('<urllib3.connection.VerifiedHTTPSConnection object at 0x10e535940>: Failed to establish a new connection: [Errno 8] nodename nor servname provided, or not known',))
2019-01-22 12:48:13.496561
2019-01-22 12:53:22.258703
2019-01-24 12:57:31.542368
2019-01-24 13:02:09.951029
2019-01-24 13:39:38.046644
2019-01-25 13:56:09.232254
2019-01-25 13:58:20.042544
2019-01-25 14:05:23.043634
2019-01-25 14:06:54.530915
2019-01-28 13:54:06.970427
2019-01-28 14:00:03.349311
2019-01-29 12:51:52.545335
2019-01-29 12:53:51.312524
2019-01-29 14:00:04.555143
2019-01-30 14:00:06.562578
2019-01-31 12:58:46.827381
2019-01-31 13:40:29.363246
2019-01-31 14:00:02.084696
2019-02-02 14:00:04.405418
2019-02-03 21:26:12.781687
2019-02-04 14:00:05.088930
2019-02-05 14:00:10.348709
2019-02-05 15:35:19.089447
2019-02-05 15:40:50.866943
2019-02-05 15:42:19.549004
2019-02-06 14:00:05.249722
2019-02-07 14:00:04.981071
2019-02-08 14:00:06.580753
2019-02-09 00:21:17.452099
2019-02-09 00:25:43.728767
2019-02-09 00:27:16.940787
2019-02-10 09:09:20.622503
2019-02-10 16:41:41.448110
2019-02-11 14:00:06.216574
2019-02-12 14:00:08.125267
2019-02-12 22:53:06.988911
2019-02-12 22:54:13.209272
2019-02-13 14:00:04.582449
2019-02-14 14:00:06.950754
2019-02-14 17:23:07.680570
2019-02-15 14:00:15.530444
2019-02-16 14:48:44.921032
2019-02-17 12:55:20.733455
2019-02-17 14:02:01.768022
2019-02-18 15:36:34.432359
2019-02-19 14:00:10.179160
2019-02-20 14:00:06.154773
2019-02-21 14:11:15.415596
Traceback (most recent call last):
  File "/Library/Frameworks/Python.framework/Versions/3.6/lib/python3.6/site-packages/urllib3/connection.py", line 141, in _new_conn
    (self.host, self.port), self.timeout, **extra_kw)
  File "/Library/Frameworks/Python.framework/Versions/3.6/lib/python3.6/site-packages/urllib3/util/connection.py", line 60, in create_connection
    for res in socket.getaddrinfo(host, port, family, socket.SOCK_STREAM):
  File "/Library/Frameworks/Python.framework/Versions/3.6/lib/python3.6/socket.py", line 745, in getaddrinfo
    for res in _socket.getaddrinfo(host, port, family, type, proto, flags):
socket.gaierror: [Errno 8] nodename nor servname provided, or not known

During handling of the above exception, another exception occurred:

Traceback (most recent call last):
  File "/Library/Frameworks/Python.framework/Versions/3.6/lib/python3.6/site-packages/urllib3/connectionpool.py", line 601, in urlopen
    chunked=chunked)
  File "/Library/Frameworks/Python.framework/Versions/3.6/lib/python3.6/site-packages/urllib3/connectionpool.py", line 346, in _make_request
    self._validate_conn(conn)
  File "/Library/Frameworks/Python.framework/Versions/3.6/lib/python3.6/site-packages/urllib3/connectionpool.py", line 850, in _validate_conn
    conn.connect()
  File "/Library/Frameworks/Python.framework/Versions/3.6/lib/python3.6/site-packages/urllib3/connection.py", line 284, in connect
    conn = self._new_conn()
  File "/Library/Frameworks/Python.framework/Versions/3.6/lib/python3.6/site-packages/urllib3/connection.py", line 150, in _new_conn
    self, "Failed to establish a new connection: %s" % e)
urllib3.exceptions.NewConnectionError: <urllib3.connection.VerifiedHTTPSConnection object at 0x10e532208>: Failed to establish a new connection: [Errno 8] nodename nor servname provided, or not known

During handling of the above exception, another exception occurred:

Traceback (most recent call last):
  File "/Library/Frameworks/Python.framework/Versions/3.6/lib/python3.6/site-packages/requests/adapters.py", line 440, in send
    timeout=timeout
  File "/Library/Frameworks/Python.framework/Versions/3.6/lib/python3.6/site-packages/urllib3/connectionpool.py", line 639, in urlopen
    _stacktrace=sys.exc_info()[2])
  File "/Library/Frameworks/Python.framework/Versions/3.6/lib/python3.6/site-packages/urllib3/util/retry.py", line 388, in increment
    raise MaxRetryError(_pool, url, error or ResponseError(cause))
urllib3.exceptions.MaxRetryError: HTTPSConnectionPool(host='api.dropboxapi.com', port=443): Max retries exceeded with url: /2/users/get_current_account (Caused by NewConnectionError('<urllib3.connection.VerifiedHTTPSConnection object at 0x10e532208>: Failed to establish a new connection: [Errno 8] nodename nor servname provided, or not known',))

During handling of the above exception, another exception occurred:

Traceback (most recent call last):
  File "/Users/hepting/Sites/dhhepting.github.io/script/sharemedia.py", line 53, in <module>
    dbx.users_get_current_account()
  File "/Library/Frameworks/Python.framework/Versions/3.6/lib/python3.6/site-packages/dropbox/base.py", line 4301, in users_get_current_account
    None,
  File "/Library/Frameworks/Python.framework/Versions/3.6/lib/python3.6/site-packages/dropbox/dropbox.py", line 272, in request
    timeout=timeout)
  File "/Library/Frameworks/Python.framework/Versions/3.6/lib/python3.6/site-packages/dropbox/dropbox.py", line 363, in request_json_string_with_retry
    timeout=timeout)
  File "/Library/Frameworks/Python.framework/Versions/3.6/lib/python3.6/site-packages/dropbox/dropbox.py", line 447, in request_json_string
    timeout=timeout,
  File "/Library/Frameworks/Python.framework/Versions/3.6/lib/python3.6/site-packages/requests/sessions.py", line 555, in post
    return self.request('POST', url, data=data, json=json, **kwargs)
  File "/Library/Frameworks/Python.framework/Versions/3.6/lib/python3.6/site-packages/requests/sessions.py", line 508, in request
    resp = self.send(prep, **send_kwargs)
  File "/Library/Frameworks/Python.framework/Versions/3.6/lib/python3.6/site-packages/requests/sessions.py", line 618, in send
    r = adapter.send(request, **kwargs)
  File "/Library/Frameworks/Python.framework/Versions/3.6/lib/python3.6/site-packages/requests/adapters.py", line 508, in send
    raise ConnectionError(e, request=request)
requests.exceptions.ConnectionError: HTTPSConnectionPool(host='api.dropboxapi.com', port=443): Max retries exceeded with url: /2/users/get_current_account (Caused by NewConnectionError('<urllib3.connection.VerifiedHTTPSConnection object at 0x10e532208>: Failed to establish a new connection: [Errno 8] nodename nor servname provided, or not known',))
2019-02-22 14:20:17.789109
2019-02-23 14:00:10.483431
2019-02-24 14:00:05.273501
2019-02-25 14:00:03.912109
2019-02-25 23:06:33.259019
2019-02-26 14:00:07.567214
2019-02-27 14:00:05.165992
2019-02-28 12:58:19.286157
Traceback (most recent call last):
  File "/Library/Frameworks/Python.framework/Versions/3.6/lib/python3.6/site-packages/urllib3/connection.py", line 141, in _new_conn
    (self.host, self.port), self.timeout, **extra_kw)
  File "/Library/Frameworks/Python.framework/Versions/3.6/lib/python3.6/site-packages/urllib3/util/connection.py", line 60, in create_connection
    for res in socket.getaddrinfo(host, port, family, socket.SOCK_STREAM):
  File "/Library/Frameworks/Python.framework/Versions/3.6/lib/python3.6/socket.py", line 745, in getaddrinfo
    for res in _socket.getaddrinfo(host, port, family, type, proto, flags):
socket.gaierror: [Errno 8] nodename nor servname provided, or not known

During handling of the above exception, another exception occurred:

Traceback (most recent call last):
  File "/Library/Frameworks/Python.framework/Versions/3.6/lib/python3.6/site-packages/urllib3/connectionpool.py", line 601, in urlopen
    chunked=chunked)
  File "/Library/Frameworks/Python.framework/Versions/3.6/lib/python3.6/site-packages/urllib3/connectionpool.py", line 346, in _make_request
    self._validate_conn(conn)
  File "/Library/Frameworks/Python.framework/Versions/3.6/lib/python3.6/site-packages/urllib3/connectionpool.py", line 850, in _validate_conn
    conn.connect()
  File "/Library/Frameworks/Python.framework/Versions/3.6/lib/python3.6/site-packages/urllib3/connection.py", line 284, in connect
    conn = self._new_conn()
  File "/Library/Frameworks/Python.framework/Versions/3.6/lib/python3.6/site-packages/urllib3/connection.py", line 150, in _new_conn
    self, "Failed to establish a new connection: %s" % e)
urllib3.exceptions.NewConnectionError: <urllib3.connection.VerifiedHTTPSConnection object at 0x10e67e2e8>: Failed to establish a new connection: [Errno 8] nodename nor servname provided, or not known

During handling of the above exception, another exception occurred:

Traceback (most recent call last):
  File "/Library/Frameworks/Python.framework/Versions/3.6/lib/python3.6/site-packages/requests/adapters.py", line 440, in send
    timeout=timeout
  File "/Library/Frameworks/Python.framework/Versions/3.6/lib/python3.6/site-packages/urllib3/connectionpool.py", line 639, in urlopen
    _stacktrace=sys.exc_info()[2])
  File "/Library/Frameworks/Python.framework/Versions/3.6/lib/python3.6/site-packages/urllib3/util/retry.py", line 388, in increment
    raise MaxRetryError(_pool, url, error or ResponseError(cause))
urllib3.exceptions.MaxRetryError: HTTPSConnectionPool(host='api.dropboxapi.com', port=443): Max retries exceeded with url: /2/users/get_current_account (Caused by NewConnectionError('<urllib3.connection.VerifiedHTTPSConnection object at 0x10e67e2e8>: Failed to establish a new connection: [Errno 8] nodename nor servname provided, or not known',))

During handling of the above exception, another exception occurred:

Traceback (most recent call last):
  File "/Users/hepting/Sites/dhhepting.github.io/script/sharemedia.py", line 53, in <module>
    dbx.users_get_current_account()
  File "/Library/Frameworks/Python.framework/Versions/3.6/lib/python3.6/site-packages/dropbox/base.py", line 4301, in users_get_current_account
    None,
  File "/Library/Frameworks/Python.framework/Versions/3.6/lib/python3.6/site-packages/dropbox/dropbox.py", line 272, in request
    timeout=timeout)
  File "/Library/Frameworks/Python.framework/Versions/3.6/lib/python3.6/site-packages/dropbox/dropbox.py", line 363, in request_json_string_with_retry
    timeout=timeout)
  File "/Library/Frameworks/Python.framework/Versions/3.6/lib/python3.6/site-packages/dropbox/dropbox.py", line 447, in request_json_string
    timeout=timeout,
  File "/Library/Frameworks/Python.framework/Versions/3.6/lib/python3.6/site-packages/requests/sessions.py", line 555, in post
    return self.request('POST', url, data=data, json=json, **kwargs)
  File "/Library/Frameworks/Python.framework/Versions/3.6/lib/python3.6/site-packages/requests/sessions.py", line 508, in request
    resp = self.send(prep, **send_kwargs)
  File "/Library/Frameworks/Python.framework/Versions/3.6/lib/python3.6/site-packages/requests/sessions.py", line 618, in send
    r = adapter.send(request, **kwargs)
  File "/Library/Frameworks/Python.framework/Versions/3.6/lib/python3.6/site-packages/requests/adapters.py", line 508, in send
    raise ConnectionError(e, request=request)
requests.exceptions.ConnectionError: HTTPSConnectionPool(host='api.dropboxapi.com', port=443): Max retries exceeded with url: /2/users/get_current_account (Caused by NewConnectionError('<urllib3.connection.VerifiedHTTPSConnection object at 0x10e67e2e8>: Failed to establish a new connection: [Errno 8] nodename nor servname provided, or not known',))
2019-02-28 13:10:11.970155
2019-02-28 13:11:28.958463
2019-02-28 13:13:50.921769
2019-02-28 13:28:38.020741
2019-02-28 13:32:48.535681
2019-02-28 14:00:01.882385
