2019-09-16 14:00:07.308692
2019-09-17 14:00:06.774311
2019-09-18 14:00:06.966798
2019-09-19 14:00:07.794515
2019-09-20 14:23:05.179685
Traceback (most recent call last):
  File "/Library/Frameworks/Python.framework/Versions/3.6/lib/python3.6/site-packages/urllib3/connection.py", line 141, in _new_conn
    (self.host, self.port), self.timeout, **extra_kw)
  File "/Library/Frameworks/Python.framework/Versions/3.6/lib/python3.6/site-packages/urllib3/util/connection.py", line 60, in create_connection
    for res in socket.getaddrinfo(host, port, family, socket.SOCK_STREAM):
  File "/Library/Frameworks/Python.framework/Versions/3.6/lib/python3.6/socket.py", line 745, in getaddrinfo
    for res in _socket.getaddrinfo(host, port, family, type, proto, flags):
socket.gaierror: [Errno 8] nodename nor servname provided, or not known

During handling of the above exception, another exception occurred:

Traceback (most recent call last):
  File "/Library/Frameworks/Python.framework/Versions/3.6/lib/python3.6/site-packages/urllib3/connectionpool.py", line 601, in urlopen
    chunked=chunked)
  File "/Library/Frameworks/Python.framework/Versions/3.6/lib/python3.6/site-packages/urllib3/connectionpool.py", line 346, in _make_request
    self._validate_conn(conn)
  File "/Library/Frameworks/Python.framework/Versions/3.6/lib/python3.6/site-packages/urllib3/connectionpool.py", line 850, in _validate_conn
    conn.connect()
  File "/Library/Frameworks/Python.framework/Versions/3.6/lib/python3.6/site-packages/urllib3/connection.py", line 284, in connect
    conn = self._new_conn()
  File "/Library/Frameworks/Python.framework/Versions/3.6/lib/python3.6/site-packages/urllib3/connection.py", line 150, in _new_conn
    self, "Failed to establish a new connection: %s" % e)
urllib3.exceptions.NewConnectionError: <urllib3.connection.VerifiedHTTPSConnection object at 0x10f525ba8>: Failed to establish a new connection: [Errno 8] nodename nor servname provided, or not known

During handling of the above exception, another exception occurred:

Traceback (most recent call last):
  File "/Library/Frameworks/Python.framework/Versions/3.6/lib/python3.6/site-packages/requests/adapters.py", line 440, in send
    timeout=timeout
  File "/Library/Frameworks/Python.framework/Versions/3.6/lib/python3.6/site-packages/urllib3/connectionpool.py", line 639, in urlopen
    _stacktrace=sys.exc_info()[2])
  File "/Library/Frameworks/Python.framework/Versions/3.6/lib/python3.6/site-packages/urllib3/util/retry.py", line 388, in increment
    raise MaxRetryError(_pool, url, error or ResponseError(cause))
urllib3.exceptions.MaxRetryError: HTTPSConnectionPool(host='api.dropboxapi.com', port=443): Max retries exceeded with url: /2/users/get_current_account (Caused by NewConnectionError('<urllib3.connection.VerifiedHTTPSConnection object at 0x10f525ba8>: Failed to establish a new connection: [Errno 8] nodename nor servname provided, or not known',))

During handling of the above exception, another exception occurred:

Traceback (most recent call last):
  File "/Users/hepting/Sites/dhhepting.github.io/script/sharemedia.py", line 53, in <module>
    dbx.users_get_current_account()
  File "/Library/Frameworks/Python.framework/Versions/3.6/lib/python3.6/site-packages/dropbox/base.py", line 4301, in users_get_current_account
    None,
  File "/Library/Frameworks/Python.framework/Versions/3.6/lib/python3.6/site-packages/dropbox/dropbox.py", line 272, in request
    timeout=timeout)
  File "/Library/Frameworks/Python.framework/Versions/3.6/lib/python3.6/site-packages/dropbox/dropbox.py", line 363, in request_json_string_with_retry
    timeout=timeout)
  File "/Library/Frameworks/Python.framework/Versions/3.6/lib/python3.6/site-packages/dropbox/dropbox.py", line 447, in request_json_string
    timeout=timeout,
  File "/Library/Frameworks/Python.framework/Versions/3.6/lib/python3.6/site-packages/requests/sessions.py", line 555, in post
    return self.request('POST', url, data=data, json=json, **kwargs)
  File "/Library/Frameworks/Python.framework/Versions/3.6/lib/python3.6/site-packages/requests/sessions.py", line 508, in request
    resp = self.send(prep, **send_kwargs)
  File "/Library/Frameworks/Python.framework/Versions/3.6/lib/python3.6/site-packages/requests/sessions.py", line 618, in send
    r = adapter.send(request, **kwargs)
  File "/Library/Frameworks/Python.framework/Versions/3.6/lib/python3.6/site-packages/requests/adapters.py", line 508, in send
    raise ConnectionError(e, request=request)
requests.exceptions.ConnectionError: HTTPSConnectionPool(host='api.dropboxapi.com', port=443): Max retries exceeded with url: /2/users/get_current_account (Caused by NewConnectionError('<urllib3.connection.VerifiedHTTPSConnection object at 0x10f525ba8>: Failed to establish a new connection: [Errno 8] nodename nor servname provided, or not known',))
2020-01-07 17:24:04.451126
2020-01-07 17:28:16.474050
2020-01-07 17:30:30.426057
2020-01-07 17:30:56.931757
2020-01-08 16:30:05.160977
2020-01-09 16:30:07.557473
2020-01-09 17:45:58.454846
2020-01-09 17:51:21.592132
2020-01-10 16:30:08.153395
2020-01-11 23:00:19.895350
Traceback (most recent call last):
  File "/Library/Frameworks/Python.framework/Versions/3.6/lib/python3.6/site-packages/urllib3/connection.py", line 141, in _new_conn
    (self.host, self.port), self.timeout, **extra_kw)
  File "/Library/Frameworks/Python.framework/Versions/3.6/lib/python3.6/site-packages/urllib3/util/connection.py", line 60, in create_connection
    for res in socket.getaddrinfo(host, port, family, socket.SOCK_STREAM):
  File "/Library/Frameworks/Python.framework/Versions/3.6/lib/python3.6/socket.py", line 745, in getaddrinfo
    for res in _socket.getaddrinfo(host, port, family, type, proto, flags):
socket.gaierror: [Errno 8] nodename nor servname provided, or not known

During handling of the above exception, another exception occurred:

Traceback (most recent call last):
  File "/Library/Frameworks/Python.framework/Versions/3.6/lib/python3.6/site-packages/urllib3/connectionpool.py", line 601, in urlopen
    chunked=chunked)
  File "/Library/Frameworks/Python.framework/Versions/3.6/lib/python3.6/site-packages/urllib3/connectionpool.py", line 346, in _make_request
    self._validate_conn(conn)
  File "/Library/Frameworks/Python.framework/Versions/3.6/lib/python3.6/site-packages/urllib3/connectionpool.py", line 850, in _validate_conn
    conn.connect()
  File "/Library/Frameworks/Python.framework/Versions/3.6/lib/python3.6/site-packages/urllib3/connection.py", line 284, in connect
    conn = self._new_conn()
  File "/Library/Frameworks/Python.framework/Versions/3.6/lib/python3.6/site-packages/urllib3/connection.py", line 150, in _new_conn
    self, "Failed to establish a new connection: %s" % e)
urllib3.exceptions.NewConnectionError: <urllib3.connection.VerifiedHTTPSConnection object at 0x10f3d20f0>: Failed to establish a new connection: [Errno 8] nodename nor servname provided, or not known

During handling of the above exception, another exception occurred:

Traceback (most recent call last):
  File "/Users/hepting/Library/Python/3.6/lib/python/site-packages/requests/adapters.py", line 449, in send
    timeout=timeout
  File "/Library/Frameworks/Python.framework/Versions/3.6/lib/python3.6/site-packages/urllib3/connectionpool.py", line 639, in urlopen
    _stacktrace=sys.exc_info()[2])
  File "/Library/Frameworks/Python.framework/Versions/3.6/lib/python3.6/site-packages/urllib3/util/retry.py", line 388, in increment
    raise MaxRetryError(_pool, url, error or ResponseError(cause))
urllib3.exceptions.MaxRetryError: HTTPSConnectionPool(host='api.dropboxapi.com', port=443): Max retries exceeded with url: /2/users/get_current_account (Caused by NewConnectionError('<urllib3.connection.VerifiedHTTPSConnection object at 0x10f3d20f0>: Failed to establish a new connection: [Errno 8] nodename nor servname provided, or not known',))

During handling of the above exception, another exception occurred:

Traceback (most recent call last):
  File "/Users/hepting/Sites/dhhepting.github.io/script/sharemedia.py", line 53, in <module>
    dbx.users_get_current_account()
  File "/Library/Frameworks/Python.framework/Versions/3.6/lib/python3.6/site-packages/dropbox/base.py", line 4301, in users_get_current_account
    None,
  File "/Library/Frameworks/Python.framework/Versions/3.6/lib/python3.6/site-packages/dropbox/dropbox.py", line 272, in request
    timeout=timeout)
  File "/Library/Frameworks/Python.framework/Versions/3.6/lib/python3.6/site-packages/dropbox/dropbox.py", line 363, in request_json_string_with_retry
    timeout=timeout)
  File "/Library/Frameworks/Python.framework/Versions/3.6/lib/python3.6/site-packages/dropbox/dropbox.py", line 447, in request_json_string
    timeout=timeout,
  File "/Users/hepting/Library/Python/3.6/lib/python/site-packages/requests/sessions.py", line 581, in post
    return self.request('POST', url, data=data, json=json, **kwargs)
  File "/Users/hepting/Library/Python/3.6/lib/python/site-packages/requests/sessions.py", line 533, in request
    resp = self.send(prep, **send_kwargs)
  File "/Users/hepting/Library/Python/3.6/lib/python/site-packages/requests/sessions.py", line 646, in send
    r = adapter.send(request, **kwargs)
  File "/Users/hepting/Library/Python/3.6/lib/python/site-packages/requests/adapters.py", line 516, in send
    raise ConnectionError(e, request=request)
requests.exceptions.ConnectionError: HTTPSConnectionPool(host='api.dropboxapi.com', port=443): Max retries exceeded with url: /2/users/get_current_account (Caused by NewConnectionError('<urllib3.connection.VerifiedHTTPSConnection object at 0x10f3d20f0>: Failed to establish a new connection: [Errno 8] nodename nor servname provided, or not known',))
2020-01-13 16:30:09.302616
2020-01-14 16:30:07.845211
2020-01-14 17:59:12.551445
2020-01-15 16:30:09.244697
2020-01-16 18:50:04.535437
2020-01-16 19:06:16.253869
2020-01-16 19:11:08.532479
2020-01-16 19:16:28.768031
2020-01-17 16:30:09.190543
2020-01-18 17:17:43.088867
2020-01-19 18:25:51.490540
2020-01-20 16:30:10.235616
2020-01-21 16:30:08.257561
2020-01-21 17:20:40.576613
2020-01-21 17:30:38.418345
2020-01-22 16:30:10.492963
2020-01-23 16:30:10.997231
2020-01-23 17:02:05.016427
2020-01-23 17:28:04.513033
2020-02-05 14:53:43.996550
2020-02-05 16:30:03.395579
2020-02-05 16:39:25.932754
2020-02-06 16:30:10.496893
2020-02-06 18:12:18.997787
2020-02-06 18:20:37.344957
2020-02-07 12:06:36.604816
2020-02-07 18:21:57.342564
2020-02-08 20:11:12.159292
2020-02-09 16:30:06.927745
2020-02-09 23:25:58.127915
2020-02-10 16:31:34.265710
2020-02-11 16:30:07.486425
2020-02-11 17:10:00.628925
2020-02-11 17:55:13.682766
2020-02-12 16:30:07.344662
2020-02-13 16:13:24.903356
2020-02-13 16:27:17.725581
2020-02-13 16:30:03.974946
2020-02-14 10:20:52.450578
2020-02-14 16:30:06.455133
2020-02-15 21:19:04.596957
2020-02-16 17:24:25.160877
2020-02-17 22:19:53.931891
2020-02-18 16:30:06.989891
2020-02-19 16:30:06.046340
2020-02-20 16:30:07.145440
2020-02-21 16:30:09.406938
2020-02-22 16:30:09.387806
2020-02-23 16:56:21.247702
2020-02-24 16:30:09.689880
