2019-09-16 14:00:07.308692
2019-09-17 14:00:06.774311
2019-09-18 14:00:06.966798
2019-09-19 14:00:07.794515
2019-09-20 14:23:05.179685
Traceback (most recent call last):
  File "/Library/Frameworks/Python.framework/Versions/3.6/lib/python3.6/site-packages/urllib3/connection.py", line 141, in _new_conn
    (self.host, self.port), self.timeout, **extra_kw)
  File "/Library/Frameworks/Python.framework/Versions/3.6/lib/python3.6/site-packages/urllib3/util/connection.py", line 60, in create_connection
    for res in socket.getaddrinfo(host, port, family, socket.SOCK_STREAM):
  File "/Library/Frameworks/Python.framework/Versions/3.6/lib/python3.6/socket.py", line 745, in getaddrinfo
    for res in _socket.getaddrinfo(host, port, family, type, proto, flags):
socket.gaierror: [Errno 8] nodename nor servname provided, or not known

During handling of the above exception, another exception occurred:

Traceback (most recent call last):
  File "/Library/Frameworks/Python.framework/Versions/3.6/lib/python3.6/site-packages/urllib3/connectionpool.py", line 601, in urlopen
    chunked=chunked)
  File "/Library/Frameworks/Python.framework/Versions/3.6/lib/python3.6/site-packages/urllib3/connectionpool.py", line 346, in _make_request
    self._validate_conn(conn)
  File "/Library/Frameworks/Python.framework/Versions/3.6/lib/python3.6/site-packages/urllib3/connectionpool.py", line 850, in _validate_conn
    conn.connect()
  File "/Library/Frameworks/Python.framework/Versions/3.6/lib/python3.6/site-packages/urllib3/connection.py", line 284, in connect
    conn = self._new_conn()
  File "/Library/Frameworks/Python.framework/Versions/3.6/lib/python3.6/site-packages/urllib3/connection.py", line 150, in _new_conn
    self, "Failed to establish a new connection: %s" % e)
urllib3.exceptions.NewConnectionError: <urllib3.connection.VerifiedHTTPSConnection object at 0x10f525ba8>: Failed to establish a new connection: [Errno 8] nodename nor servname provided, or not known

During handling of the above exception, another exception occurred:

Traceback (most recent call last):
  File "/Library/Frameworks/Python.framework/Versions/3.6/lib/python3.6/site-packages/requests/adapters.py", line 440, in send
    timeout=timeout
  File "/Library/Frameworks/Python.framework/Versions/3.6/lib/python3.6/site-packages/urllib3/connectionpool.py", line 639, in urlopen
    _stacktrace=sys.exc_info()[2])
  File "/Library/Frameworks/Python.framework/Versions/3.6/lib/python3.6/site-packages/urllib3/util/retry.py", line 388, in increment
    raise MaxRetryError(_pool, url, error or ResponseError(cause))
urllib3.exceptions.MaxRetryError: HTTPSConnectionPool(host='api.dropboxapi.com', port=443): Max retries exceeded with url: /2/users/get_current_account (Caused by NewConnectionError('<urllib3.connection.VerifiedHTTPSConnection object at 0x10f525ba8>: Failed to establish a new connection: [Errno 8] nodename nor servname provided, or not known',))

During handling of the above exception, another exception occurred:

Traceback (most recent call last):
  File "/Users/hepting/Sites/dhhepting.github.io/script/sharemedia.py", line 53, in <module>
    dbx.users_get_current_account()
  File "/Library/Frameworks/Python.framework/Versions/3.6/lib/python3.6/site-packages/dropbox/base.py", line 4301, in users_get_current_account
    None,
  File "/Library/Frameworks/Python.framework/Versions/3.6/lib/python3.6/site-packages/dropbox/dropbox.py", line 272, in request
    timeout=timeout)
  File "/Library/Frameworks/Python.framework/Versions/3.6/lib/python3.6/site-packages/dropbox/dropbox.py", line 363, in request_json_string_with_retry
    timeout=timeout)
  File "/Library/Frameworks/Python.framework/Versions/3.6/lib/python3.6/site-packages/dropbox/dropbox.py", line 447, in request_json_string
    timeout=timeout,
  File "/Library/Frameworks/Python.framework/Versions/3.6/lib/python3.6/site-packages/requests/sessions.py", line 555, in post
    return self.request('POST', url, data=data, json=json, **kwargs)
  File "/Library/Frameworks/Python.framework/Versions/3.6/lib/python3.6/site-packages/requests/sessions.py", line 508, in request
    resp = self.send(prep, **send_kwargs)
  File "/Library/Frameworks/Python.framework/Versions/3.6/lib/python3.6/site-packages/requests/sessions.py", line 618, in send
    r = adapter.send(request, **kwargs)
  File "/Library/Frameworks/Python.framework/Versions/3.6/lib/python3.6/site-packages/requests/adapters.py", line 508, in send
    raise ConnectionError(e, request=request)
requests.exceptions.ConnectionError: HTTPSConnectionPool(host='api.dropboxapi.com', port=443): Max retries exceeded with url: /2/users/get_current_account (Caused by NewConnectionError('<urllib3.connection.VerifiedHTTPSConnection object at 0x10f525ba8>: Failed to establish a new connection: [Errno 8] nodename nor servname provided, or not known',))
2020-01-07 17:24:04.451126
2020-01-07 17:28:16.474050
2020-01-07 17:30:30.426057
2020-01-07 17:30:56.931757
2020-01-08 16:30:05.160977
2020-01-09 16:30:07.557473
2020-01-09 17:45:58.454846
2020-01-09 17:51:21.592132
