2019-10-31 19:26:45.699677
2019-10-31 21:11:34.600179
2019-10-31 21:13:47.804468
2019-11-01 15:00:07.860930
2019-11-02 16:34:25.606056
Traceback (most recent call last):
  File "/Library/Frameworks/Python.framework/Versions/3.6/lib/python3.6/site-packages/urllib3/connectionpool.py", line 601, in urlopen
    chunked=chunked)
  File "/Library/Frameworks/Python.framework/Versions/3.6/lib/python3.6/site-packages/urllib3/connectionpool.py", line 387, in _make_request
    six.raise_from(e, None)
  File "<string>", line 2, in raise_from
  File "/Library/Frameworks/Python.framework/Versions/3.6/lib/python3.6/site-packages/urllib3/connectionpool.py", line 383, in _make_request
    httplib_response = conn.getresponse()
  File "/Library/Frameworks/Python.framework/Versions/3.6/lib/python3.6/http/client.py", line 1331, in getresponse
    response.begin()
  File "/Library/Frameworks/Python.framework/Versions/3.6/lib/python3.6/http/client.py", line 297, in begin
    version, status, reason = self._read_status()
  File "/Library/Frameworks/Python.framework/Versions/3.6/lib/python3.6/http/client.py", line 258, in _read_status
    line = str(self.fp.readline(_MAXLINE + 1), "iso-8859-1")
  File "/Library/Frameworks/Python.framework/Versions/3.6/lib/python3.6/socket.py", line 586, in readinto
    return self._sock.recv_into(b)
  File "/Library/Frameworks/Python.framework/Versions/3.6/lib/python3.6/site-packages/urllib3/contrib/pyopenssl.py", line 296, in recv_into
    return self.recv_into(*args, **kwargs)
  File "/Library/Frameworks/Python.framework/Versions/3.6/lib/python3.6/site-packages/urllib3/contrib/pyopenssl.py", line 285, in recv_into
    raise SocketError(str(e))
OSError: (60, 'ETIMEDOUT')

During handling of the above exception, another exception occurred:

Traceback (most recent call last):
  File "/Library/Frameworks/Python.framework/Versions/3.6/lib/python3.6/site-packages/requests/adapters.py", line 440, in send
    timeout=timeout
  File "/Library/Frameworks/Python.framework/Versions/3.6/lib/python3.6/site-packages/urllib3/connectionpool.py", line 639, in urlopen
    _stacktrace=sys.exc_info()[2])
  File "/Library/Frameworks/Python.framework/Versions/3.6/lib/python3.6/site-packages/urllib3/util/retry.py", line 357, in increment
    raise six.reraise(type(error), error, _stacktrace)
  File "/Library/Frameworks/Python.framework/Versions/3.6/lib/python3.6/site-packages/urllib3/packages/six.py", line 685, in reraise
    raise value.with_traceback(tb)
  File "/Library/Frameworks/Python.framework/Versions/3.6/lib/python3.6/site-packages/urllib3/connectionpool.py", line 601, in urlopen
    chunked=chunked)
  File "/Library/Frameworks/Python.framework/Versions/3.6/lib/python3.6/site-packages/urllib3/connectionpool.py", line 387, in _make_request
    six.raise_from(e, None)
  File "<string>", line 2, in raise_from
  File "/Library/Frameworks/Python.framework/Versions/3.6/lib/python3.6/site-packages/urllib3/connectionpool.py", line 383, in _make_request
    httplib_response = conn.getresponse()
  File "/Library/Frameworks/Python.framework/Versions/3.6/lib/python3.6/http/client.py", line 1331, in getresponse
    response.begin()
  File "/Library/Frameworks/Python.framework/Versions/3.6/lib/python3.6/http/client.py", line 297, in begin
    version, status, reason = self._read_status()
  File "/Library/Frameworks/Python.framework/Versions/3.6/lib/python3.6/http/client.py", line 258, in _read_status
    line = str(self.fp.readline(_MAXLINE + 1), "iso-8859-1")
  File "/Library/Frameworks/Python.framework/Versions/3.6/lib/python3.6/socket.py", line 586, in readinto
    return self._sock.recv_into(b)
  File "/Library/Frameworks/Python.framework/Versions/3.6/lib/python3.6/site-packages/urllib3/contrib/pyopenssl.py", line 296, in recv_into
    return self.recv_into(*args, **kwargs)
  File "/Library/Frameworks/Python.framework/Versions/3.6/lib/python3.6/site-packages/urllib3/contrib/pyopenssl.py", line 285, in recv_into
    raise SocketError(str(e))
urllib3.exceptions.ProtocolError: ('Connection aborted.', OSError("(60, 'ETIMEDOUT')",))

During handling of the above exception, another exception occurred:

Traceback (most recent call last):
  File "/Users/hepting/Sites/dhhepting.github.io/script/sharemedia.py", line 71, in <module>
    share = dbx.sharing_create_shared_link(dbp)
  File "/Library/Frameworks/Python.framework/Versions/3.6/lib/python3.6/site-packages/dropbox/base.py", line 3095, in sharing_create_shared_link
    None,
  File "/Library/Frameworks/Python.framework/Versions/3.6/lib/python3.6/site-packages/dropbox/dropbox.py", line 272, in request
    timeout=timeout)
  File "/Library/Frameworks/Python.framework/Versions/3.6/lib/python3.6/site-packages/dropbox/dropbox.py", line 363, in request_json_string_with_retry
    timeout=timeout)
  File "/Library/Frameworks/Python.framework/Versions/3.6/lib/python3.6/site-packages/dropbox/dropbox.py", line 447, in request_json_string
    timeout=timeout,
  File "/Library/Frameworks/Python.framework/Versions/3.6/lib/python3.6/site-packages/requests/sessions.py", line 555, in post
    return self.request('POST', url, data=data, json=json, **kwargs)
  File "/Library/Frameworks/Python.framework/Versions/3.6/lib/python3.6/site-packages/requests/sessions.py", line 508, in request
    resp = self.send(prep, **send_kwargs)
  File "/Library/Frameworks/Python.framework/Versions/3.6/lib/python3.6/site-packages/requests/sessions.py", line 618, in send
    r = adapter.send(request, **kwargs)
  File "/Library/Frameworks/Python.framework/Versions/3.6/lib/python3.6/site-packages/requests/adapters.py", line 490, in send
    raise ConnectionError(err, request=request)
requests.exceptions.ConnectionError: ('Connection aborted.', OSError("(60, 'ETIMEDOUT')",))
2019-11-03 15:45:27.486766
Traceback (most recent call last):
  File "/Library/Frameworks/Python.framework/Versions/3.6/lib/python3.6/site-packages/urllib3/connectionpool.py", line 601, in urlopen
    chunked=chunked)
  File "/Library/Frameworks/Python.framework/Versions/3.6/lib/python3.6/site-packages/urllib3/connectionpool.py", line 387, in _make_request
    six.raise_from(e, None)
  File "<string>", line 2, in raise_from
  File "/Library/Frameworks/Python.framework/Versions/3.6/lib/python3.6/site-packages/urllib3/connectionpool.py", line 383, in _make_request
    httplib_response = conn.getresponse()
  File "/Library/Frameworks/Python.framework/Versions/3.6/lib/python3.6/http/client.py", line 1331, in getresponse
    response.begin()
  File "/Library/Frameworks/Python.framework/Versions/3.6/lib/python3.6/http/client.py", line 297, in begin
    version, status, reason = self._read_status()
  File "/Library/Frameworks/Python.framework/Versions/3.6/lib/python3.6/http/client.py", line 258, in _read_status
    line = str(self.fp.readline(_MAXLINE + 1), "iso-8859-1")
  File "/Library/Frameworks/Python.framework/Versions/3.6/lib/python3.6/socket.py", line 586, in readinto
    return self._sock.recv_into(b)
  File "/Library/Frameworks/Python.framework/Versions/3.6/lib/python3.6/site-packages/urllib3/contrib/pyopenssl.py", line 296, in recv_into
    return self.recv_into(*args, **kwargs)
  File "/Library/Frameworks/Python.framework/Versions/3.6/lib/python3.6/site-packages/urllib3/contrib/pyopenssl.py", line 285, in recv_into
    raise SocketError(str(e))
OSError: (65, 'EHOSTUNREACH')

During handling of the above exception, another exception occurred:

Traceback (most recent call last):
  File "/Library/Frameworks/Python.framework/Versions/3.6/lib/python3.6/site-packages/requests/adapters.py", line 440, in send
    timeout=timeout
  File "/Library/Frameworks/Python.framework/Versions/3.6/lib/python3.6/site-packages/urllib3/connectionpool.py", line 639, in urlopen
    _stacktrace=sys.exc_info()[2])
  File "/Library/Frameworks/Python.framework/Versions/3.6/lib/python3.6/site-packages/urllib3/util/retry.py", line 357, in increment
    raise six.reraise(type(error), error, _stacktrace)
  File "/Library/Frameworks/Python.framework/Versions/3.6/lib/python3.6/site-packages/urllib3/packages/six.py", line 685, in reraise
    raise value.with_traceback(tb)
  File "/Library/Frameworks/Python.framework/Versions/3.6/lib/python3.6/site-packages/urllib3/connectionpool.py", line 601, in urlopen
    chunked=chunked)
  File "/Library/Frameworks/Python.framework/Versions/3.6/lib/python3.6/site-packages/urllib3/connectionpool.py", line 387, in _make_request
    six.raise_from(e, None)
  File "<string>", line 2, in raise_from
  File "/Library/Frameworks/Python.framework/Versions/3.6/lib/python3.6/site-packages/urllib3/connectionpool.py", line 383, in _make_request
    httplib_response = conn.getresponse()
  File "/Library/Frameworks/Python.framework/Versions/3.6/lib/python3.6/http/client.py", line 1331, in getresponse
    response.begin()
  File "/Library/Frameworks/Python.framework/Versions/3.6/lib/python3.6/http/client.py", line 297, in begin
    version, status, reason = self._read_status()
  File "/Library/Frameworks/Python.framework/Versions/3.6/lib/python3.6/http/client.py", line 258, in _read_status
    line = str(self.fp.readline(_MAXLINE + 1), "iso-8859-1")
  File "/Library/Frameworks/Python.framework/Versions/3.6/lib/python3.6/socket.py", line 586, in readinto
    return self._sock.recv_into(b)
  File "/Library/Frameworks/Python.framework/Versions/3.6/lib/python3.6/site-packages/urllib3/contrib/pyopenssl.py", line 296, in recv_into
    return self.recv_into(*args, **kwargs)
  File "/Library/Frameworks/Python.framework/Versions/3.6/lib/python3.6/site-packages/urllib3/contrib/pyopenssl.py", line 285, in recv_into
    raise SocketError(str(e))
urllib3.exceptions.ProtocolError: ('Connection aborted.', OSError("(65, 'EHOSTUNREACH')",))

During handling of the above exception, another exception occurred:

Traceback (most recent call last):
  File "/Users/hepting/Sites/dhhepting.github.io/script/sharemedia.py", line 71, in <module>
    share = dbx.sharing_create_shared_link(dbp)
  File "/Library/Frameworks/Python.framework/Versions/3.6/lib/python3.6/site-packages/dropbox/base.py", line 3095, in sharing_create_shared_link
    None,
  File "/Library/Frameworks/Python.framework/Versions/3.6/lib/python3.6/site-packages/dropbox/dropbox.py", line 272, in request
    timeout=timeout)
  File "/Library/Frameworks/Python.framework/Versions/3.6/lib/python3.6/site-packages/dropbox/dropbox.py", line 363, in request_json_string_with_retry
    timeout=timeout)
  File "/Library/Frameworks/Python.framework/Versions/3.6/lib/python3.6/site-packages/dropbox/dropbox.py", line 447, in request_json_string
    timeout=timeout,
  File "/Library/Frameworks/Python.framework/Versions/3.6/lib/python3.6/site-packages/requests/sessions.py", line 555, in post
    return self.request('POST', url, data=data, json=json, **kwargs)
  File "/Library/Frameworks/Python.framework/Versions/3.6/lib/python3.6/site-packages/requests/sessions.py", line 508, in request
    resp = self.send(prep, **send_kwargs)
  File "/Library/Frameworks/Python.framework/Versions/3.6/lib/python3.6/site-packages/requests/sessions.py", line 618, in send
    r = adapter.send(request, **kwargs)
  File "/Library/Frameworks/Python.framework/Versions/3.6/lib/python3.6/site-packages/requests/adapters.py", line 490, in send
    raise ConnectionError(err, request=request)
requests.exceptions.ConnectionError: ('Connection aborted.', OSError("(65, 'EHOSTUNREACH')",))
2019-11-04 15:00:07.044688
2019-11-05 15:00:07.448709
2019-11-06 15:00:06.991324
2019-11-07 12:56:33.266000
2019-11-07 15:00:06.978674
2019-11-08 15:00:07.283740
2019-11-09 15:00:07.067440
2019-11-10 15:00:06.750976
2019-11-11 15:00:07.204723
2019-11-12 15:00:06.959469
2019-11-13 14:56:44.504482
2019-11-13 14:59:36.381628
2019-11-14 15:00:07.681249
2019-11-14 18:46:30.947133
2019-11-14 18:51:07.394518
2019-11-14 19:19:14.910920
2019-11-15 15:00:06.466504
2019-11-16 17:30:30.249197
Traceback (most recent call last):
  File "/Library/Frameworks/Python.framework/Versions/3.6/lib/python3.6/site-packages/urllib3/connectionpool.py", line 601, in urlopen
    chunked=chunked)
  File "/Library/Frameworks/Python.framework/Versions/3.6/lib/python3.6/site-packages/urllib3/connectionpool.py", line 387, in _make_request
    six.raise_from(e, None)
  File "<string>", line 2, in raise_from
  File "/Library/Frameworks/Python.framework/Versions/3.6/lib/python3.6/site-packages/urllib3/connectionpool.py", line 383, in _make_request
    httplib_response = conn.getresponse()
  File "/Library/Frameworks/Python.framework/Versions/3.6/lib/python3.6/http/client.py", line 1331, in getresponse
    response.begin()
  File "/Library/Frameworks/Python.framework/Versions/3.6/lib/python3.6/http/client.py", line 297, in begin
    version, status, reason = self._read_status()
  File "/Library/Frameworks/Python.framework/Versions/3.6/lib/python3.6/http/client.py", line 258, in _read_status
    line = str(self.fp.readline(_MAXLINE + 1), "iso-8859-1")
  File "/Library/Frameworks/Python.framework/Versions/3.6/lib/python3.6/socket.py", line 586, in readinto
    return self._sock.recv_into(b)
  File "/Library/Frameworks/Python.framework/Versions/3.6/lib/python3.6/site-packages/urllib3/contrib/pyopenssl.py", line 296, in recv_into
    return self.recv_into(*args, **kwargs)
  File "/Library/Frameworks/Python.framework/Versions/3.6/lib/python3.6/site-packages/urllib3/contrib/pyopenssl.py", line 285, in recv_into
    raise SocketError(str(e))
OSError: (60, 'ETIMEDOUT')

During handling of the above exception, another exception occurred:

Traceback (most recent call last):
  File "/Library/Frameworks/Python.framework/Versions/3.6/lib/python3.6/site-packages/requests/adapters.py", line 440, in send
    timeout=timeout
  File "/Library/Frameworks/Python.framework/Versions/3.6/lib/python3.6/site-packages/urllib3/connectionpool.py", line 639, in urlopen
    _stacktrace=sys.exc_info()[2])
  File "/Library/Frameworks/Python.framework/Versions/3.6/lib/python3.6/site-packages/urllib3/util/retry.py", line 357, in increment
    raise six.reraise(type(error), error, _stacktrace)
  File "/Library/Frameworks/Python.framework/Versions/3.6/lib/python3.6/site-packages/urllib3/packages/six.py", line 685, in reraise
    raise value.with_traceback(tb)
  File "/Library/Frameworks/Python.framework/Versions/3.6/lib/python3.6/site-packages/urllib3/connectionpool.py", line 601, in urlopen
    chunked=chunked)
  File "/Library/Frameworks/Python.framework/Versions/3.6/lib/python3.6/site-packages/urllib3/connectionpool.py", line 387, in _make_request
    six.raise_from(e, None)
  File "<string>", line 2, in raise_from
  File "/Library/Frameworks/Python.framework/Versions/3.6/lib/python3.6/site-packages/urllib3/connectionpool.py", line 383, in _make_request
    httplib_response = conn.getresponse()
  File "/Library/Frameworks/Python.framework/Versions/3.6/lib/python3.6/http/client.py", line 1331, in getresponse
    response.begin()
  File "/Library/Frameworks/Python.framework/Versions/3.6/lib/python3.6/http/client.py", line 297, in begin
    version, status, reason = self._read_status()
  File "/Library/Frameworks/Python.framework/Versions/3.6/lib/python3.6/http/client.py", line 258, in _read_status
    line = str(self.fp.readline(_MAXLINE + 1), "iso-8859-1")
  File "/Library/Frameworks/Python.framework/Versions/3.6/lib/python3.6/socket.py", line 586, in readinto
    return self._sock.recv_into(b)
  File "/Library/Frameworks/Python.framework/Versions/3.6/lib/python3.6/site-packages/urllib3/contrib/pyopenssl.py", line 296, in recv_into
    return self.recv_into(*args, **kwargs)
  File "/Library/Frameworks/Python.framework/Versions/3.6/lib/python3.6/site-packages/urllib3/contrib/pyopenssl.py", line 285, in recv_into
    raise SocketError(str(e))
urllib3.exceptions.ProtocolError: ('Connection aborted.', OSError("(60, 'ETIMEDOUT')",))

During handling of the above exception, another exception occurred:

Traceback (most recent call last):
  File "/Users/hepting/Sites/dhhepting.github.io/script/sharemedia.py", line 71, in <module>
    share = dbx.sharing_create_shared_link(dbp)
  File "/Library/Frameworks/Python.framework/Versions/3.6/lib/python3.6/site-packages/dropbox/base.py", line 3095, in sharing_create_shared_link
    None,
  File "/Library/Frameworks/Python.framework/Versions/3.6/lib/python3.6/site-packages/dropbox/dropbox.py", line 272, in request
    timeout=timeout)
  File "/Library/Frameworks/Python.framework/Versions/3.6/lib/python3.6/site-packages/dropbox/dropbox.py", line 363, in request_json_string_with_retry
    timeout=timeout)
  File "/Library/Frameworks/Python.framework/Versions/3.6/lib/python3.6/site-packages/dropbox/dropbox.py", line 447, in request_json_string
    timeout=timeout,
  File "/Library/Frameworks/Python.framework/Versions/3.6/lib/python3.6/site-packages/requests/sessions.py", line 555, in post
    return self.request('POST', url, data=data, json=json, **kwargs)
  File "/Library/Frameworks/Python.framework/Versions/3.6/lib/python3.6/site-packages/requests/sessions.py", line 508, in request
    resp = self.send(prep, **send_kwargs)
  File "/Library/Frameworks/Python.framework/Versions/3.6/lib/python3.6/site-packages/requests/sessions.py", line 618, in send
    r = adapter.send(request, **kwargs)
  File "/Library/Frameworks/Python.framework/Versions/3.6/lib/python3.6/site-packages/requests/adapters.py", line 490, in send
    raise ConnectionError(err, request=request)
requests.exceptions.ConnectionError: ('Connection aborted.', OSError("(60, 'ETIMEDOUT')",))
2019-11-18 15:00:11.556896
2019-11-19 15:00:06.793648
2019-11-19 17:46:24.175729
2019-11-19 17:48:25.889276
2019-11-19 17:50:06.547041
2019-11-20 15:00:07.194718
2019-11-21 15:00:07.798664
2019-11-21 18:17:01.140519
2019-11-21 18:21:35.625305
2019-11-22 15:00:09.138864
Traceback (most recent call last):
  File "/Library/Frameworks/Python.framework/Versions/3.6/lib/python3.6/site-packages/urllib3/connection.py", line 141, in _new_conn
    (self.host, self.port), self.timeout, **extra_kw)
  File "/Library/Frameworks/Python.framework/Versions/3.6/lib/python3.6/site-packages/urllib3/util/connection.py", line 60, in create_connection
    for res in socket.getaddrinfo(host, port, family, socket.SOCK_STREAM):
  File "/Library/Frameworks/Python.framework/Versions/3.6/lib/python3.6/socket.py", line 745, in getaddrinfo
    for res in _socket.getaddrinfo(host, port, family, type, proto, flags):
socket.gaierror: [Errno 8] nodename nor servname provided, or not known

During handling of the above exception, another exception occurred:

Traceback (most recent call last):
  File "/Library/Frameworks/Python.framework/Versions/3.6/lib/python3.6/site-packages/urllib3/connectionpool.py", line 601, in urlopen
    chunked=chunked)
  File "/Library/Frameworks/Python.framework/Versions/3.6/lib/python3.6/site-packages/urllib3/connectionpool.py", line 346, in _make_request
    self._validate_conn(conn)
  File "/Library/Frameworks/Python.framework/Versions/3.6/lib/python3.6/site-packages/urllib3/connectionpool.py", line 850, in _validate_conn
    conn.connect()
  File "/Library/Frameworks/Python.framework/Versions/3.6/lib/python3.6/site-packages/urllib3/connection.py", line 284, in connect
    conn = self._new_conn()
  File "/Library/Frameworks/Python.framework/Versions/3.6/lib/python3.6/site-packages/urllib3/connection.py", line 150, in _new_conn
    self, "Failed to establish a new connection: %s" % e)
urllib3.exceptions.NewConnectionError: <urllib3.connection.VerifiedHTTPSConnection object at 0x10f509668>: Failed to establish a new connection: [Errno 8] nodename nor servname provided, or not known

During handling of the above exception, another exception occurred:

Traceback (most recent call last):
  File "/Library/Frameworks/Python.framework/Versions/3.6/lib/python3.6/site-packages/requests/adapters.py", line 440, in send
    timeout=timeout
  File "/Library/Frameworks/Python.framework/Versions/3.6/lib/python3.6/site-packages/urllib3/connectionpool.py", line 639, in urlopen
    _stacktrace=sys.exc_info()[2])
  File "/Library/Frameworks/Python.framework/Versions/3.6/lib/python3.6/site-packages/urllib3/util/retry.py", line 388, in increment
    raise MaxRetryError(_pool, url, error or ResponseError(cause))
urllib3.exceptions.MaxRetryError: HTTPSConnectionPool(host='api.dropboxapi.com', port=443): Max retries exceeded with url: /2/users/get_current_account (Caused by NewConnectionError('<urllib3.connection.VerifiedHTTPSConnection object at 0x10f509668>: Failed to establish a new connection: [Errno 8] nodename nor servname provided, or not known',))

During handling of the above exception, another exception occurred:

Traceback (most recent call last):
  File "/Users/hepting/Sites/dhhepting.github.io/script/sharemedia.py", line 53, in <module>
    dbx.users_get_current_account()
  File "/Library/Frameworks/Python.framework/Versions/3.6/lib/python3.6/site-packages/dropbox/base.py", line 4301, in users_get_current_account
    None,
  File "/Library/Frameworks/Python.framework/Versions/3.6/lib/python3.6/site-packages/dropbox/dropbox.py", line 272, in request
    timeout=timeout)
  File "/Library/Frameworks/Python.framework/Versions/3.6/lib/python3.6/site-packages/dropbox/dropbox.py", line 363, in request_json_string_with_retry
    timeout=timeout)
  File "/Library/Frameworks/Python.framework/Versions/3.6/lib/python3.6/site-packages/dropbox/dropbox.py", line 447, in request_json_string
    timeout=timeout,
  File "/Library/Frameworks/Python.framework/Versions/3.6/lib/python3.6/site-packages/requests/sessions.py", line 555, in post
    return self.request('POST', url, data=data, json=json, **kwargs)
  File "/Library/Frameworks/Python.framework/Versions/3.6/lib/python3.6/site-packages/requests/sessions.py", line 508, in request
    resp = self.send(prep, **send_kwargs)
  File "/Library/Frameworks/Python.framework/Versions/3.6/lib/python3.6/site-packages/requests/sessions.py", line 618, in send
    r = adapter.send(request, **kwargs)
  File "/Library/Frameworks/Python.framework/Versions/3.6/lib/python3.6/site-packages/requests/adapters.py", line 508, in send
    raise ConnectionError(e, request=request)
requests.exceptions.ConnectionError: HTTPSConnectionPool(host='api.dropboxapi.com', port=443): Max retries exceeded with url: /2/users/get_current_account (Caused by NewConnectionError('<urllib3.connection.VerifiedHTTPSConnection object at 0x10f509668>: Failed to establish a new connection: [Errno 8] nodename nor servname provided, or not known',))
2019-11-23 16:12:12.250352
2019-11-24 23:20:00.078935
2019-11-25 15:00:07.832473
2019-11-26 15:00:03.983549
