2023-09-06 13:03:02.221474
2023-09-06 17:00:07.5468252023-09-07 17:00:01.629725
2023-09-08 18:00:03.256673
Traceback (most recent call last):
  File "/usr/local/lib/python3.11/site-packages/urllib3/connection.py", line 203, in _new_conn
    sock = connection.create_connection(
           ^^^^^^^^^^^^^^^^^^^^^^^^^^^^^
  File "/usr/local/lib/python3.11/site-packages/urllib3/util/connection.py", line 60, in create_connection
    for res in socket.getaddrinfo(host, port, family, socket.SOCK_STREAM):
               ^^^^^^^^^^^^^^^^^^^^^^^^^^^^^^^^^^^^^^^^^^^^^^^^^^^^^^^^^^
  File "/usr/local/Cellar/python@3.11/3.11.5/Frameworks/Python.framework/Versions/3.11/lib/python3.11/socket.py", line 962, in getaddrinfo
    for res in _socket.getaddrinfo(host, port, family, type, proto, flags):
               ^^^^^^^^^^^^^^^^^^^^^^^^^^^^^^^^^^^^^^^^^^^^^^^^^^^^^^^^^^^
socket.gaierror: [Errno 8] nodename nor servname provided, or not known

The above exception was the direct cause of the following exception:

Traceback (most recent call last):
  File "/usr/local/lib/python3.11/site-packages/urllib3/connectionpool.py", line 790, in urlopen
    response = self._make_request(
               ^^^^^^^^^^^^^^^^^^^
  File "/usr/local/lib/python3.11/site-packages/urllib3/connectionpool.py", line 491, in _make_request
    raise new_e
  File "/usr/local/lib/python3.11/site-packages/urllib3/connectionpool.py", line 467, in _make_request
    self._validate_conn(conn)
  File "/usr/local/lib/python3.11/site-packages/urllib3/connectionpool.py", line 1092, in _validate_conn
    conn.connect()
  File "/usr/local/lib/python3.11/site-packages/urllib3/connection.py", line 611, in connect
    self.sock = sock = self._new_conn()
                       ^^^^^^^^^^^^^^^^
  File "/usr/local/lib/python3.11/site-packages/urllib3/connection.py", line 210, in _new_conn
    raise NameResolutionError(self.host, self, e) from e
urllib3.exceptions.NameResolutionError: <urllib3.connection.HTTPSConnection object at 0x103879ad0>: Failed to resolve 'api.dropboxapi.com' ([Errno 8] nodename nor servname provided, or not known)

The above exception was the direct cause of the following exception:

Traceback (most recent call last):
  File "/usr/local/lib/python3.11/site-packages/requests/adapters.py", line 486, in send
    resp = conn.urlopen(
           ^^^^^^^^^^^^^
  File "/usr/local/lib/python3.11/site-packages/urllib3/connectionpool.py", line 844, in urlopen
    retries = retries.increment(
              ^^^^^^^^^^^^^^^^^^
  File "/usr/local/lib/python3.11/site-packages/urllib3/util/retry.py", line 515, in increment
    raise MaxRetryError(_pool, url, reason) from reason  # type: ignore[arg-type]
    ^^^^^^^^^^^^^^^^^^^^^^^^^^^^^^^^^^^^^^^^^^^^^^^^^^^
urllib3.exceptions.MaxRetryError: HTTPSConnectionPool(host='api.dropboxapi.com', port=443): Max retries exceeded with url: /2/users/get_current_account (Caused by NameResolutionError("<urllib3.connection.HTTPSConnection object at 0x103879ad0>: Failed to resolve 'api.dropboxapi.com' ([Errno 8] nodename nor servname provided, or not known)"))

During handling of the above exception, another exception occurred:

Traceback (most recent call last):
  File "/Users/hepting/Sites/dhhepting.github.io/script/sharemedia.py", line 55, in <module>
    dbx.users_get_current_account()
  File "/usr/local/lib/python3.11/site-packages/dropbox/base.py", line 5866, in users_get_current_account
    r = self.request(
        ^^^^^^^^^^^^^
  File "/usr/local/lib/python3.11/site-packages/dropbox/dropbox_client.py", line 326, in request
    res = self.request_json_string_with_retry(host,
          ^^^^^^^^^^^^^^^^^^^^^^^^^^^^^^^^^^^^^^^^^
  File "/usr/local/lib/python3.11/site-packages/dropbox/dropbox_client.py", line 476, in request_json_string_with_retry
    return self.request_json_string(host,
           ^^^^^^^^^^^^^^^^^^^^^^^^^^^^^^
  File "/usr/local/lib/python3.11/site-packages/dropbox/dropbox_client.py", line 589, in request_json_string
    r = self._session.post(url,
        ^^^^^^^^^^^^^^^^^^^^^^^
  File "/usr/local/lib/python3.11/site-packages/requests/sessions.py", line 637, in post
    return self.request("POST", url, data=data, json=json, **kwargs)
           ^^^^^^^^^^^^^^^^^^^^^^^^^^^^^^^^^^^^^^^^^^^^^^^^^^^^^^^^^
  File "/usr/local/lib/python3.11/site-packages/requests/sessions.py", line 589, in request
    resp = self.send(prep, **send_kwargs)
           ^^^^^^^^^^^^^^^^^^^^^^^^^^^^^^
  File "/usr/local/lib/python3.11/site-packages/requests/sessions.py", line 703, in send
    r = adapter.send(request, **kwargs)
        ^^^^^^^^^^^^^^^^^^^^^^^^^^^^^^^
  File "/usr/local/lib/python3.11/site-packages/requests/adapters.py", line 519, in send
    raise ConnectionError(e, request=request)
requests.exceptions.ConnectionError: HTTPSConnectionPool(host='api.dropboxapi.com', port=443): Max retries exceeded with url: /2/users/get_current_account (Caused by NameResolutionError("<urllib3.connection.HTTPSConnection object at 0x103879ad0>: Failed to resolve 'api.dropboxapi.com' ([Errno 8] nodename nor servname provided, or not known)"))
2023-09-09 17:03:53.920684
Traceback (most recent call last):
  File "/usr/local/lib/python3.11/site-packages/urllib3/connectionpool.py", line 536, in _make_request
    response = conn.getresponse()
               ^^^^^^^^^^^^^^^^^^
  File "/usr/local/lib/python3.11/site-packages/urllib3/connection.py", line 461, in getresponse
    httplib_response = super().getresponse()
                       ^^^^^^^^^^^^^^^^^^^^^
  File "/usr/local/Cellar/python@3.11/3.11.5/Frameworks/Python.framework/Versions/3.11/lib/python3.11/http/client.py", line 1378, in getresponse
    response.begin()
  File "/usr/local/Cellar/python@3.11/3.11.5/Frameworks/Python.framework/Versions/3.11/lib/python3.11/http/client.py", line 318, in begin
    version, status, reason = self._read_status()
                              ^^^^^^^^^^^^^^^^^^^
  File "/usr/local/Cellar/python@3.11/3.11.5/Frameworks/Python.framework/Versions/3.11/lib/python3.11/http/client.py", line 279, in _read_status
    line = str(self.fp.readline(_MAXLINE + 1), "iso-8859-1")
               ^^^^^^^^^^^^^^^^^^^^^^^^^^^^^^
  File "/usr/local/Cellar/python@3.11/3.11.5/Frameworks/Python.framework/Versions/3.11/lib/python3.11/socket.py", line 706, in readinto
    return self._sock.recv_into(b)
           ^^^^^^^^^^^^^^^^^^^^^^^
  File "/usr/local/Cellar/python@3.11/3.11.5/Frameworks/Python.framework/Versions/3.11/lib/python3.11/ssl.py", line 1311, in recv_into
    return self.read(nbytes, buffer)
           ^^^^^^^^^^^^^^^^^^^^^^^^^
  File "/usr/local/Cellar/python@3.11/3.11.5/Frameworks/Python.framework/Versions/3.11/lib/python3.11/ssl.py", line 1167, in read
    return self._sslobj.read(len, buffer)
           ^^^^^^^^^^^^^^^^^^^^^^^^^^^^^^
TimeoutError: The read operation timed out

The above exception was the direct cause of the following exception:

Traceback (most recent call last):
  File "/usr/local/lib/python3.11/site-packages/requests/adapters.py", line 486, in send
    resp = conn.urlopen(
           ^^^^^^^^^^^^^
  File "/usr/local/lib/python3.11/site-packages/urllib3/connectionpool.py", line 844, in urlopen
    retries = retries.increment(
              ^^^^^^^^^^^^^^^^^^
  File "/usr/local/lib/python3.11/site-packages/urllib3/util/retry.py", line 470, in increment
    raise reraise(type(error), error, _stacktrace)
          ^^^^^^^^^^^^^^^^^^^^^^^^^^^^^^^^^^^^^^^^
  File "/usr/local/lib/python3.11/site-packages/urllib3/util/util.py", line 39, in reraise
    raise value
  File "/usr/local/lib/python3.11/site-packages/urllib3/connectionpool.py", line 790, in urlopen
    response = self._make_request(
               ^^^^^^^^^^^^^^^^^^^
  File "/usr/local/lib/python3.11/site-packages/urllib3/connectionpool.py", line 538, in _make_request
    self._raise_timeout(err=e, url=url, timeout_value=read_timeout)
  File "/usr/local/lib/python3.11/site-packages/urllib3/connectionpool.py", line 370, in _raise_timeout
    raise ReadTimeoutError(
urllib3.exceptions.ReadTimeoutError: HTTPSConnectionPool(host='api.dropboxapi.com', port=443): Read timed out. (read timeout=100)

During handling of the above exception, another exception occurred:

Traceback (most recent call last):
  File "/Users/hepting/Sites/dhhepting.github.io/script/sharemedia.py", line 75, in <module>
    share = dbx.sharing_create_shared_link(dbp)
            ^^^^^^^^^^^^^^^^^^^^^^^^^^^^^^^^^^^
  File "/usr/local/lib/python3.11/site-packages/dropbox/base.py", line 4553, in sharing_create_shared_link
    r = self.request(
        ^^^^^^^^^^^^^
  File "/usr/local/lib/python3.11/site-packages/dropbox/dropbox_client.py", line 326, in request
    res = self.request_json_string_with_retry(host,
          ^^^^^^^^^^^^^^^^^^^^^^^^^^^^^^^^^^^^^^^^^
  File "/usr/local/lib/python3.11/site-packages/dropbox/dropbox_client.py", line 476, in request_json_string_with_retry
    return self.request_json_string(host,
           ^^^^^^^^^^^^^^^^^^^^^^^^^^^^^^
  File "/usr/local/lib/python3.11/site-packages/dropbox/dropbox_client.py", line 589, in request_json_string
    r = self._session.post(url,
        ^^^^^^^^^^^^^^^^^^^^^^^
  File "/usr/local/lib/python3.11/site-packages/requests/sessions.py", line 637, in post
    return self.request("POST", url, data=data, json=json, **kwargs)
           ^^^^^^^^^^^^^^^^^^^^^^^^^^^^^^^^^^^^^^^^^^^^^^^^^^^^^^^^^
  File "/usr/local/lib/python3.11/site-packages/requests/sessions.py", line 589, in request
    resp = self.send(prep, **send_kwargs)
           ^^^^^^^^^^^^^^^^^^^^^^^^^^^^^^
  File "/usr/local/lib/python3.11/site-packages/requests/sessions.py", line 703, in send
    r = adapter.send(request, **kwargs)
        ^^^^^^^^^^^^^^^^^^^^^^^^^^^^^^^
  File "/usr/local/lib/python3.11/site-packages/requests/adapters.py", line 532, in send
    raise ReadTimeout(e, request=request)
requests.exceptions.ReadTimeout: HTTPSConnectionPool(host='api.dropboxapi.com', port=443): Read timed out. (read timeout=100)
2023-09-10 17:18:05.026502
Traceback (most recent call last):
  File "/usr/local/lib/python3.11/site-packages/urllib3/connectionpool.py", line 790, in urlopen
    response = self._make_request(
               ^^^^^^^^^^^^^^^^^^^
  File "/usr/local/lib/python3.11/site-packages/urllib3/connectionpool.py", line 536, in _make_request
    response = conn.getresponse()
               ^^^^^^^^^^^^^^^^^^
  File "/usr/local/lib/python3.11/site-packages/urllib3/connection.py", line 461, in getresponse
    httplib_response = super().getresponse()
                       ^^^^^^^^^^^^^^^^^^^^^
  File "/usr/local/Cellar/python@3.11/3.11.5/Frameworks/Python.framework/Versions/3.11/lib/python3.11/http/client.py", line 1378, in getresponse
    response.begin()
  File "/usr/local/Cellar/python@3.11/3.11.5/Frameworks/Python.framework/Versions/3.11/lib/python3.11/http/client.py", line 318, in begin
    version, status, reason = self._read_status()
                              ^^^^^^^^^^^^^^^^^^^
  File "/usr/local/Cellar/python@3.11/3.11.5/Frameworks/Python.framework/Versions/3.11/lib/python3.11/http/client.py", line 287, in _read_status
    raise RemoteDisconnected("Remote end closed connection without"
http.client.RemoteDisconnected: Remote end closed connection without response

During handling of the above exception, another exception occurred:

Traceback (most recent call last):
  File "/usr/local/lib/python3.11/site-packages/requests/adapters.py", line 486, in send
    resp = conn.urlopen(
           ^^^^^^^^^^^^^
  File "/usr/local/lib/python3.11/site-packages/urllib3/connectionpool.py", line 844, in urlopen
    retries = retries.increment(
              ^^^^^^^^^^^^^^^^^^
  File "/usr/local/lib/python3.11/site-packages/urllib3/util/retry.py", line 470, in increment
    raise reraise(type(error), error, _stacktrace)
          ^^^^^^^^^^^^^^^^^^^^^^^^^^^^^^^^^^^^^^^^
  File "/usr/local/lib/python3.11/site-packages/urllib3/util/util.py", line 38, in reraise
    raise value.with_traceback(tb)
  File "/usr/local/lib/python3.11/site-packages/urllib3/connectionpool.py", line 790, in urlopen
    response = self._make_request(
               ^^^^^^^^^^^^^^^^^^^
  File "/usr/local/lib/python3.11/site-packages/urllib3/connectionpool.py", line 536, in _make_request
    response = conn.getresponse()
               ^^^^^^^^^^^^^^^^^^
  File "/usr/local/lib/python3.11/site-packages/urllib3/connection.py", line 461, in getresponse
    httplib_response = super().getresponse()
                       ^^^^^^^^^^^^^^^^^^^^^
  File "/usr/local/Cellar/python@3.11/3.11.5/Frameworks/Python.framework/Versions/3.11/lib/python3.11/http/client.py", line 1378, in getresponse
    response.begin()
  File "/usr/local/Cellar/python@3.11/3.11.5/Frameworks/Python.framework/Versions/3.11/lib/python3.11/http/client.py", line 318, in begin
    version, status, reason = self._read_status()
                              ^^^^^^^^^^^^^^^^^^^
  File "/usr/local/Cellar/python@3.11/3.11.5/Frameworks/Python.framework/Versions/3.11/lib/python3.11/http/client.py", line 287, in _read_status
    raise RemoteDisconnected("Remote end closed connection without"
urllib3.exceptions.ProtocolError: ('Connection aborted.', RemoteDisconnected('Remote end closed connection without response'))

During handling of the above exception, another exception occurred:

Traceback (most recent call last):
  File "/Users/hepting/Sites/dhhepting.github.io/script/sharemedia.py", line 75, in <module>
    share = dbx.sharing_create_shared_link(dbp)
            ^^^^^^^^^^^^^^^^^^^^^^^^^^^^^^^^^^^
  File "/usr/local/lib/python3.11/site-packages/dropbox/base.py", line 4553, in sharing_create_shared_link
    r = self.request(
        ^^^^^^^^^^^^^
  File "/usr/local/lib/python3.11/site-packages/dropbox/dropbox_client.py", line 326, in request
    res = self.request_json_string_with_retry(host,
          ^^^^^^^^^^^^^^^^^^^^^^^^^^^^^^^^^^^^^^^^^
  File "/usr/local/lib/python3.11/site-packages/dropbox/dropbox_client.py", line 476, in request_json_string_with_retry
    return self.request_json_string(host,
           ^^^^^^^^^^^^^^^^^^^^^^^^^^^^^^
  File "/usr/local/lib/python3.11/site-packages/dropbox/dropbox_client.py", line 589, in request_json_string
    r = self._session.post(url,
        ^^^^^^^^^^^^^^^^^^^^^^^
  File "/usr/local/lib/python3.11/site-packages/requests/sessions.py", line 637, in post
    return self.request("POST", url, data=data, json=json, **kwargs)
           ^^^^^^^^^^^^^^^^^^^^^^^^^^^^^^^^^^^^^^^^^^^^^^^^^^^^^^^^^
  File "/usr/local/lib/python3.11/site-packages/requests/sessions.py", line 589, in request
    resp = self.send(prep, **send_kwargs)
           ^^^^^^^^^^^^^^^^^^^^^^^^^^^^^^
  File "/usr/local/lib/python3.11/site-packages/requests/sessions.py", line 703, in send
    r = adapter.send(request, **kwargs)
        ^^^^^^^^^^^^^^^^^^^^^^^^^^^^^^^
  File "/usr/local/lib/python3.11/site-packages/requests/adapters.py", line 501, in send
    raise ConnectionError(err, request=request)
requests.exceptions.ConnectionError: ('Connection aborted.', RemoteDisconnected('Remote end closed connection without response'))
2023-09-11 13:09:16.727770
2023-09-11 18:00:14.179529
Traceback (most recent call last):
  File "/usr/local/lib/python3.11/site-packages/urllib3/connection.py", line 203, in _new_conn
    sock = connection.create_connection(
           ^^^^^^^^^^^^^^^^^^^^^^^^^^^^^
  File "/usr/local/lib/python3.11/site-packages/urllib3/util/connection.py", line 60, in create_connection
    for res in socket.getaddrinfo(host, port, family, socket.SOCK_STREAM):
               ^^^^^^^^^^^^^^^^^^^^^^^^^^^^^^^^^^^^^^^^^^^^^^^^^^^^^^^^^^
  File "/usr/local/Cellar/python@3.11/3.11.5/Frameworks/Python.framework/Versions/3.11/lib/python3.11/socket.py", line 962, in getaddrinfo
    for res in _socket.getaddrinfo(host, port, family, type, proto, flags):
               ^^^^^^^^^^^^^^^^^^^^^^^^^^^^^^^^^^^^^^^^^^^^^^^^^^^^^^^^^^^
socket.gaierror: [Errno 8] nodename nor servname provided, or not known

The above exception was the direct cause of the following exception:

Traceback (most recent call last):
  File "/usr/local/lib/python3.11/site-packages/urllib3/connectionpool.py", line 790, in urlopen
    response = self._make_request(
               ^^^^^^^^^^^^^^^^^^^
  File "/usr/local/lib/python3.11/site-packages/urllib3/connectionpool.py", line 491, in _make_request
    raise new_e
  File "/usr/local/lib/python3.11/site-packages/urllib3/connectionpool.py", line 467, in _make_request
    self._validate_conn(conn)
  File "/usr/local/lib/python3.11/site-packages/urllib3/connectionpool.py", line 1092, in _validate_conn
    conn.connect()
  File "/usr/local/lib/python3.11/site-packages/urllib3/connection.py", line 611, in connect
    self.sock = sock = self._new_conn()
                       ^^^^^^^^^^^^^^^^
  File "/usr/local/lib/python3.11/site-packages/urllib3/connection.py", line 210, in _new_conn
    raise NameResolutionError(self.host, self, e) from e
urllib3.exceptions.NameResolutionError: <urllib3.connection.HTTPSConnection object at 0x1126c5ad0>: Failed to resolve 'api.dropboxapi.com' ([Errno 8] nodename nor servname provided, or not known)

The above exception was the direct cause of the following exception:

Traceback (most recent call last):
  File "/usr/local/lib/python3.11/site-packages/requests/adapters.py", line 486, in send
    resp = conn.urlopen(
           ^^^^^^^^^^^^^
  File "/usr/local/lib/python3.11/site-packages/urllib3/connectionpool.py", line 844, in urlopen
    retries = retries.increment(
              ^^^^^^^^^^^^^^^^^^
  File "/usr/local/lib/python3.11/site-packages/urllib3/util/retry.py", line 515, in increment
    raise MaxRetryError(_pool, url, reason) from reason  # type: ignore[arg-type]
    ^^^^^^^^^^^^^^^^^^^^^^^^^^^^^^^^^^^^^^^^^^^^^^^^^^^
urllib3.exceptions.MaxRetryError: HTTPSConnectionPool(host='api.dropboxapi.com', port=443): Max retries exceeded with url: /2/users/get_current_account (Caused by NameResolutionError("<urllib3.connection.HTTPSConnection object at 0x1126c5ad0>: Failed to resolve 'api.dropboxapi.com' ([Errno 8] nodename nor servname provided, or not known)"))

During handling of the above exception, another exception occurred:

Traceback (most recent call last):
  File "/Users/hepting/Sites/dhhepting.github.io/script/sharemedia.py", line 55, in <module>
    dbx.users_get_current_account()
  File "/usr/local/lib/python3.11/site-packages/dropbox/base.py", line 5866, in users_get_current_account
    r = self.request(
        ^^^^^^^^^^^^^
  File "/usr/local/lib/python3.11/site-packages/dropbox/dropbox_client.py", line 326, in request
    res = self.request_json_string_with_retry(host,
          ^^^^^^^^^^^^^^^^^^^^^^^^^^^^^^^^^^^^^^^^^
  File "/usr/local/lib/python3.11/site-packages/dropbox/dropbox_client.py", line 476, in request_json_string_with_retry
    return self.request_json_string(host,
           ^^^^^^^^^^^^^^^^^^^^^^^^^^^^^^
  File "/usr/local/lib/python3.11/site-packages/dropbox/dropbox_client.py", line 589, in request_json_string
    r = self._session.post(url,
        ^^^^^^^^^^^^^^^^^^^^^^^
  File "/usr/local/lib/python3.11/site-packages/requests/sessions.py", line 637, in post
    return self.request("POST", url, data=data, json=json, **kwargs)
           ^^^^^^^^^^^^^^^^^^^^^^^^^^^^^^^^^^^^^^^^^^^^^^^^^^^^^^^^^
  File "/usr/local/lib/python3.11/site-packages/requests/sessions.py", line 589, in request
    resp = self.send(prep, **send_kwargs)
           ^^^^^^^^^^^^^^^^^^^^^^^^^^^^^^
  File "/usr/local/lib/python3.11/site-packages/requests/sessions.py", line 703, in send
    r = adapter.send(request, **kwargs)
        ^^^^^^^^^^^^^^^^^^^^^^^^^^^^^^^
  File "/usr/local/lib/python3.11/site-packages/requests/adapters.py", line 519, in send
    raise ConnectionError(e, request=request)
requests.exceptions.ConnectionError: HTTPSConnectionPool(host='api.dropboxapi.com', port=443): Max retries exceeded with url: /2/users/get_current_account (Caused by NameResolutionError("<urllib3.connection.HTTPSConnection object at 0x1126c5ad0>: Failed to resolve 'api.dropboxapi.com' ([Errno 8] nodename nor servname provided, or not known)"))
2023-09-12 17:00:01.641256
2023-09-13 11:53:23.686013
2023-09-13 17:00:02.495985
2023-09-14 17:00:01.672563
2023-09-15 17:00:01.177404
2023-09-16 18:00:12.979904
Traceback (most recent call last):
  File "/usr/local/lib/python3.11/site-packages/urllib3/connectionpool.py", line 790, in urlopen
    response = self._make_request(
               ^^^^^^^^^^^^^^^^^^^
  File "/usr/local/lib/python3.11/site-packages/urllib3/connectionpool.py", line 536, in _make_request
    response = conn.getresponse()
               ^^^^^^^^^^^^^^^^^^
  File "/usr/local/lib/python3.11/site-packages/urllib3/connection.py", line 461, in getresponse
    httplib_response = super().getresponse()
                       ^^^^^^^^^^^^^^^^^^^^^
  File "/usr/local/Cellar/python@3.11/3.11.5/Frameworks/Python.framework/Versions/3.11/lib/python3.11/http/client.py", line 1378, in getresponse
    response.begin()
  File "/usr/local/Cellar/python@3.11/3.11.5/Frameworks/Python.framework/Versions/3.11/lib/python3.11/http/client.py", line 318, in begin
    version, status, reason = self._read_status()
                              ^^^^^^^^^^^^^^^^^^^
  File "/usr/local/Cellar/python@3.11/3.11.5/Frameworks/Python.framework/Versions/3.11/lib/python3.11/http/client.py", line 287, in _read_status
    raise RemoteDisconnected("Remote end closed connection without"
http.client.RemoteDisconnected: Remote end closed connection without response

During handling of the above exception, another exception occurred:

Traceback (most recent call last):
  File "/usr/local/lib/python3.11/site-packages/requests/adapters.py", line 486, in send
    resp = conn.urlopen(
           ^^^^^^^^^^^^^
  File "/usr/local/lib/python3.11/site-packages/urllib3/connectionpool.py", line 844, in urlopen
    retries = retries.increment(
              ^^^^^^^^^^^^^^^^^^
  File "/usr/local/lib/python3.11/site-packages/urllib3/util/retry.py", line 470, in increment
    raise reraise(type(error), error, _stacktrace)
          ^^^^^^^^^^^^^^^^^^^^^^^^^^^^^^^^^^^^^^^^
  File "/usr/local/lib/python3.11/site-packages/urllib3/util/util.py", line 38, in reraise
    raise value.with_traceback(tb)
  File "/usr/local/lib/python3.11/site-packages/urllib3/connectionpool.py", line 790, in urlopen
    response = self._make_request(
               ^^^^^^^^^^^^^^^^^^^
  File "/usr/local/lib/python3.11/site-packages/urllib3/connectionpool.py", line 536, in _make_request
    response = conn.getresponse()
               ^^^^^^^^^^^^^^^^^^
  File "/usr/local/lib/python3.11/site-packages/urllib3/connection.py", line 461, in getresponse
    httplib_response = super().getresponse()
                       ^^^^^^^^^^^^^^^^^^^^^
  File "/usr/local/Cellar/python@3.11/3.11.5/Frameworks/Python.framework/Versions/3.11/lib/python3.11/http/client.py", line 1378, in getresponse
    response.begin()
  File "/usr/local/Cellar/python@3.11/3.11.5/Frameworks/Python.framework/Versions/3.11/lib/python3.11/http/client.py", line 318, in begin
    version, status, reason = self._read_status()
                              ^^^^^^^^^^^^^^^^^^^
  File "/usr/local/Cellar/python@3.11/3.11.5/Frameworks/Python.framework/Versions/3.11/lib/python3.11/http/client.py", line 287, in _read_status
    raise RemoteDisconnected("Remote end closed connection without"
urllib3.exceptions.ProtocolError: ('Connection aborted.', RemoteDisconnected('Remote end closed connection without response'))

During handling of the above exception, another exception occurred:

Traceback (most recent call last):
  File "/Users/hepting/Sites/dhhepting.github.io/script/sharemedia.py", line 75, in <module>
    share = dbx.sharing_create_shared_link(dbp)
            ^^^^^^^^^^^^^^^^^^^^^^^^^^^^^^^^^^^
  File "/usr/local/lib/python3.11/site-packages/dropbox/base.py", line 4553, in sharing_create_shared_link
    r = self.request(
        ^^^^^^^^^^^^^
  File "/usr/local/lib/python3.11/site-packages/dropbox/dropbox_client.py", line 326, in request
    res = self.request_json_string_with_retry(host,
          ^^^^^^^^^^^^^^^^^^^^^^^^^^^^^^^^^^^^^^^^^
  File "/usr/local/lib/python3.11/site-packages/dropbox/dropbox_client.py", line 476, in request_json_string_with_retry
    return self.request_json_string(host,
           ^^^^^^^^^^^^^^^^^^^^^^^^^^^^^^
  File "/usr/local/lib/python3.11/site-packages/dropbox/dropbox_client.py", line 589, in request_json_string
    r = self._session.post(url,
        ^^^^^^^^^^^^^^^^^^^^^^^
  File "/usr/local/lib/python3.11/site-packages/requests/sessions.py", line 637, in post
    return self.request("POST", url, data=data, json=json, **kwargs)
           ^^^^^^^^^^^^^^^^^^^^^^^^^^^^^^^^^^^^^^^^^^^^^^^^^^^^^^^^^
  File "/usr/local/lib/python3.11/site-packages/requests/sessions.py", line 589, in request
    resp = self.send(prep, **send_kwargs)
           ^^^^^^^^^^^^^^^^^^^^^^^^^^^^^^
  File "/usr/local/lib/python3.11/site-packages/requests/sessions.py", line 703, in send
    r = adapter.send(request, **kwargs)
        ^^^^^^^^^^^^^^^^^^^^^^^^^^^^^^^
  File "/usr/local/lib/python3.11/site-packages/requests/adapters.py", line 501, in send
    raise ConnectionError(err, request=request)
requests.exceptions.ConnectionError: ('Connection aborted.', RemoteDisconnected('Remote end closed connection without response'))
2023-09-17 18:00:13.175222
Traceback (most recent call last):
  File "/usr/local/lib/python3.11/site-packages/urllib3/connectionpool.py", line 790, in urlopen
    response = self._make_request(
               ^^^^^^^^^^^^^^^^^^^
  File "/usr/local/lib/python3.11/site-packages/urllib3/connectionpool.py", line 536, in _make_request
    response = conn.getresponse()
               ^^^^^^^^^^^^^^^^^^
  File "/usr/local/lib/python3.11/site-packages/urllib3/connection.py", line 461, in getresponse
    httplib_response = super().getresponse()
                       ^^^^^^^^^^^^^^^^^^^^^
  File "/usr/local/Cellar/python@3.11/3.11.5/Frameworks/Python.framework/Versions/3.11/lib/python3.11/http/client.py", line 1378, in getresponse
    response.begin()
  File "/usr/local/Cellar/python@3.11/3.11.5/Frameworks/Python.framework/Versions/3.11/lib/python3.11/http/client.py", line 318, in begin
    version, status, reason = self._read_status()
                              ^^^^^^^^^^^^^^^^^^^
  File "/usr/local/Cellar/python@3.11/3.11.5/Frameworks/Python.framework/Versions/3.11/lib/python3.11/http/client.py", line 287, in _read_status
    raise RemoteDisconnected("Remote end closed connection without"
http.client.RemoteDisconnected: Remote end closed connection without response

During handling of the above exception, another exception occurred:

Traceback (most recent call last):
  File "/usr/local/lib/python3.11/site-packages/requests/adapters.py", line 486, in send
    resp = conn.urlopen(
           ^^^^^^^^^^^^^
  File "/usr/local/lib/python3.11/site-packages/urllib3/connectionpool.py", line 844, in urlopen
    retries = retries.increment(
              ^^^^^^^^^^^^^^^^^^
  File "/usr/local/lib/python3.11/site-packages/urllib3/util/retry.py", line 470, in increment
    raise reraise(type(error), error, _stacktrace)
          ^^^^^^^^^^^^^^^^^^^^^^^^^^^^^^^^^^^^^^^^
  File "/usr/local/lib/python3.11/site-packages/urllib3/util/util.py", line 38, in reraise
    raise value.with_traceback(tb)
  File "/usr/local/lib/python3.11/site-packages/urllib3/connectionpool.py", line 790, in urlopen
    response = self._make_request(
               ^^^^^^^^^^^^^^^^^^^
  File "/usr/local/lib/python3.11/site-packages/urllib3/connectionpool.py", line 536, in _make_request
    response = conn.getresponse()
               ^^^^^^^^^^^^^^^^^^
  File "/usr/local/lib/python3.11/site-packages/urllib3/connection.py", line 461, in getresponse
    httplib_response = super().getresponse()
                       ^^^^^^^^^^^^^^^^^^^^^
  File "/usr/local/Cellar/python@3.11/3.11.5/Frameworks/Python.framework/Versions/3.11/lib/python3.11/http/client.py", line 1378, in getresponse
    response.begin()
  File "/usr/local/Cellar/python@3.11/3.11.5/Frameworks/Python.framework/Versions/3.11/lib/python3.11/http/client.py", line 318, in begin
    version, status, reason = self._read_status()
                              ^^^^^^^^^^^^^^^^^^^
  File "/usr/local/Cellar/python@3.11/3.11.5/Frameworks/Python.framework/Versions/3.11/lib/python3.11/http/client.py", line 287, in _read_status
    raise RemoteDisconnected("Remote end closed connection without"
urllib3.exceptions.ProtocolError: ('Connection aborted.', RemoteDisconnected('Remote end closed connection without response'))

During handling of the above exception, another exception occurred:

Traceback (most recent call last):
  File "/Users/hepting/Sites/dhhepting.github.io/script/sharemedia.py", line 75, in <module>
    share = dbx.sharing_create_shared_link(dbp)
            ^^^^^^^^^^^^^^^^^^^^^^^^^^^^^^^^^^^
  File "/usr/local/lib/python3.11/site-packages/dropbox/base.py", line 4553, in sharing_create_shared_link
    r = self.request(
        ^^^^^^^^^^^^^
  File "/usr/local/lib/python3.11/site-packages/dropbox/dropbox_client.py", line 326, in request
    res = self.request_json_string_with_retry(host,
          ^^^^^^^^^^^^^^^^^^^^^^^^^^^^^^^^^^^^^^^^^
  File "/usr/local/lib/python3.11/site-packages/dropbox/dropbox_client.py", line 476, in request_json_string_with_retry
    return self.request_json_string(host,
           ^^^^^^^^^^^^^^^^^^^^^^^^^^^^^^
  File "/usr/local/lib/python3.11/site-packages/dropbox/dropbox_client.py", line 589, in request_json_string
    r = self._session.post(url,
        ^^^^^^^^^^^^^^^^^^^^^^^
  File "/usr/local/lib/python3.11/site-packages/requests/sessions.py", line 637, in post
    return self.request("POST", url, data=data, json=json, **kwargs)
           ^^^^^^^^^^^^^^^^^^^^^^^^^^^^^^^^^^^^^^^^^^^^^^^^^^^^^^^^^
  File "/usr/local/lib/python3.11/site-packages/requests/sessions.py", line 589, in request
    resp = self.send(prep, **send_kwargs)
           ^^^^^^^^^^^^^^^^^^^^^^^^^^^^^^
  File "/usr/local/lib/python3.11/site-packages/requests/sessions.py", line 703, in send
    r = adapter.send(request, **kwargs)
        ^^^^^^^^^^^^^^^^^^^^^^^^^^^^^^^
  File "/usr/local/lib/python3.11/site-packages/requests/adapters.py", line 501, in send
    raise ConnectionError(err, request=request)
requests.exceptions.ConnectionError: ('Connection aborted.', RemoteDisconnected('Remote end closed connection without response'))
2023-09-18 12:47:07.291189
2023-09-18 12:51:44.854350
2023-09-18 12:53:22.516718
2023-09-18 17:00:01.918999
2023-09-19 17:00:01.275020
2023-09-20 15:28:59.834977
2023-09-20 17:00:01.956970
