2019-01-10 12:54:25.057202
Traceback (most recent call last):
  File "/Library/Frameworks/Python.framework/Versions/3.6/lib/python3.6/site-packages/urllib3/connection.py", line 141, in _new_conn
    (self.host, self.port), self.timeout, **extra_kw)
  File "/Library/Frameworks/Python.framework/Versions/3.6/lib/python3.6/site-packages/urllib3/util/connection.py", line 60, in create_connection
    for res in socket.getaddrinfo(host, port, family, socket.SOCK_STREAM):
  File "/Library/Frameworks/Python.framework/Versions/3.6/lib/python3.6/socket.py", line 745, in getaddrinfo
    for res in _socket.getaddrinfo(host, port, family, type, proto, flags):
socket.gaierror: [Errno 8] nodename nor servname provided, or not known

During handling of the above exception, another exception occurred:

Traceback (most recent call last):
  File "/Library/Frameworks/Python.framework/Versions/3.6/lib/python3.6/site-packages/urllib3/connectionpool.py", line 601, in urlopen
    chunked=chunked)
  File "/Library/Frameworks/Python.framework/Versions/3.6/lib/python3.6/site-packages/urllib3/connectionpool.py", line 346, in _make_request
    self._validate_conn(conn)
  File "/Library/Frameworks/Python.framework/Versions/3.6/lib/python3.6/site-packages/urllib3/connectionpool.py", line 850, in _validate_conn
    conn.connect()
  File "/Library/Frameworks/Python.framework/Versions/3.6/lib/python3.6/site-packages/urllib3/connection.py", line 284, in connect
    conn = self._new_conn()
  File "/Library/Frameworks/Python.framework/Versions/3.6/lib/python3.6/site-packages/urllib3/connection.py", line 150, in _new_conn
    self, "Failed to establish a new connection: %s" % e)
urllib3.exceptions.NewConnectionError: <urllib3.connection.VerifiedHTTPSConnection object at 0x10e67d470>: Failed to establish a new connection: [Errno 8] nodename nor servname provided, or not known

During handling of the above exception, another exception occurred:

Traceback (most recent call last):
  File "/Library/Frameworks/Python.framework/Versions/3.6/lib/python3.6/site-packages/requests/adapters.py", line 440, in send
    timeout=timeout
  File "/Library/Frameworks/Python.framework/Versions/3.6/lib/python3.6/site-packages/urllib3/connectionpool.py", line 639, in urlopen
    _stacktrace=sys.exc_info()[2])
  File "/Library/Frameworks/Python.framework/Versions/3.6/lib/python3.6/site-packages/urllib3/util/retry.py", line 388, in increment
    raise MaxRetryError(_pool, url, error or ResponseError(cause))
urllib3.exceptions.MaxRetryError: HTTPSConnectionPool(host='api.dropboxapi.com', port=443): Max retries exceeded with url: /2/users/get_current_account (Caused by NewConnectionError('<urllib3.connection.VerifiedHTTPSConnection object at 0x10e67d470>: Failed to establish a new connection: [Errno 8] nodename nor servname provided, or not known',))

During handling of the above exception, another exception occurred:

Traceback (most recent call last):
  File "/Users/hepting/Sites/dhhepting.github.io/script/sharemedia.py", line 53, in <module>
    dbx.users_get_current_account()
  File "/Library/Frameworks/Python.framework/Versions/3.6/lib/python3.6/site-packages/dropbox/base.py", line 4301, in users_get_current_account
    None,
  File "/Library/Frameworks/Python.framework/Versions/3.6/lib/python3.6/site-packages/dropbox/dropbox.py", line 272, in request
    timeout=timeout)
  File "/Library/Frameworks/Python.framework/Versions/3.6/lib/python3.6/site-packages/dropbox/dropbox.py", line 363, in request_json_string_with_retry
    timeout=timeout)
  File "/Library/Frameworks/Python.framework/Versions/3.6/lib/python3.6/site-packages/dropbox/dropbox.py", line 447, in request_json_string
    timeout=timeout,
  File "/Library/Frameworks/Python.framework/Versions/3.6/lib/python3.6/site-packages/requests/sessions.py", line 555, in post
    return self.request('POST', url, data=data, json=json, **kwargs)
  File "/Library/Frameworks/Python.framework/Versions/3.6/lib/python3.6/site-packages/requests/sessions.py", line 508, in request
    resp = self.send(prep, **send_kwargs)
  File "/Library/Frameworks/Python.framework/Versions/3.6/lib/python3.6/site-packages/requests/sessions.py", line 618, in send
    r = adapter.send(request, **kwargs)
  File "/Library/Frameworks/Python.framework/Versions/3.6/lib/python3.6/site-packages/requests/adapters.py", line 508, in send
    raise ConnectionError(e, request=request)
requests.exceptions.ConnectionError: HTTPSConnectionPool(host='api.dropboxapi.com', port=443): Max retries exceeded with url: /2/users/get_current_account (Caused by NewConnectionError('<urllib3.connection.VerifiedHTTPSConnection object at 0x10e67d470>: Failed to establish a new connection: [Errno 8] nodename nor servname provided, or not known',))
2019-01-14 00:04:40.186723
2019-01-14 00:05:56.299741
2019-01-14 00:06:09.591956
2019-01-14 00:07:38.594371
2019-01-14 00:11:11.261508
2019-01-15 00:00:03.934002
2019-01-15 00:00:22.933164
2019-01-15 13:01:44.946700
2019-01-16 14:01:19.476979
2019-01-16 14:08:14.436826
2019-01-18 13:54:27.477559
2019-01-18 13:55:53.047039
2019-01-21 11:03:03.203537
Traceback (most recent call last):
  File "/Library/Frameworks/Python.framework/Versions/3.6/lib/python3.6/site-packages/urllib3/connection.py", line 141, in _new_conn
    (self.host, self.port), self.timeout, **extra_kw)
  File "/Library/Frameworks/Python.framework/Versions/3.6/lib/python3.6/site-packages/urllib3/util/connection.py", line 60, in create_connection
    for res in socket.getaddrinfo(host, port, family, socket.SOCK_STREAM):
  File "/Library/Frameworks/Python.framework/Versions/3.6/lib/python3.6/socket.py", line 745, in getaddrinfo
    for res in _socket.getaddrinfo(host, port, family, type, proto, flags):
socket.gaierror: [Errno 8] nodename nor servname provided, or not known

During handling of the above exception, another exception occurred:

Traceback (most recent call last):
  File "/Library/Frameworks/Python.framework/Versions/3.6/lib/python3.6/site-packages/urllib3/connectionpool.py", line 601, in urlopen
    chunked=chunked)
  File "/Library/Frameworks/Python.framework/Versions/3.6/lib/python3.6/site-packages/urllib3/connectionpool.py", line 346, in _make_request
    self._validate_conn(conn)
  File "/Library/Frameworks/Python.framework/Versions/3.6/lib/python3.6/site-packages/urllib3/connectionpool.py", line 850, in _validate_conn
    conn.connect()
  File "/Library/Frameworks/Python.framework/Versions/3.6/lib/python3.6/site-packages/urllib3/connection.py", line 284, in connect
    conn = self._new_conn()
  File "/Library/Frameworks/Python.framework/Versions/3.6/lib/python3.6/site-packages/urllib3/connection.py", line 150, in _new_conn
    self, "Failed to establish a new connection: %s" % e)
urllib3.exceptions.NewConnectionError: <urllib3.connection.VerifiedHTTPSConnection object at 0x10e535e48>: Failed to establish a new connection: [Errno 8] nodename nor servname provided, or not known

During handling of the above exception, another exception occurred:

Traceback (most recent call last):
  File "/Library/Frameworks/Python.framework/Versions/3.6/lib/python3.6/site-packages/requests/adapters.py", line 440, in send
    timeout=timeout
  File "/Library/Frameworks/Python.framework/Versions/3.6/lib/python3.6/site-packages/urllib3/connectionpool.py", line 639, in urlopen
    _stacktrace=sys.exc_info()[2])
  File "/Library/Frameworks/Python.framework/Versions/3.6/lib/python3.6/site-packages/urllib3/util/retry.py", line 388, in increment
    raise MaxRetryError(_pool, url, error or ResponseError(cause))
urllib3.exceptions.MaxRetryError: HTTPSConnectionPool(host='api.dropboxapi.com', port=443): Max retries exceeded with url: /2/users/get_current_account (Caused by NewConnectionError('<urllib3.connection.VerifiedHTTPSConnection object at 0x10e535e48>: Failed to establish a new connection: [Errno 8] nodename nor servname provided, or not known',))

During handling of the above exception, another exception occurred:

Traceback (most recent call last):
  File "/Users/hepting/Sites/dhhepting.github.io/script/sharemedia.py", line 53, in <module>
    dbx.users_get_current_account()
  File "/Library/Frameworks/Python.framework/Versions/3.6/lib/python3.6/site-packages/dropbox/base.py", line 4301, in users_get_current_account
    None,
  File "/Library/Frameworks/Python.framework/Versions/3.6/lib/python3.6/site-packages/dropbox/dropbox.py", line 272, in request
    timeout=timeout)
  File "/Library/Frameworks/Python.framework/Versions/3.6/lib/python3.6/site-packages/dropbox/dropbox.py", line 363, in request_json_string_with_retry
    timeout=timeout)
  File "/Library/Frameworks/Python.framework/Versions/3.6/lib/python3.6/site-packages/dropbox/dropbox.py", line 447, in request_json_string
    timeout=timeout,
  File "/Library/Frameworks/Python.framework/Versions/3.6/lib/python3.6/site-packages/requests/sessions.py", line 555, in post
    return self.request('POST', url, data=data, json=json, **kwargs)
  File "/Library/Frameworks/Python.framework/Versions/3.6/lib/python3.6/site-packages/requests/sessions.py", line 508, in request
    resp = self.send(prep, **send_kwargs)
  File "/Library/Frameworks/Python.framework/Versions/3.6/lib/python3.6/site-packages/requests/sessions.py", line 618, in send
    r = adapter.send(request, **kwargs)
  File "/Library/Frameworks/Python.framework/Versions/3.6/lib/python3.6/site-packages/requests/adapters.py", line 508, in send
    raise ConnectionError(e, request=request)
requests.exceptions.ConnectionError: HTTPSConnectionPool(host='api.dropboxapi.com', port=443): Max retries exceeded with url: /2/users/get_current_account (Caused by NewConnectionError('<urllib3.connection.VerifiedHTTPSConnection object at 0x10e535e48>: Failed to establish a new connection: [Errno 8] nodename nor servname provided, or not known',))
2019-01-21 14:15:06.826347
2019-01-21 14:16:36.632628
2019-01-23 14:12:50.850015
2019-01-23 14:15:29.750330
2019-01-23 15:03:07.651645
2019-01-25 13:55:38.152382
2019-01-25 14:08:41.584631
2019-01-28 12:19:44.246129
2019-01-28 13:47:30.547551
2019-01-28 13:50:02.800823
2019-01-28 13:51:38.300506
2019-01-30 15:38:51.988195
2019-01-30 15:44:12.214429
2019-02-04 13:48:43.392441
2019-02-04 13:57:53.721263
2019-02-06 14:00:47.591925
2019-02-06 14:04:22.279282
2019-02-09 00:22:26.028290
2019-02-09 00:26:33.000314
2019-02-09 00:30:29.808295
2019-02-11 15:17:20.370366
2019-02-12 22:53:57.265592
2019-02-13 21:47:39.552643
2019-02-13 21:50:17.735239
2019-02-17 12:55:20.733065
2019-02-17 12:56:06.407367
2019-02-17 12:57:02.567912
2019-02-17 12:58:01.391989
2019-02-17 12:59:01.625693
2019-02-17 13:00:01.344933
2019-02-17 13:01:01.267913
2019-02-17 13:02:01.375157
2019-02-17 13:03:01.733341
2019-02-17 13:04:02.430423
2019-02-17 13:05:08.096357
2019-02-17 13:06:02.210778
2019-02-17 13:07:01.559096
2019-02-17 13:08:02.967972
2019-02-17 13:09:01.620305
2019-02-17 13:10:01.706376
2019-02-17 13:11:01.501013
2019-02-17 13:12:01.711716
2019-02-17 13:13:01.716015
2019-02-17 13:14:01.780214
2019-02-17 13:15:02.262296
2019-02-17 13:16:01.717480
Traceback (most recent call last):
  File "/Library/Frameworks/Python.framework/Versions/3.6/lib/python3.6/site-packages/urllib3/connection.py", line 141, in _new_conn
    (self.host, self.port), self.timeout, **extra_kw)
  File "/Library/Frameworks/Python.framework/Versions/3.6/lib/python3.6/site-packages/urllib3/util/connection.py", line 60, in create_connection
    for res in socket.getaddrinfo(host, port, family, socket.SOCK_STREAM):
  File "/Library/Frameworks/Python.framework/Versions/3.6/lib/python3.6/socket.py", line 745, in getaddrinfo
    for res in _socket.getaddrinfo(host, port, family, type, proto, flags):
socket.gaierror: [Errno 8] nodename nor servname provided, or not known

During handling of the above exception, another exception occurred:

Traceback (most recent call last):
  File "/Library/Frameworks/Python.framework/Versions/3.6/lib/python3.6/site-packages/urllib3/connectionpool.py", line 601, in urlopen
    chunked=chunked)
  File "/Library/Frameworks/Python.framework/Versions/3.6/lib/python3.6/site-packages/urllib3/connectionpool.py", line 346, in _make_request
    self._validate_conn(conn)
  File "/Library/Frameworks/Python.framework/Versions/3.6/lib/python3.6/site-packages/urllib3/connectionpool.py", line 850, in _validate_conn
    conn.connect()
  File "/Library/Frameworks/Python.framework/Versions/3.6/lib/python3.6/site-packages/urllib3/connection.py", line 284, in connect
    conn = self._new_conn()
  File "/Library/Frameworks/Python.framework/Versions/3.6/lib/python3.6/site-packages/urllib3/connection.py", line 150, in _new_conn
    self, "Failed to establish a new connection: %s" % e)
urllib3.exceptions.NewConnectionError: <urllib3.connection.VerifiedHTTPSConnection object at 0x10e632fd0>: Failed to establish a new connection: [Errno 8] nodename nor servname provided, or not known

During handling of the above exception, another exception occurred:

Traceback (most recent call last):
  File "/Library/Frameworks/Python.framework/Versions/3.6/lib/python3.6/site-packages/requests/adapters.py", line 440, in send
    timeout=timeout
  File "/Library/Frameworks/Python.framework/Versions/3.6/lib/python3.6/site-packages/urllib3/connectionpool.py", line 639, in urlopen
    _stacktrace=sys.exc_info()[2])
  File "/Library/Frameworks/Python.framework/Versions/3.6/lib/python3.6/site-packages/urllib3/util/retry.py", line 388, in increment
    raise MaxRetryError(_pool, url, error or ResponseError(cause))
urllib3.exceptions.MaxRetryError: HTTPSConnectionPool(host='api.dropboxapi.com', port=443): Max retries exceeded with url: /2/users/get_current_account (Caused by NewConnectionError('<urllib3.connection.VerifiedHTTPSConnection object at 0x10e632fd0>: Failed to establish a new connection: [Errno 8] nodename nor servname provided, or not known',))

During handling of the above exception, another exception occurred:

Traceback (most recent call last):
  File "/Users/hepting/Sites/dhhepting.github.io/script/sharemedia.py", line 53, in <module>
    dbx.users_get_current_account()
  File "/Library/Frameworks/Python.framework/Versions/3.6/lib/python3.6/site-packages/dropbox/base.py", line 4301, in users_get_current_account
    None,
  File "/Library/Frameworks/Python.framework/Versions/3.6/lib/python3.6/site-packages/dropbox/dropbox.py", line 272, in request
    timeout=timeout)
  File "/Library/Frameworks/Python.framework/Versions/3.6/lib/python3.6/site-packages/dropbox/dropbox.py", line 363, in request_json_string_with_retry
    timeout=timeout)
  File "/Library/Frameworks/Python.framework/Versions/3.6/lib/python3.6/site-packages/dropbox/dropbox.py", line 447, in request_json_string
    timeout=timeout,
  File "/Library/Frameworks/Python.framework/Versions/3.6/lib/python3.6/site-packages/requests/sessions.py", line 555, in post
    return self.request('POST', url, data=data, json=json, **kwargs)
  File "/Library/Frameworks/Python.framework/Versions/3.6/lib/python3.6/site-packages/requests/sessions.py", line 508, in request
    resp = self.send(prep, **send_kwargs)
  File "/Library/Frameworks/Python.framework/Versions/3.6/lib/python3.6/site-packages/requests/sessions.py", line 618, in send
    r = adapter.send(request, **kwargs)
  File "/Library/Frameworks/Python.framework/Versions/3.6/lib/python3.6/site-packages/requests/adapters.py", line 508, in send
    raise ConnectionError(e, request=request)
requests.exceptions.ConnectionError: HTTPSConnectionPool(host='api.dropboxapi.com', port=443): Max retries exceeded with url: /2/users/get_current_account (Caused by NewConnectionError('<urllib3.connection.VerifiedHTTPSConnection object at 0x10e632fd0>: Failed to establish a new connection: [Errno 8] nodename nor servname provided, or not known',))
2019-02-17 14:02:01.762900
2019-02-17 14:03:01.279358
2019-02-17 14:04:01.837565
2019-02-17 14:05:01.918627
2019-02-17 14:06:02.490472
2019-02-17 14:07:01.830949
2019-02-17 14:08:01.846641
2019-02-17 14:09:01.958518
2019-02-17 14:10:02.455462
2019-02-17 14:11:01.731404
2019-02-17 14:12:02.314058
2019-02-17 14:13:01.740608
2019-02-17 14:14:01.543054
2019-02-17 14:15:01.684475
2019-02-17 14:16:01.678815
2019-02-17 14:17:01.501010
2019-02-17 14:18:01.471547
2019-02-17 14:19:01.622976
2019-02-17 14:20:01.854182
2019-02-17 14:21:03.214779
2019-02-17 14:22:01.676858
2019-02-17 14:23:01.543157
2019-02-17 14:24:01.526437
2019-02-17 14:25:02.097461
2019-02-17 14:26:01.604697
2019-02-17 14:27:02.514303
2019-02-17 14:28:02.066871
2019-02-17 14:29:01.461743
2019-02-17 14:30:02.550890
2019-02-17 14:31:02.242978
2019-02-17 14:32:01.696556
2019-02-17 14:33:02.519810
2019-02-17 14:34:00.953159
2019-02-17 14:35:00.848699
2019-02-17 14:36:01.297334
2019-02-17 14:37:01.809123
2019-02-17 14:38:02.124747
2019-02-17 14:39:00.970625
2019-02-17 14:40:01.877298
2019-02-17 14:41:02.396320
2019-02-17 14:42:02.390620
2019-02-17 14:43:00.813514
2019-02-17 14:44:00.713961
2019-02-17 14:45:00.552198
2019-02-17 14:46:00.694240
2019-02-17 17:46:59.426138
Traceback (most recent call last):
  File "/Library/Frameworks/Python.framework/Versions/3.6/lib/python3.6/site-packages/urllib3/connection.py", line 141, in _new_conn
    (self.host, self.port), self.timeout, **extra_kw)
  File "/Library/Frameworks/Python.framework/Versions/3.6/lib/python3.6/site-packages/urllib3/util/connection.py", line 60, in create_connection
    for res in socket.getaddrinfo(host, port, family, socket.SOCK_STREAM):
  File "/Library/Frameworks/Python.framework/Versions/3.6/lib/python3.6/socket.py", line 745, in getaddrinfo
    for res in _socket.getaddrinfo(host, port, family, type, proto, flags):
socket.gaierror: [Errno 8] nodename nor servname provided, or not known

During handling of the above exception, another exception occurred:

Traceback (most recent call last):
  File "/Library/Frameworks/Python.framework/Versions/3.6/lib/python3.6/site-packages/urllib3/connectionpool.py", line 601, in urlopen
    chunked=chunked)
  File "/Library/Frameworks/Python.framework/Versions/3.6/lib/python3.6/site-packages/urllib3/connectionpool.py", line 346, in _make_request
    self._validate_conn(conn)
  File "/Library/Frameworks/Python.framework/Versions/3.6/lib/python3.6/site-packages/urllib3/connectionpool.py", line 850, in _validate_conn
    conn.connect()
  File "/Library/Frameworks/Python.framework/Versions/3.6/lib/python3.6/site-packages/urllib3/connection.py", line 284, in connect
    conn = self._new_conn()
  File "/Library/Frameworks/Python.framework/Versions/3.6/lib/python3.6/site-packages/urllib3/connection.py", line 150, in _new_conn
    self, "Failed to establish a new connection: %s" % e)
urllib3.exceptions.NewConnectionError: <urllib3.connection.VerifiedHTTPSConnection object at 0x10e6325f8>: Failed to establish a new connection: [Errno 8] nodename nor servname provided, or not known

During handling of the above exception, another exception occurred:

Traceback (most recent call last):
  File "/Library/Frameworks/Python.framework/Versions/3.6/lib/python3.6/site-packages/requests/adapters.py", line 440, in send
    timeout=timeout
  File "/Library/Frameworks/Python.framework/Versions/3.6/lib/python3.6/site-packages/urllib3/connectionpool.py", line 639, in urlopen
    _stacktrace=sys.exc_info()[2])
  File "/Library/Frameworks/Python.framework/Versions/3.6/lib/python3.6/site-packages/urllib3/util/retry.py", line 388, in increment
    raise MaxRetryError(_pool, url, error or ResponseError(cause))
urllib3.exceptions.MaxRetryError: HTTPSConnectionPool(host='api.dropboxapi.com', port=443): Max retries exceeded with url: /2/users/get_current_account (Caused by NewConnectionError('<urllib3.connection.VerifiedHTTPSConnection object at 0x10e6325f8>: Failed to establish a new connection: [Errno 8] nodename nor servname provided, or not known',))

During handling of the above exception, another exception occurred:

Traceback (most recent call last):
  File "/Users/hepting/Sites/dhhepting.github.io/script/sharemedia.py", line 53, in <module>
    dbx.users_get_current_account()
  File "/Library/Frameworks/Python.framework/Versions/3.6/lib/python3.6/site-packages/dropbox/base.py", line 4301, in users_get_current_account
    None,
  File "/Library/Frameworks/Python.framework/Versions/3.6/lib/python3.6/site-packages/dropbox/dropbox.py", line 272, in request
    timeout=timeout)
  File "/Library/Frameworks/Python.framework/Versions/3.6/lib/python3.6/site-packages/dropbox/dropbox.py", line 363, in request_json_string_with_retry
    timeout=timeout)
  File "/Library/Frameworks/Python.framework/Versions/3.6/lib/python3.6/site-packages/dropbox/dropbox.py", line 447, in request_json_string
    timeout=timeout,
  File "/Library/Frameworks/Python.framework/Versions/3.6/lib/python3.6/site-packages/requests/sessions.py", line 555, in post
    return self.request('POST', url, data=data, json=json, **kwargs)
  File "/Library/Frameworks/Python.framework/Versions/3.6/lib/python3.6/site-packages/requests/sessions.py", line 508, in request
    resp = self.send(prep, **send_kwargs)
  File "/Library/Frameworks/Python.framework/Versions/3.6/lib/python3.6/site-packages/requests/sessions.py", line 618, in send
    r = adapter.send(request, **kwargs)
  File "/Library/Frameworks/Python.framework/Versions/3.6/lib/python3.6/site-packages/requests/adapters.py", line 508, in send
    raise ConnectionError(e, request=request)
requests.exceptions.ConnectionError: HTTPSConnectionPool(host='api.dropboxapi.com', port=443): Max retries exceeded with url: /2/users/get_current_account (Caused by NewConnectionError('<urllib3.connection.VerifiedHTTPSConnection object at 0x10e6325f8>: Failed to establish a new connection: [Errno 8] nodename nor servname provided, or not known',))
2019-02-18 08:18:05.754903
Traceback (most recent call last):
  File "/Library/Frameworks/Python.framework/Versions/3.6/lib/python3.6/site-packages/urllib3/connectionpool.py", line 387, in _make_request
    six.raise_from(e, None)
  File "<string>", line 2, in raise_from
  File "/Library/Frameworks/Python.framework/Versions/3.6/lib/python3.6/site-packages/urllib3/connectionpool.py", line 383, in _make_request
    httplib_response = conn.getresponse()
  File "/Library/Frameworks/Python.framework/Versions/3.6/lib/python3.6/http/client.py", line 1331, in getresponse
    response.begin()
  File "/Library/Frameworks/Python.framework/Versions/3.6/lib/python3.6/http/client.py", line 297, in begin
    version, status, reason = self._read_status()
  File "/Library/Frameworks/Python.framework/Versions/3.6/lib/python3.6/http/client.py", line 258, in _read_status
    line = str(self.fp.readline(_MAXLINE + 1), "iso-8859-1")
  File "/Library/Frameworks/Python.framework/Versions/3.6/lib/python3.6/socket.py", line 586, in readinto
    return self._sock.recv_into(b)
  File "/Library/Frameworks/Python.framework/Versions/3.6/lib/python3.6/ssl.py", line 1009, in recv_into
    return self.read(nbytes, buffer)
  File "/Library/Frameworks/Python.framework/Versions/3.6/lib/python3.6/ssl.py", line 871, in read
    return self._sslobj.read(len, buffer)
  File "/Library/Frameworks/Python.framework/Versions/3.6/lib/python3.6/ssl.py", line 631, in read
    v = self._sslobj.read(len, buffer)
socket.timeout: The read operation timed out

During handling of the above exception, another exception occurred:

Traceback (most recent call last):
  File "/Library/Frameworks/Python.framework/Versions/3.6/lib/python3.6/site-packages/requests/adapters.py", line 440, in send
    timeout=timeout
  File "/Library/Frameworks/Python.framework/Versions/3.6/lib/python3.6/site-packages/urllib3/connectionpool.py", line 639, in urlopen
    _stacktrace=sys.exc_info()[2])
  File "/Library/Frameworks/Python.framework/Versions/3.6/lib/python3.6/site-packages/urllib3/util/retry.py", line 357, in increment
    raise six.reraise(type(error), error, _stacktrace)
  File "/Library/Frameworks/Python.framework/Versions/3.6/lib/python3.6/site-packages/urllib3/packages/six.py", line 686, in reraise
    raise value
  File "/Library/Frameworks/Python.framework/Versions/3.6/lib/python3.6/site-packages/urllib3/connectionpool.py", line 601, in urlopen
    chunked=chunked)
  File "/Library/Frameworks/Python.framework/Versions/3.6/lib/python3.6/site-packages/urllib3/connectionpool.py", line 389, in _make_request
    self._raise_timeout(err=e, url=url, timeout_value=read_timeout)
  File "/Library/Frameworks/Python.framework/Versions/3.6/lib/python3.6/site-packages/urllib3/connectionpool.py", line 309, in _raise_timeout
    raise ReadTimeoutError(self, url, "Read timed out. (read timeout=%s)" % timeout_value)
urllib3.exceptions.ReadTimeoutError: HTTPSConnectionPool(host='api.dropboxapi.com', port=443): Read timed out. (read timeout=30)

During handling of the above exception, another exception occurred:

Traceback (most recent call last):
  File "/Users/hepting/Sites/dhhepting.github.io/script/sharemedia.py", line 71, in <module>
    share = dbx.sharing_create_shared_link(dbp)
  File "/Library/Frameworks/Python.framework/Versions/3.6/lib/python3.6/site-packages/dropbox/base.py", line 3095, in sharing_create_shared_link
    None,
  File "/Library/Frameworks/Python.framework/Versions/3.6/lib/python3.6/site-packages/dropbox/dropbox.py", line 272, in request
    timeout=timeout)
  File "/Library/Frameworks/Python.framework/Versions/3.6/lib/python3.6/site-packages/dropbox/dropbox.py", line 363, in request_json_string_with_retry
    timeout=timeout)
  File "/Library/Frameworks/Python.framework/Versions/3.6/lib/python3.6/site-packages/dropbox/dropbox.py", line 447, in request_json_string
    timeout=timeout,
  File "/Library/Frameworks/Python.framework/Versions/3.6/lib/python3.6/site-packages/requests/sessions.py", line 555, in post
    return self.request('POST', url, data=data, json=json, **kwargs)
  File "/Library/Frameworks/Python.framework/Versions/3.6/lib/python3.6/site-packages/requests/sessions.py", line 508, in request
    resp = self.send(prep, **send_kwargs)
  File "/Library/Frameworks/Python.framework/Versions/3.6/lib/python3.6/site-packages/requests/sessions.py", line 618, in send
    r = adapter.send(request, **kwargs)
  File "/Library/Frameworks/Python.framework/Versions/3.6/lib/python3.6/site-packages/requests/adapters.py", line 521, in send
    raise ReadTimeout(e, request=request)
requests.exceptions.ReadTimeout: HTTPSConnectionPool(host='api.dropboxapi.com', port=443): Read timed out. (read timeout=30)
2019-02-18 12:25:31.577615
2019-02-18 12:27:01.525089
2019-02-18 12:28:01.137809
2019-02-18 12:29:00.953842
2019-02-18 12:30:01.238347
2019-02-18 12:31:01.122286
2019-02-18 12:32:00.867154
2019-02-18 12:33:00.955020
2019-02-18 12:34:00.915952
2019-02-18 12:35:00.933216
2019-02-18 12:36:01.115933
Traceback (most recent call last):
  File "/Library/Frameworks/Python.framework/Versions/3.6/lib/python3.6/site-packages/urllib3/connectionpool.py", line 601, in urlopen
    chunked=chunked)
  File "/Library/Frameworks/Python.framework/Versions/3.6/lib/python3.6/site-packages/urllib3/connectionpool.py", line 387, in _make_request
    six.raise_from(e, None)
  File "<string>", line 2, in raise_from
  File "/Library/Frameworks/Python.framework/Versions/3.6/lib/python3.6/site-packages/urllib3/connectionpool.py", line 383, in _make_request
    httplib_response = conn.getresponse()
  File "/Library/Frameworks/Python.framework/Versions/3.6/lib/python3.6/http/client.py", line 1331, in getresponse
    response.begin()
  File "/Library/Frameworks/Python.framework/Versions/3.6/lib/python3.6/http/client.py", line 297, in begin
    version, status, reason = self._read_status()
  File "/Library/Frameworks/Python.framework/Versions/3.6/lib/python3.6/http/client.py", line 258, in _read_status
    line = str(self.fp.readline(_MAXLINE + 1), "iso-8859-1")
  File "/Library/Frameworks/Python.framework/Versions/3.6/lib/python3.6/socket.py", line 586, in readinto
    return self._sock.recv_into(b)
  File "/Library/Frameworks/Python.framework/Versions/3.6/lib/python3.6/ssl.py", line 1009, in recv_into
    return self.read(nbytes, buffer)
  File "/Library/Frameworks/Python.framework/Versions/3.6/lib/python3.6/ssl.py", line 871, in read
    return self._sslobj.read(len, buffer)
  File "/Library/Frameworks/Python.framework/Versions/3.6/lib/python3.6/ssl.py", line 631, in read
    v = self._sslobj.read(len, buffer)
ConnectionResetError: [Errno 54] Connection reset by peer

During handling of the above exception, another exception occurred:

Traceback (most recent call last):
  File "/Library/Frameworks/Python.framework/Versions/3.6/lib/python3.6/site-packages/requests/adapters.py", line 440, in send
    timeout=timeout
  File "/Library/Frameworks/Python.framework/Versions/3.6/lib/python3.6/site-packages/urllib3/connectionpool.py", line 639, in urlopen
    _stacktrace=sys.exc_info()[2])
  File "/Library/Frameworks/Python.framework/Versions/3.6/lib/python3.6/site-packages/urllib3/util/retry.py", line 357, in increment
    raise six.reraise(type(error), error, _stacktrace)
  File "/Library/Frameworks/Python.framework/Versions/3.6/lib/python3.6/site-packages/urllib3/packages/six.py", line 685, in reraise
    raise value.with_traceback(tb)
  File "/Library/Frameworks/Python.framework/Versions/3.6/lib/python3.6/site-packages/urllib3/connectionpool.py", line 601, in urlopen
    chunked=chunked)
  File "/Library/Frameworks/Python.framework/Versions/3.6/lib/python3.6/site-packages/urllib3/connectionpool.py", line 387, in _make_request
    six.raise_from(e, None)
  File "<string>", line 2, in raise_from
  File "/Library/Frameworks/Python.framework/Versions/3.6/lib/python3.6/site-packages/urllib3/connectionpool.py", line 383, in _make_request
    httplib_response = conn.getresponse()
  File "/Library/Frameworks/Python.framework/Versions/3.6/lib/python3.6/http/client.py", line 1331, in getresponse
    response.begin()
  File "/Library/Frameworks/Python.framework/Versions/3.6/lib/python3.6/http/client.py", line 297, in begin
    version, status, reason = self._read_status()
  File "/Library/Frameworks/Python.framework/Versions/3.6/lib/python3.6/http/client.py", line 258, in _read_status
    line = str(self.fp.readline(_MAXLINE + 1), "iso-8859-1")
  File "/Library/Frameworks/Python.framework/Versions/3.6/lib/python3.6/socket.py", line 586, in readinto
    return self._sock.recv_into(b)
  File "/Library/Frameworks/Python.framework/Versions/3.6/lib/python3.6/ssl.py", line 1009, in recv_into
    return self.read(nbytes, buffer)
  File "/Library/Frameworks/Python.framework/Versions/3.6/lib/python3.6/ssl.py", line 871, in read
    return self._sslobj.read(len, buffer)
  File "/Library/Frameworks/Python.framework/Versions/3.6/lib/python3.6/ssl.py", line 631, in read
    v = self._sslobj.read(len, buffer)
urllib3.exceptions.ProtocolError: ('Connection aborted.', ConnectionResetError(54, 'Connection reset by peer'))

During handling of the above exception, another exception occurred:

Traceback (most recent call last):
  File "/Users/hepting/Sites/dhhepting.github.io/script/sharemedia.py", line 71, in <module>
    share = dbx.sharing_create_shared_link(dbp)
  File "/Library/Frameworks/Python.framework/Versions/3.6/lib/python3.6/site-packages/dropbox/base.py", line 3095, in sharing_create_shared_link
    None,
  File "/Library/Frameworks/Python.framework/Versions/3.6/lib/python3.6/site-packages/dropbox/dropbox.py", line 272, in request
    timeout=timeout)
  File "/Library/Frameworks/Python.framework/Versions/3.6/lib/python3.6/site-packages/dropbox/dropbox.py", line 363, in request_json_string_with_retry
    timeout=timeout)
  File "/Library/Frameworks/Python.framework/Versions/3.6/lib/python3.6/site-packages/dropbox/dropbox.py", line 447, in request_json_string
    timeout=timeout,
  File "/Library/Frameworks/Python.framework/Versions/3.6/lib/python3.6/site-packages/requests/sessions.py", line 555, in post
    return self.request('POST', url, data=data, json=json, **kwargs)
  File "/Library/Frameworks/Python.framework/Versions/3.6/lib/python3.6/site-packages/requests/sessions.py", line 508, in request
    resp = self.send(prep, **send_kwargs)
  File "/Library/Frameworks/Python.framework/Versions/3.6/lib/python3.6/site-packages/requests/sessions.py", line 618, in send
    r = adapter.send(request, **kwargs)
  File "/Library/Frameworks/Python.framework/Versions/3.6/lib/python3.6/site-packages/requests/adapters.py", line 490, in send
    raise ConnectionError(err, request=request)
requests.exceptions.ConnectionError: ('Connection aborted.', ConnectionResetError(54, 'Connection reset by peer'))
2019-02-18 18:24:37.665257
2019-02-18 18:26:00.993084
2019-02-18 18:27:00.705933
2019-02-18 18:28:00.918744
2019-02-18 18:29:01.171288
2019-02-18 18:30:01.261511
2019-02-18 18:31:01.100465
2019-02-18 18:32:50.833122
2019-02-19 14:00:10.179209
2019-02-20 14:00:05.221772
2019-02-21 14:11:15.415845
Traceback (most recent call last):
  File "/Library/Frameworks/Python.framework/Versions/3.6/lib/python3.6/site-packages/urllib3/connection.py", line 141, in _new_conn
    (self.host, self.port), self.timeout, **extra_kw)
  File "/Library/Frameworks/Python.framework/Versions/3.6/lib/python3.6/site-packages/urllib3/util/connection.py", line 60, in create_connection
    for res in socket.getaddrinfo(host, port, family, socket.SOCK_STREAM):
  File "/Library/Frameworks/Python.framework/Versions/3.6/lib/python3.6/socket.py", line 745, in getaddrinfo
    for res in _socket.getaddrinfo(host, port, family, type, proto, flags):
socket.gaierror: [Errno 8] nodename nor servname provided, or not known

During handling of the above exception, another exception occurred:

Traceback (most recent call last):
  File "/Library/Frameworks/Python.framework/Versions/3.6/lib/python3.6/site-packages/urllib3/connectionpool.py", line 601, in urlopen
    chunked=chunked)
  File "/Library/Frameworks/Python.framework/Versions/3.6/lib/python3.6/site-packages/urllib3/connectionpool.py", line 346, in _make_request
    self._validate_conn(conn)
  File "/Library/Frameworks/Python.framework/Versions/3.6/lib/python3.6/site-packages/urllib3/connectionpool.py", line 850, in _validate_conn
    conn.connect()
  File "/Library/Frameworks/Python.framework/Versions/3.6/lib/python3.6/site-packages/urllib3/connection.py", line 284, in connect
    conn = self._new_conn()
  File "/Library/Frameworks/Python.framework/Versions/3.6/lib/python3.6/site-packages/urllib3/connection.py", line 150, in _new_conn
    self, "Failed to establish a new connection: %s" % e)
urllib3.exceptions.NewConnectionError: <urllib3.connection.VerifiedHTTPSConnection object at 0x10e637470>: Failed to establish a new connection: [Errno 8] nodename nor servname provided, or not known

During handling of the above exception, another exception occurred:

Traceback (most recent call last):
  File "/Library/Frameworks/Python.framework/Versions/3.6/lib/python3.6/site-packages/requests/adapters.py", line 440, in send
    timeout=timeout
  File "/Library/Frameworks/Python.framework/Versions/3.6/lib/python3.6/site-packages/urllib3/connectionpool.py", line 639, in urlopen
    _stacktrace=sys.exc_info()[2])
  File "/Library/Frameworks/Python.framework/Versions/3.6/lib/python3.6/site-packages/urllib3/util/retry.py", line 388, in increment
    raise MaxRetryError(_pool, url, error or ResponseError(cause))
urllib3.exceptions.MaxRetryError: HTTPSConnectionPool(host='api.dropboxapi.com', port=443): Max retries exceeded with url: /2/users/get_current_account (Caused by NewConnectionError('<urllib3.connection.VerifiedHTTPSConnection object at 0x10e637470>: Failed to establish a new connection: [Errno 8] nodename nor servname provided, or not known',))

During handling of the above exception, another exception occurred:

Traceback (most recent call last):
  File "/Users/hepting/Sites/dhhepting.github.io/script/sharemedia.py", line 53, in <module>
    dbx.users_get_current_account()
  File "/Library/Frameworks/Python.framework/Versions/3.6/lib/python3.6/site-packages/dropbox/base.py", line 4301, in users_get_current_account
    None,
  File "/Library/Frameworks/Python.framework/Versions/3.6/lib/python3.6/site-packages/dropbox/dropbox.py", line 272, in request
    timeout=timeout)
  File "/Library/Frameworks/Python.framework/Versions/3.6/lib/python3.6/site-packages/dropbox/dropbox.py", line 363, in request_json_string_with_retry
    timeout=timeout)
  File "/Library/Frameworks/Python.framework/Versions/3.6/lib/python3.6/site-packages/dropbox/dropbox.py", line 447, in request_json_string
    timeout=timeout,
  File "/Library/Frameworks/Python.framework/Versions/3.6/lib/python3.6/site-packages/requests/sessions.py", line 555, in post
    return self.request('POST', url, data=data, json=json, **kwargs)
  File "/Library/Frameworks/Python.framework/Versions/3.6/lib/python3.6/site-packages/requests/sessions.py", line 508, in request
    resp = self.send(prep, **send_kwargs)
  File "/Library/Frameworks/Python.framework/Versions/3.6/lib/python3.6/site-packages/requests/sessions.py", line 618, in send
    r = adapter.send(request, **kwargs)
  File "/Library/Frameworks/Python.framework/Versions/3.6/lib/python3.6/site-packages/requests/adapters.py", line 508, in send
    raise ConnectionError(e, request=request)
requests.exceptions.ConnectionError: HTTPSConnectionPool(host='api.dropboxapi.com', port=443): Max retries exceeded with url: /2/users/get_current_account (Caused by NewConnectionError('<urllib3.connection.VerifiedHTTPSConnection object at 0x10e637470>: Failed to establish a new connection: [Errno 8] nodename nor servname provided, or not known',))
2019-02-22 14:20:17.788323
2019-02-23 14:00:09.565127
2019-02-24 14:00:05.273540
2019-02-25 14:00:03.913709
2019-02-25 23:06:03.805694
2019-02-26 14:00:07.567010
2019-02-27 14:00:05.165378
2019-02-28 10:33:42.375724
2019-02-28 12:58:19.312710
Traceback (most recent call last):
  File "/Library/Frameworks/Python.framework/Versions/3.6/lib/python3.6/site-packages/urllib3/connection.py", line 141, in _new_conn
    (self.host, self.port), self.timeout, **extra_kw)
  File "/Library/Frameworks/Python.framework/Versions/3.6/lib/python3.6/site-packages/urllib3/util/connection.py", line 60, in create_connection
    for res in socket.getaddrinfo(host, port, family, socket.SOCK_STREAM):
  File "/Library/Frameworks/Python.framework/Versions/3.6/lib/python3.6/socket.py", line 745, in getaddrinfo
    for res in _socket.getaddrinfo(host, port, family, type, proto, flags):
socket.gaierror: [Errno 8] nodename nor servname provided, or not known

During handling of the above exception, another exception occurred:

Traceback (most recent call last):
  File "/Library/Frameworks/Python.framework/Versions/3.6/lib/python3.6/site-packages/urllib3/connectionpool.py", line 601, in urlopen
    chunked=chunked)
  File "/Library/Frameworks/Python.framework/Versions/3.6/lib/python3.6/site-packages/urllib3/connectionpool.py", line 346, in _make_request
    self._validate_conn(conn)
  File "/Library/Frameworks/Python.framework/Versions/3.6/lib/python3.6/site-packages/urllib3/connectionpool.py", line 850, in _validate_conn
    conn.connect()
  File "/Library/Frameworks/Python.framework/Versions/3.6/lib/python3.6/site-packages/urllib3/connection.py", line 284, in connect
    conn = self._new_conn()
  File "/Library/Frameworks/Python.framework/Versions/3.6/lib/python3.6/site-packages/urllib3/connection.py", line 150, in _new_conn
    self, "Failed to establish a new connection: %s" % e)
urllib3.exceptions.NewConnectionError: <urllib3.connection.VerifiedHTTPSConnection object at 0x10e564780>: Failed to establish a new connection: [Errno 8] nodename nor servname provided, or not known

During handling of the above exception, another exception occurred:

Traceback (most recent call last):
  File "/Library/Frameworks/Python.framework/Versions/3.6/lib/python3.6/site-packages/requests/adapters.py", line 440, in send
    timeout=timeout
  File "/Library/Frameworks/Python.framework/Versions/3.6/lib/python3.6/site-packages/urllib3/connectionpool.py", line 639, in urlopen
    _stacktrace=sys.exc_info()[2])
  File "/Library/Frameworks/Python.framework/Versions/3.6/lib/python3.6/site-packages/urllib3/util/retry.py", line 388, in increment
    raise MaxRetryError(_pool, url, error or ResponseError(cause))
urllib3.exceptions.MaxRetryError: HTTPSConnectionPool(host='api.dropboxapi.com', port=443): Max retries exceeded with url: /2/users/get_current_account (Caused by NewConnectionError('<urllib3.connection.VerifiedHTTPSConnection object at 0x10e564780>: Failed to establish a new connection: [Errno 8] nodename nor servname provided, or not known',))

During handling of the above exception, another exception occurred:

Traceback (most recent call last):
  File "/Users/hepting/Sites/dhhepting.github.io/script/sharemedia.py", line 53, in <module>
    dbx.users_get_current_account()
  File "/Library/Frameworks/Python.framework/Versions/3.6/lib/python3.6/site-packages/dropbox/base.py", line 4301, in users_get_current_account
    None,
  File "/Library/Frameworks/Python.framework/Versions/3.6/lib/python3.6/site-packages/dropbox/dropbox.py", line 272, in request
    timeout=timeout)
  File "/Library/Frameworks/Python.framework/Versions/3.6/lib/python3.6/site-packages/dropbox/dropbox.py", line 363, in request_json_string_with_retry
    timeout=timeout)
  File "/Library/Frameworks/Python.framework/Versions/3.6/lib/python3.6/site-packages/dropbox/dropbox.py", line 447, in request_json_string
    timeout=timeout,
  File "/Library/Frameworks/Python.framework/Versions/3.6/lib/python3.6/site-packages/requests/sessions.py", line 555, in post
    return self.request('POST', url, data=data, json=json, **kwargs)
  File "/Library/Frameworks/Python.framework/Versions/3.6/lib/python3.6/site-packages/requests/sessions.py", line 508, in request
    resp = self.send(prep, **send_kwargs)
  File "/Library/Frameworks/Python.framework/Versions/3.6/lib/python3.6/site-packages/requests/sessions.py", line 618, in send
    r = adapter.send(request, **kwargs)
  File "/Library/Frameworks/Python.framework/Versions/3.6/lib/python3.6/site-packages/requests/adapters.py", line 508, in send
    raise ConnectionError(e, request=request)
requests.exceptions.ConnectionError: HTTPSConnectionPool(host='api.dropboxapi.com', port=443): Max retries exceeded with url: /2/users/get_current_account (Caused by NewConnectionError('<urllib3.connection.VerifiedHTTPSConnection object at 0x10e564780>: Failed to establish a new connection: [Errno 8] nodename nor servname provided, or not known',))
2019-02-28 13:15:24.515469
2019-02-28 13:16:34.002075
2019-02-28 14:00:01.882377
2019-03-01 14:58:11.356987
Traceback (most recent call last):
  File "/Library/Frameworks/Python.framework/Versions/3.6/lib/python3.6/site-packages/urllib3/connection.py", line 141, in _new_conn
    (self.host, self.port), self.timeout, **extra_kw)
  File "/Library/Frameworks/Python.framework/Versions/3.6/lib/python3.6/site-packages/urllib3/util/connection.py", line 60, in create_connection
    for res in socket.getaddrinfo(host, port, family, socket.SOCK_STREAM):
  File "/Library/Frameworks/Python.framework/Versions/3.6/lib/python3.6/socket.py", line 745, in getaddrinfo
    for res in _socket.getaddrinfo(host, port, family, type, proto, flags):
socket.gaierror: [Errno 8] nodename nor servname provided, or not known

During handling of the above exception, another exception occurred:

Traceback (most recent call last):
  File "/Library/Frameworks/Python.framework/Versions/3.6/lib/python3.6/site-packages/urllib3/connectionpool.py", line 601, in urlopen
    chunked=chunked)
  File "/Library/Frameworks/Python.framework/Versions/3.6/lib/python3.6/site-packages/urllib3/connectionpool.py", line 346, in _make_request
    self._validate_conn(conn)
  File "/Library/Frameworks/Python.framework/Versions/3.6/lib/python3.6/site-packages/urllib3/connectionpool.py", line 850, in _validate_conn
    conn.connect()
  File "/Library/Frameworks/Python.framework/Versions/3.6/lib/python3.6/site-packages/urllib3/connection.py", line 284, in connect
    conn = self._new_conn()
  File "/Library/Frameworks/Python.framework/Versions/3.6/lib/python3.6/site-packages/urllib3/connection.py", line 150, in _new_conn
    self, "Failed to establish a new connection: %s" % e)
urllib3.exceptions.NewConnectionError: <urllib3.connection.VerifiedHTTPSConnection object at 0x10e564780>: Failed to establish a new connection: [Errno 8] nodename nor servname provided, or not known

During handling of the above exception, another exception occurred:

Traceback (most recent call last):
  File "/Library/Frameworks/Python.framework/Versions/3.6/lib/python3.6/site-packages/requests/adapters.py", line 440, in send
    timeout=timeout
  File "/Library/Frameworks/Python.framework/Versions/3.6/lib/python3.6/site-packages/urllib3/connectionpool.py", line 639, in urlopen
    _stacktrace=sys.exc_info()[2])
  File "/Library/Frameworks/Python.framework/Versions/3.6/lib/python3.6/site-packages/urllib3/util/retry.py", line 388, in increment
    raise MaxRetryError(_pool, url, error or ResponseError(cause))
urllib3.exceptions.MaxRetryError: HTTPSConnectionPool(host='api.dropboxapi.com', port=443): Max retries exceeded with url: /2/users/get_current_account (Caused by NewConnectionError('<urllib3.connection.VerifiedHTTPSConnection object at 0x10e564780>: Failed to establish a new connection: [Errno 8] nodename nor servname provided, or not known',))

During handling of the above exception, another exception occurred:

Traceback (most recent call last):
  File "/Users/hepting/Sites/dhhepting.github.io/script/sharemedia.py", line 53, in <module>
    dbx.users_get_current_account()
  File "/Library/Frameworks/Python.framework/Versions/3.6/lib/python3.6/site-packages/dropbox/base.py", line 4301, in users_get_current_account
    None,
  File "/Library/Frameworks/Python.framework/Versions/3.6/lib/python3.6/site-packages/dropbox/dropbox.py", line 272, in request
    timeout=timeout)
  File "/Library/Frameworks/Python.framework/Versions/3.6/lib/python3.6/site-packages/dropbox/dropbox.py", line 363, in request_json_string_with_retry
    timeout=timeout)
  File "/Library/Frameworks/Python.framework/Versions/3.6/lib/python3.6/site-packages/dropbox/dropbox.py", line 447, in request_json_string
    timeout=timeout,
  File "/Library/Frameworks/Python.framework/Versions/3.6/lib/python3.6/site-packages/requests/sessions.py", line 555, in post
    return self.request('POST', url, data=data, json=json, **kwargs)
  File "/Library/Frameworks/Python.framework/Versions/3.6/lib/python3.6/site-packages/requests/sessions.py", line 508, in request
    resp = self.send(prep, **send_kwargs)
  File "/Library/Frameworks/Python.framework/Versions/3.6/lib/python3.6/site-packages/requests/sessions.py", line 618, in send
    r = adapter.send(request, **kwargs)
  File "/Library/Frameworks/Python.framework/Versions/3.6/lib/python3.6/site-packages/requests/adapters.py", line 508, in send
    raise ConnectionError(e, request=request)
requests.exceptions.ConnectionError: HTTPSConnectionPool(host='api.dropboxapi.com', port=443): Max retries exceeded with url: /2/users/get_current_account (Caused by NewConnectionError('<urllib3.connection.VerifiedHTTPSConnection object at 0x10e564780>: Failed to establish a new connection: [Errno 8] nodename nor servname provided, or not known',))
2019-03-02 15:26:43.859714
2019-03-03 15:37:12.375809
2019-03-04 11:33:12.175146
2019-03-04 14:00:04.210518
2019-03-05 14:00:05.605362
2019-03-06 11:28:01.233634
2019-03-06 11:34:22.861035
2019-03-06 14:00:05.567668
2019-03-06 17:03:59.735360
2019-03-06 17:06:05.149615
Traceback (most recent call last):
  File "/Library/Frameworks/Python.framework/Versions/3.6/lib/python3.6/site-packages/urllib3/connectionpool.py", line 387, in _make_request
    six.raise_from(e, None)
  File "<string>", line 2, in raise_from
  File "/Library/Frameworks/Python.framework/Versions/3.6/lib/python3.6/site-packages/urllib3/connectionpool.py", line 383, in _make_request
    httplib_response = conn.getresponse()
  File "/Library/Frameworks/Python.framework/Versions/3.6/lib/python3.6/http/client.py", line 1331, in getresponse
    response.begin()
  File "/Library/Frameworks/Python.framework/Versions/3.6/lib/python3.6/http/client.py", line 297, in begin
    version, status, reason = self._read_status()
  File "/Library/Frameworks/Python.framework/Versions/3.6/lib/python3.6/http/client.py", line 258, in _read_status
    line = str(self.fp.readline(_MAXLINE + 1), "iso-8859-1")
  File "/Library/Frameworks/Python.framework/Versions/3.6/lib/python3.6/socket.py", line 586, in readinto
    return self._sock.recv_into(b)
  File "/Library/Frameworks/Python.framework/Versions/3.6/lib/python3.6/ssl.py", line 1009, in recv_into
    return self.read(nbytes, buffer)
  File "/Library/Frameworks/Python.framework/Versions/3.6/lib/python3.6/ssl.py", line 871, in read
    return self._sslobj.read(len, buffer)
  File "/Library/Frameworks/Python.framework/Versions/3.6/lib/python3.6/ssl.py", line 631, in read
    v = self._sslobj.read(len, buffer)
TimeoutError: [Errno 60] Operation timed out

During handling of the above exception, another exception occurred:

Traceback (most recent call last):
  File "/Library/Frameworks/Python.framework/Versions/3.6/lib/python3.6/site-packages/requests/adapters.py", line 440, in send
    timeout=timeout
  File "/Library/Frameworks/Python.framework/Versions/3.6/lib/python3.6/site-packages/urllib3/connectionpool.py", line 639, in urlopen
    _stacktrace=sys.exc_info()[2])
  File "/Library/Frameworks/Python.framework/Versions/3.6/lib/python3.6/site-packages/urllib3/util/retry.py", line 357, in increment
    raise six.reraise(type(error), error, _stacktrace)
  File "/Library/Frameworks/Python.framework/Versions/3.6/lib/python3.6/site-packages/urllib3/packages/six.py", line 686, in reraise
    raise value
  File "/Library/Frameworks/Python.framework/Versions/3.6/lib/python3.6/site-packages/urllib3/connectionpool.py", line 601, in urlopen
    chunked=chunked)
  File "/Library/Frameworks/Python.framework/Versions/3.6/lib/python3.6/site-packages/urllib3/connectionpool.py", line 389, in _make_request
    self._raise_timeout(err=e, url=url, timeout_value=read_timeout)
  File "/Library/Frameworks/Python.framework/Versions/3.6/lib/python3.6/site-packages/urllib3/connectionpool.py", line 320, in _raise_timeout
    raise ReadTimeoutError(self, url, "Read timed out. (read timeout=%s)" % timeout_value)
urllib3.exceptions.ReadTimeoutError: HTTPSConnectionPool(host='api.dropboxapi.com', port=443): Read timed out. (read timeout=30)

During handling of the above exception, another exception occurred:

Traceback (most recent call last):
  File "/Users/hepting/Sites/dhhepting.github.io/script/sharemedia.py", line 71, in <module>
    share = dbx.sharing_create_shared_link(dbp)
  File "/Library/Frameworks/Python.framework/Versions/3.6/lib/python3.6/site-packages/dropbox/base.py", line 3095, in sharing_create_shared_link
    None,
  File "/Library/Frameworks/Python.framework/Versions/3.6/lib/python3.6/site-packages/dropbox/dropbox.py", line 272, in request
    timeout=timeout)
  File "/Library/Frameworks/Python.framework/Versions/3.6/lib/python3.6/site-packages/dropbox/dropbox.py", line 363, in request_json_string_with_retry
    timeout=timeout)
  File "/Library/Frameworks/Python.framework/Versions/3.6/lib/python3.6/site-packages/dropbox/dropbox.py", line 447, in request_json_string
    timeout=timeout,
  File "/Library/Frameworks/Python.framework/Versions/3.6/lib/python3.6/site-packages/requests/sessions.py", line 555, in post
    return self.request('POST', url, data=data, json=json, **kwargs)
  File "/Library/Frameworks/Python.framework/Versions/3.6/lib/python3.6/site-packages/requests/sessions.py", line 508, in request
    resp = self.send(prep, **send_kwargs)
  File "/Library/Frameworks/Python.framework/Versions/3.6/lib/python3.6/site-packages/requests/sessions.py", line 618, in send
    r = adapter.send(request, **kwargs)
  File "/Library/Frameworks/Python.framework/Versions/3.6/lib/python3.6/site-packages/requests/adapters.py", line 521, in send
    raise ReadTimeout(e, request=request)
requests.exceptions.ReadTimeout: HTTPSConnectionPool(host='api.dropboxapi.com', port=443): Read timed out. (read timeout=30)
2019-03-07 14:00:05.559656
2019-03-08 14:00:05.022959
2019-03-09 14:00:04.494234
2019-03-10 15:23:44.956437
2019-03-11 14:00:05.550735
2019-03-12 14:00:06.980139
2019-03-13 11:24:34.132344
2019-03-14 14:00:06.853540
2019-03-15 14:00:04.544143
2019-03-16 14:00:03.426971
2019-03-17 19:36:33.280379
2019-03-18 11:00:07.974174
2019-03-18 11:06:55.020703
2019-03-18 11:17:57.114380
2019-03-18 11:19:14.057014
2019-03-18 11:21:36.379182
2019-03-18 11:24:49.685361
2019-03-18 11:26:13.452752
2019-03-18 11:32:36.058204
2019-03-18 13:53:04.543276
2019-03-18 13:54:37.754930
2019-03-18 14:00:02.816755
2019-03-18 21:53:19.167210
2019-03-19 14:00:06.601774
2019-03-20 10:12:57.384649
2019-03-20 14:00:05.732953
2019-03-20 14:11:46.774454
2019-03-20 14:16:15.049716
2019-03-21 14:13:23.907754
2019-03-22 14:00:09.337722
2019-03-23 14:00:05.841552
2019-03-24 20:12:31.698757
2019-03-25 14:00:09.714640
2019-03-25 16:26:30.041228
2019-03-25 16:28:25.694020
2019-03-26 14:00:11.823898
2019-03-27 14:00:04.559131
2019-03-27 14:42:48.309725
2019-03-28 14:00:04.277637
2019-03-29 14:00:11.282659
2019-03-29 15:15:37.332081
2019-03-29 15:23:15.002428
2019-03-30 16:22:10.685416
2019-03-31 15:05:52.777439
Traceback (most recent call last):
  File "/Library/Frameworks/Python.framework/Versions/3.6/lib/python3.6/site-packages/urllib3/connectionpool.py", line 387, in _make_request
    six.raise_from(e, None)
  File "<string>", line 2, in raise_from
  File "/Library/Frameworks/Python.framework/Versions/3.6/lib/python3.6/site-packages/urllib3/connectionpool.py", line 383, in _make_request
    httplib_response = conn.getresponse()
  File "/Library/Frameworks/Python.framework/Versions/3.6/lib/python3.6/http/client.py", line 1331, in getresponse
    response.begin()
  File "/Library/Frameworks/Python.framework/Versions/3.6/lib/python3.6/http/client.py", line 297, in begin
    version, status, reason = self._read_status()
  File "/Library/Frameworks/Python.framework/Versions/3.6/lib/python3.6/http/client.py", line 258, in _read_status
    line = str(self.fp.readline(_MAXLINE + 1), "iso-8859-1")
  File "/Library/Frameworks/Python.framework/Versions/3.6/lib/python3.6/socket.py", line 586, in readinto
    return self._sock.recv_into(b)
  File "/Library/Frameworks/Python.framework/Versions/3.6/lib/python3.6/site-packages/urllib3/contrib/pyopenssl.py", line 294, in recv_into
    raise timeout('The read operation timed out')
socket.timeout: The read operation timed out

During handling of the above exception, another exception occurred:

Traceback (most recent call last):
  File "/Library/Frameworks/Python.framework/Versions/3.6/lib/python3.6/site-packages/requests/adapters.py", line 440, in send
    timeout=timeout
  File "/Library/Frameworks/Python.framework/Versions/3.6/lib/python3.6/site-packages/urllib3/connectionpool.py", line 639, in urlopen
    _stacktrace=sys.exc_info()[2])
  File "/Library/Frameworks/Python.framework/Versions/3.6/lib/python3.6/site-packages/urllib3/util/retry.py", line 357, in increment
    raise six.reraise(type(error), error, _stacktrace)
  File "/Library/Frameworks/Python.framework/Versions/3.6/lib/python3.6/site-packages/urllib3/packages/six.py", line 686, in reraise
    raise value
  File "/Library/Frameworks/Python.framework/Versions/3.6/lib/python3.6/site-packages/urllib3/connectionpool.py", line 601, in urlopen
    chunked=chunked)
  File "/Library/Frameworks/Python.framework/Versions/3.6/lib/python3.6/site-packages/urllib3/connectionpool.py", line 389, in _make_request
    self._raise_timeout(err=e, url=url, timeout_value=read_timeout)
  File "/Library/Frameworks/Python.framework/Versions/3.6/lib/python3.6/site-packages/urllib3/connectionpool.py", line 309, in _raise_timeout
    raise ReadTimeoutError(self, url, "Read timed out. (read timeout=%s)" % timeout_value)
urllib3.exceptions.ReadTimeoutError: HTTPSConnectionPool(host='api.dropboxapi.com', port=443): Read timed out. (read timeout=30)

During handling of the above exception, another exception occurred:

Traceback (most recent call last):
  File "/Users/hepting/Sites/dhhepting.github.io/script/sharemedia.py", line 71, in <module>
    share = dbx.sharing_create_shared_link(dbp)
  File "/Library/Frameworks/Python.framework/Versions/3.6/lib/python3.6/site-packages/dropbox/base.py", line 3095, in sharing_create_shared_link
    None,
  File "/Library/Frameworks/Python.framework/Versions/3.6/lib/python3.6/site-packages/dropbox/dropbox.py", line 272, in request
    timeout=timeout)
  File "/Library/Frameworks/Python.framework/Versions/3.6/lib/python3.6/site-packages/dropbox/dropbox.py", line 363, in request_json_string_with_retry
    timeout=timeout)
  File "/Library/Frameworks/Python.framework/Versions/3.6/lib/python3.6/site-packages/dropbox/dropbox.py", line 447, in request_json_string
    timeout=timeout,
  File "/Library/Frameworks/Python.framework/Versions/3.6/lib/python3.6/site-packages/requests/sessions.py", line 555, in post
    return self.request('POST', url, data=data, json=json, **kwargs)
  File "/Library/Frameworks/Python.framework/Versions/3.6/lib/python3.6/site-packages/requests/sessions.py", line 508, in request
    resp = self.send(prep, **send_kwargs)
  File "/Library/Frameworks/Python.framework/Versions/3.6/lib/python3.6/site-packages/requests/sessions.py", line 618, in send
    r = adapter.send(request, **kwargs)
  File "/Library/Frameworks/Python.framework/Versions/3.6/lib/python3.6/site-packages/requests/adapters.py", line 521, in send
    raise ReadTimeout(e, request=request)
requests.exceptions.ReadTimeout: HTTPSConnectionPool(host='api.dropboxapi.com', port=443): Read timed out. (read timeout=30)
2019-04-01 14:00:09.593542
2019-04-02 14:00:09.783115
2019-04-03 10:27:14.323800
2019-04-03 10:39:37.099420
2019-04-03 13:29:19.969626
2019-04-03 13:36:34.901308
Traceback (most recent call last):
  File "/Users/hepting/Sites/dhhepting.github.io/script/sharemedia.py", line 84, in <module>
    print (meeetstr)
NameError: name 'meeetstr' is not defined
2019-04-03 13:38:49.308647
2019-04-03 13:49:37.916290
2019-04-03 13:51:09.211261
2019-04-03 14:03:25.453091
2019-04-04 14:00:07.510308
2019-04-05 14:00:19.855694
2019-04-05 15:54:56.040565
2019-04-05 16:05:36.881447
2019-04-05 16:12:38.524170
2019-04-06 15:11:14.915121
2019-04-07 16:48:09.151833
2019-04-08 14:00:08.094474
2019-04-09 14:53:33.596645
2019-04-10 13:56:02.643196
Traceback (most recent call last):
  File "/Library/Frameworks/Python.framework/Versions/3.6/lib/python3.6/site-packages/urllib3/connectionpool.py", line 601, in urlopen
    chunked=chunked)
  File "/Library/Frameworks/Python.framework/Versions/3.6/lib/python3.6/site-packages/urllib3/connectionpool.py", line 387, in _make_request
    six.raise_from(e, None)
  File "<string>", line 2, in raise_from
  File "/Library/Frameworks/Python.framework/Versions/3.6/lib/python3.6/site-packages/urllib3/connectionpool.py", line 383, in _make_request
    httplib_response = conn.getresponse()
  File "/Library/Frameworks/Python.framework/Versions/3.6/lib/python3.6/http/client.py", line 1331, in getresponse
    response.begin()
  File "/Library/Frameworks/Python.framework/Versions/3.6/lib/python3.6/http/client.py", line 297, in begin
    version, status, reason = self._read_status()
  File "/Library/Frameworks/Python.framework/Versions/3.6/lib/python3.6/http/client.py", line 258, in _read_status
    line = str(self.fp.readline(_MAXLINE + 1), "iso-8859-1")
  File "/Library/Frameworks/Python.framework/Versions/3.6/lib/python3.6/socket.py", line 586, in readinto
    return self._sock.recv_into(b)
  File "/Library/Frameworks/Python.framework/Versions/3.6/lib/python3.6/site-packages/urllib3/contrib/pyopenssl.py", line 296, in recv_into
    return self.recv_into(*args, **kwargs)
  File "/Library/Frameworks/Python.framework/Versions/3.6/lib/python3.6/site-packages/urllib3/contrib/pyopenssl.py", line 285, in recv_into
    raise SocketError(str(e))
OSError: (60, 'ETIMEDOUT')

During handling of the above exception, another exception occurred:

Traceback (most recent call last):
  File "/Library/Frameworks/Python.framework/Versions/3.6/lib/python3.6/site-packages/requests/adapters.py", line 440, in send
    timeout=timeout
  File "/Library/Frameworks/Python.framework/Versions/3.6/lib/python3.6/site-packages/urllib3/connectionpool.py", line 639, in urlopen
    _stacktrace=sys.exc_info()[2])
  File "/Library/Frameworks/Python.framework/Versions/3.6/lib/python3.6/site-packages/urllib3/util/retry.py", line 357, in increment
    raise six.reraise(type(error), error, _stacktrace)
  File "/Library/Frameworks/Python.framework/Versions/3.6/lib/python3.6/site-packages/urllib3/packages/six.py", line 685, in reraise
    raise value.with_traceback(tb)
  File "/Library/Frameworks/Python.framework/Versions/3.6/lib/python3.6/site-packages/urllib3/connectionpool.py", line 601, in urlopen
    chunked=chunked)
  File "/Library/Frameworks/Python.framework/Versions/3.6/lib/python3.6/site-packages/urllib3/connectionpool.py", line 387, in _make_request
    six.raise_from(e, None)
  File "<string>", line 2, in raise_from
  File "/Library/Frameworks/Python.framework/Versions/3.6/lib/python3.6/site-packages/urllib3/connectionpool.py", line 383, in _make_request
    httplib_response = conn.getresponse()
  File "/Library/Frameworks/Python.framework/Versions/3.6/lib/python3.6/http/client.py", line 1331, in getresponse
    response.begin()
  File "/Library/Frameworks/Python.framework/Versions/3.6/lib/python3.6/http/client.py", line 297, in begin
    version, status, reason = self._read_status()
  File "/Library/Frameworks/Python.framework/Versions/3.6/lib/python3.6/http/client.py", line 258, in _read_status
    line = str(self.fp.readline(_MAXLINE + 1), "iso-8859-1")
  File "/Library/Frameworks/Python.framework/Versions/3.6/lib/python3.6/socket.py", line 586, in readinto
    return self._sock.recv_into(b)
  File "/Library/Frameworks/Python.framework/Versions/3.6/lib/python3.6/site-packages/urllib3/contrib/pyopenssl.py", line 296, in recv_into
    return self.recv_into(*args, **kwargs)
  File "/Library/Frameworks/Python.framework/Versions/3.6/lib/python3.6/site-packages/urllib3/contrib/pyopenssl.py", line 285, in recv_into
    raise SocketError(str(e))
urllib3.exceptions.ProtocolError: ('Connection aborted.', OSError("(60, 'ETIMEDOUT')",))

During handling of the above exception, another exception occurred:

Traceback (most recent call last):
  File "/Users/hepting/Sites/dhhepting.github.io/script/sharemedia.py", line 71, in <module>
    share = dbx.sharing_create_shared_link(dbp)
  File "/Library/Frameworks/Python.framework/Versions/3.6/lib/python3.6/site-packages/dropbox/base.py", line 3095, in sharing_create_shared_link
    None,
  File "/Library/Frameworks/Python.framework/Versions/3.6/lib/python3.6/site-packages/dropbox/dropbox.py", line 272, in request
    timeout=timeout)
  File "/Library/Frameworks/Python.framework/Versions/3.6/lib/python3.6/site-packages/dropbox/dropbox.py", line 363, in request_json_string_with_retry
    timeout=timeout)
  File "/Library/Frameworks/Python.framework/Versions/3.6/lib/python3.6/site-packages/dropbox/dropbox.py", line 447, in request_json_string
    timeout=timeout,
  File "/Library/Frameworks/Python.framework/Versions/3.6/lib/python3.6/site-packages/requests/sessions.py", line 555, in post
    return self.request('POST', url, data=data, json=json, **kwargs)
  File "/Library/Frameworks/Python.framework/Versions/3.6/lib/python3.6/site-packages/requests/sessions.py", line 508, in request
    resp = self.send(prep, **send_kwargs)
  File "/Library/Frameworks/Python.framework/Versions/3.6/lib/python3.6/site-packages/requests/sessions.py", line 618, in send
    r = adapter.send(request, **kwargs)
  File "/Library/Frameworks/Python.framework/Versions/3.6/lib/python3.6/site-packages/requests/adapters.py", line 490, in send
    raise ConnectionError(err, request=request)
requests.exceptions.ConnectionError: ('Connection aborted.', OSError("(60, 'ETIMEDOUT')",))
2019-04-10 14:26:42.200568
2019-04-10 14:29:53.292278
2019-04-11 14:00:08.374037
2019-04-12 14:00:05.179215
2019-04-13 14:00:13.285752
2019-04-14 14:00:06.791652
2019-04-14 14:48:17.644343
2019-04-15 14:00:07.433225
2019-04-16 14:00:05.491961
2019-04-17 15:03:52.486940
2019-04-18 14:00:05.791003
2019-04-19 16:27:05.479242
2019-04-20 16:52:23.161388
2019-04-21 15:28:54.346008
2019-04-22 14:00:05.362111
2019-04-23 14:00:04.625447
2019-04-24 14:00:04.807946
2019-04-25 14:00:05.643988
2019-04-26 14:28:46.542137
2019-04-27 14:00:05.535051
2019-04-28 14:00:08.177901
2019-04-29 03:03:16.637618
2019-04-29 03:40:58.996534
2019-04-29 14:00:03.882566
2019-04-30 14:00:03.873845
2019-05-01 14:00:03.620604
2019-05-02 14:22:17.486162
Traceback (most recent call last):
  File "/Library/Frameworks/Python.framework/Versions/3.6/lib/python3.6/site-packages/urllib3/connectionpool.py", line 601, in urlopen
    chunked=chunked)
  File "/Library/Frameworks/Python.framework/Versions/3.6/lib/python3.6/site-packages/urllib3/connectionpool.py", line 387, in _make_request
    six.raise_from(e, None)
  File "<string>", line 2, in raise_from
  File "/Library/Frameworks/Python.framework/Versions/3.6/lib/python3.6/site-packages/urllib3/connectionpool.py", line 383, in _make_request
    httplib_response = conn.getresponse()
  File "/Library/Frameworks/Python.framework/Versions/3.6/lib/python3.6/http/client.py", line 1331, in getresponse
    response.begin()
  File "/Library/Frameworks/Python.framework/Versions/3.6/lib/python3.6/http/client.py", line 297, in begin
    version, status, reason = self._read_status()
  File "/Library/Frameworks/Python.framework/Versions/3.6/lib/python3.6/http/client.py", line 258, in _read_status
    line = str(self.fp.readline(_MAXLINE + 1), "iso-8859-1")
  File "/Library/Frameworks/Python.framework/Versions/3.6/lib/python3.6/socket.py", line 586, in readinto
    return self._sock.recv_into(b)
  File "/Library/Frameworks/Python.framework/Versions/3.6/lib/python3.6/site-packages/urllib3/contrib/pyopenssl.py", line 296, in recv_into
    return self.recv_into(*args, **kwargs)
  File "/Library/Frameworks/Python.framework/Versions/3.6/lib/python3.6/site-packages/urllib3/contrib/pyopenssl.py", line 285, in recv_into
    raise SocketError(str(e))
OSError: (54, 'ECONNRESET')

During handling of the above exception, another exception occurred:

Traceback (most recent call last):
  File "/Library/Frameworks/Python.framework/Versions/3.6/lib/python3.6/site-packages/requests/adapters.py", line 440, in send
    timeout=timeout
  File "/Library/Frameworks/Python.framework/Versions/3.6/lib/python3.6/site-packages/urllib3/connectionpool.py", line 639, in urlopen
    _stacktrace=sys.exc_info()[2])
  File "/Library/Frameworks/Python.framework/Versions/3.6/lib/python3.6/site-packages/urllib3/util/retry.py", line 357, in increment
    raise six.reraise(type(error), error, _stacktrace)
  File "/Library/Frameworks/Python.framework/Versions/3.6/lib/python3.6/site-packages/urllib3/packages/six.py", line 685, in reraise
    raise value.with_traceback(tb)
  File "/Library/Frameworks/Python.framework/Versions/3.6/lib/python3.6/site-packages/urllib3/connectionpool.py", line 601, in urlopen
    chunked=chunked)
  File "/Library/Frameworks/Python.framework/Versions/3.6/lib/python3.6/site-packages/urllib3/connectionpool.py", line 387, in _make_request
    six.raise_from(e, None)
  File "<string>", line 2, in raise_from
  File "/Library/Frameworks/Python.framework/Versions/3.6/lib/python3.6/site-packages/urllib3/connectionpool.py", line 383, in _make_request
    httplib_response = conn.getresponse()
  File "/Library/Frameworks/Python.framework/Versions/3.6/lib/python3.6/http/client.py", line 1331, in getresponse
    response.begin()
  File "/Library/Frameworks/Python.framework/Versions/3.6/lib/python3.6/http/client.py", line 297, in begin
    version, status, reason = self._read_status()
  File "/Library/Frameworks/Python.framework/Versions/3.6/lib/python3.6/http/client.py", line 258, in _read_status
    line = str(self.fp.readline(_MAXLINE + 1), "iso-8859-1")
  File "/Library/Frameworks/Python.framework/Versions/3.6/lib/python3.6/socket.py", line 586, in readinto
    return self._sock.recv_into(b)
  File "/Library/Frameworks/Python.framework/Versions/3.6/lib/python3.6/site-packages/urllib3/contrib/pyopenssl.py", line 296, in recv_into
    return self.recv_into(*args, **kwargs)
  File "/Library/Frameworks/Python.framework/Versions/3.6/lib/python3.6/site-packages/urllib3/contrib/pyopenssl.py", line 285, in recv_into
    raise SocketError(str(e))
urllib3.exceptions.ProtocolError: ('Connection aborted.', OSError("(54, 'ECONNRESET')",))

During handling of the above exception, another exception occurred:

Traceback (most recent call last):
  File "/Users/hepting/Sites/dhhepting.github.io/script/sharemedia.py", line 71, in <module>
    share = dbx.sharing_create_shared_link(dbp)
  File "/Library/Frameworks/Python.framework/Versions/3.6/lib/python3.6/site-packages/dropbox/base.py", line 3095, in sharing_create_shared_link
    None,
  File "/Library/Frameworks/Python.framework/Versions/3.6/lib/python3.6/site-packages/dropbox/dropbox.py", line 272, in request
    timeout=timeout)
  File "/Library/Frameworks/Python.framework/Versions/3.6/lib/python3.6/site-packages/dropbox/dropbox.py", line 363, in request_json_string_with_retry
    timeout=timeout)
  File "/Library/Frameworks/Python.framework/Versions/3.6/lib/python3.6/site-packages/dropbox/dropbox.py", line 447, in request_json_string
    timeout=timeout,
  File "/Library/Frameworks/Python.framework/Versions/3.6/lib/python3.6/site-packages/requests/sessions.py", line 555, in post
    return self.request('POST', url, data=data, json=json, **kwargs)
  File "/Library/Frameworks/Python.framework/Versions/3.6/lib/python3.6/site-packages/requests/sessions.py", line 508, in request
    resp = self.send(prep, **send_kwargs)
  File "/Library/Frameworks/Python.framework/Versions/3.6/lib/python3.6/site-packages/requests/sessions.py", line 618, in send
    r = adapter.send(request, **kwargs)
  File "/Library/Frameworks/Python.framework/Versions/3.6/lib/python3.6/site-packages/requests/adapters.py", line 490, in send
    raise ConnectionError(err, request=request)
requests.exceptions.ConnectionError: ('Connection aborted.', OSError("(54, 'ECONNRESET')",))
2019-05-03 13:15:15.510761
Traceback (most recent call last):
  File "/Library/Frameworks/Python.framework/Versions/3.6/lib/python3.6/site-packages/urllib3/connection.py", line 141, in _new_conn
    (self.host, self.port), self.timeout, **extra_kw)
  File "/Library/Frameworks/Python.framework/Versions/3.6/lib/python3.6/site-packages/urllib3/util/connection.py", line 60, in create_connection
    for res in socket.getaddrinfo(host, port, family, socket.SOCK_STREAM):
  File "/Library/Frameworks/Python.framework/Versions/3.6/lib/python3.6/socket.py", line 745, in getaddrinfo
    for res in _socket.getaddrinfo(host, port, family, type, proto, flags):
socket.gaierror: [Errno 8] nodename nor servname provided, or not known

During handling of the above exception, another exception occurred:

Traceback (most recent call last):
  File "/Library/Frameworks/Python.framework/Versions/3.6/lib/python3.6/site-packages/urllib3/connectionpool.py", line 601, in urlopen
    chunked=chunked)
  File "/Library/Frameworks/Python.framework/Versions/3.6/lib/python3.6/site-packages/urllib3/connectionpool.py", line 346, in _make_request
    self._validate_conn(conn)
  File "/Library/Frameworks/Python.framework/Versions/3.6/lib/python3.6/site-packages/urllib3/connectionpool.py", line 850, in _validate_conn
    conn.connect()
  File "/Library/Frameworks/Python.framework/Versions/3.6/lib/python3.6/site-packages/urllib3/connection.py", line 284, in connect
    conn = self._new_conn()
  File "/Library/Frameworks/Python.framework/Versions/3.6/lib/python3.6/site-packages/urllib3/connection.py", line 150, in _new_conn
    self, "Failed to establish a new connection: %s" % e)
urllib3.exceptions.NewConnectionError: <urllib3.connection.VerifiedHTTPSConnection object at 0x10f22f550>: Failed to establish a new connection: [Errno 8] nodename nor servname provided, or not known

During handling of the above exception, another exception occurred:

Traceback (most recent call last):
  File "/Library/Frameworks/Python.framework/Versions/3.6/lib/python3.6/site-packages/requests/adapters.py", line 440, in send
    timeout=timeout
  File "/Library/Frameworks/Python.framework/Versions/3.6/lib/python3.6/site-packages/urllib3/connectionpool.py", line 639, in urlopen
    _stacktrace=sys.exc_info()[2])
  File "/Library/Frameworks/Python.framework/Versions/3.6/lib/python3.6/site-packages/urllib3/util/retry.py", line 388, in increment
    raise MaxRetryError(_pool, url, error or ResponseError(cause))
urllib3.exceptions.MaxRetryError: HTTPSConnectionPool(host='api.dropboxapi.com', port=443): Max retries exceeded with url: /2/users/get_current_account (Caused by NewConnectionError('<urllib3.connection.VerifiedHTTPSConnection object at 0x10f22f550>: Failed to establish a new connection: [Errno 8] nodename nor servname provided, or not known',))

During handling of the above exception, another exception occurred:

Traceback (most recent call last):
  File "/Users/hepting/Sites/dhhepting.github.io/script/sharemedia.py", line 53, in <module>
    dbx.users_get_current_account()
  File "/Library/Frameworks/Python.framework/Versions/3.6/lib/python3.6/site-packages/dropbox/base.py", line 4301, in users_get_current_account
    None,
  File "/Library/Frameworks/Python.framework/Versions/3.6/lib/python3.6/site-packages/dropbox/dropbox.py", line 272, in request
    timeout=timeout)
  File "/Library/Frameworks/Python.framework/Versions/3.6/lib/python3.6/site-packages/dropbox/dropbox.py", line 363, in request_json_string_with_retry
    timeout=timeout)
  File "/Library/Frameworks/Python.framework/Versions/3.6/lib/python3.6/site-packages/dropbox/dropbox.py", line 447, in request_json_string
    timeout=timeout,
  File "/Library/Frameworks/Python.framework/Versions/3.6/lib/python3.6/site-packages/requests/sessions.py", line 555, in post
    return self.request('POST', url, data=data, json=json, **kwargs)
  File "/Library/Frameworks/Python.framework/Versions/3.6/lib/python3.6/site-packages/requests/sessions.py", line 508, in request
    resp = self.send(prep, **send_kwargs)
  File "/Library/Frameworks/Python.framework/Versions/3.6/lib/python3.6/site-packages/requests/sessions.py", line 618, in send
    r = adapter.send(request, **kwargs)
  File "/Library/Frameworks/Python.framework/Versions/3.6/lib/python3.6/site-packages/requests/adapters.py", line 508, in send
    raise ConnectionError(e, request=request)
requests.exceptions.ConnectionError: HTTPSConnectionPool(host='api.dropboxapi.com', port=443): Max retries exceeded with url: /2/users/get_current_account (Caused by NewConnectionError('<urllib3.connection.VerifiedHTTPSConnection object at 0x10f22f550>: Failed to establish a new connection: [Errno 8] nodename nor servname provided, or not known',))
2019-05-03 14:00:02.891091
2019-05-04 14:00:09.164362
2019-05-05 14:00:02.264264
2019-05-06 14:48:28.668107
2019-05-07 14:44:57.220199
2019-05-08 14:00:04.952067
2019-05-09 14:01:23.080120
2019-05-10 14:01:26.836331
2019-05-11 14:23:11.983081
Traceback (most recent call last):
  File "/Library/Frameworks/Python.framework/Versions/3.6/lib/python3.6/site-packages/urllib3/connectionpool.py", line 601, in urlopen
    chunked=chunked)
  File "/Library/Frameworks/Python.framework/Versions/3.6/lib/python3.6/site-packages/urllib3/connectionpool.py", line 387, in _make_request
    six.raise_from(e, None)
  File "<string>", line 2, in raise_from
  File "/Library/Frameworks/Python.framework/Versions/3.6/lib/python3.6/site-packages/urllib3/connectionpool.py", line 383, in _make_request
    httplib_response = conn.getresponse()
  File "/Library/Frameworks/Python.framework/Versions/3.6/lib/python3.6/http/client.py", line 1331, in getresponse
    response.begin()
  File "/Library/Frameworks/Python.framework/Versions/3.6/lib/python3.6/http/client.py", line 297, in begin
    version, status, reason = self._read_status()
  File "/Library/Frameworks/Python.framework/Versions/3.6/lib/python3.6/http/client.py", line 258, in _read_status
    line = str(self.fp.readline(_MAXLINE + 1), "iso-8859-1")
  File "/Library/Frameworks/Python.framework/Versions/3.6/lib/python3.6/socket.py", line 586, in readinto
    return self._sock.recv_into(b)
  File "/Library/Frameworks/Python.framework/Versions/3.6/lib/python3.6/site-packages/urllib3/contrib/pyopenssl.py", line 296, in recv_into
    return self.recv_into(*args, **kwargs)
  File "/Library/Frameworks/Python.framework/Versions/3.6/lib/python3.6/site-packages/urllib3/contrib/pyopenssl.py", line 285, in recv_into
    raise SocketError(str(e))
OSError: (54, 'ECONNRESET')

During handling of the above exception, another exception occurred:

Traceback (most recent call last):
  File "/Library/Frameworks/Python.framework/Versions/3.6/lib/python3.6/site-packages/requests/adapters.py", line 440, in send
    timeout=timeout
  File "/Library/Frameworks/Python.framework/Versions/3.6/lib/python3.6/site-packages/urllib3/connectionpool.py", line 639, in urlopen
    _stacktrace=sys.exc_info()[2])
  File "/Library/Frameworks/Python.framework/Versions/3.6/lib/python3.6/site-packages/urllib3/util/retry.py", line 357, in increment
    raise six.reraise(type(error), error, _stacktrace)
  File "/Library/Frameworks/Python.framework/Versions/3.6/lib/python3.6/site-packages/urllib3/packages/six.py", line 685, in reraise
    raise value.with_traceback(tb)
  File "/Library/Frameworks/Python.framework/Versions/3.6/lib/python3.6/site-packages/urllib3/connectionpool.py", line 601, in urlopen
    chunked=chunked)
  File "/Library/Frameworks/Python.framework/Versions/3.6/lib/python3.6/site-packages/urllib3/connectionpool.py", line 387, in _make_request
    six.raise_from(e, None)
  File "<string>", line 2, in raise_from
  File "/Library/Frameworks/Python.framework/Versions/3.6/lib/python3.6/site-packages/urllib3/connectionpool.py", line 383, in _make_request
    httplib_response = conn.getresponse()
  File "/Library/Frameworks/Python.framework/Versions/3.6/lib/python3.6/http/client.py", line 1331, in getresponse
    response.begin()
  File "/Library/Frameworks/Python.framework/Versions/3.6/lib/python3.6/http/client.py", line 297, in begin
    version, status, reason = self._read_status()
  File "/Library/Frameworks/Python.framework/Versions/3.6/lib/python3.6/http/client.py", line 258, in _read_status
    line = str(self.fp.readline(_MAXLINE + 1), "iso-8859-1")
  File "/Library/Frameworks/Python.framework/Versions/3.6/lib/python3.6/socket.py", line 586, in readinto
    return self._sock.recv_into(b)
  File "/Library/Frameworks/Python.framework/Versions/3.6/lib/python3.6/site-packages/urllib3/contrib/pyopenssl.py", line 296, in recv_into
    return self.recv_into(*args, **kwargs)
  File "/Library/Frameworks/Python.framework/Versions/3.6/lib/python3.6/site-packages/urllib3/contrib/pyopenssl.py", line 285, in recv_into
    raise SocketError(str(e))
urllib3.exceptions.ProtocolError: ('Connection aborted.', OSError("(54, 'ECONNRESET')",))

During handling of the above exception, another exception occurred:

Traceback (most recent call last):
  File "/Users/hepting/Sites/dhhepting.github.io/script/sharemedia.py", line 71, in <module>
    share = dbx.sharing_create_shared_link(dbp)
  File "/Library/Frameworks/Python.framework/Versions/3.6/lib/python3.6/site-packages/dropbox/base.py", line 3095, in sharing_create_shared_link
    None,
  File "/Library/Frameworks/Python.framework/Versions/3.6/lib/python3.6/site-packages/dropbox/dropbox.py", line 272, in request
    timeout=timeout)
  File "/Library/Frameworks/Python.framework/Versions/3.6/lib/python3.6/site-packages/dropbox/dropbox.py", line 363, in request_json_string_with_retry
    timeout=timeout)
  File "/Library/Frameworks/Python.framework/Versions/3.6/lib/python3.6/site-packages/dropbox/dropbox.py", line 447, in request_json_string
    timeout=timeout,
  File "/Library/Frameworks/Python.framework/Versions/3.6/lib/python3.6/site-packages/requests/sessions.py", line 555, in post
    return self.request('POST', url, data=data, json=json, **kwargs)
  File "/Library/Frameworks/Python.framework/Versions/3.6/lib/python3.6/site-packages/requests/sessions.py", line 508, in request
    resp = self.send(prep, **send_kwargs)
  File "/Library/Frameworks/Python.framework/Versions/3.6/lib/python3.6/site-packages/requests/sessions.py", line 618, in send
    r = adapter.send(request, **kwargs)
  File "/Library/Frameworks/Python.framework/Versions/3.6/lib/python3.6/site-packages/requests/adapters.py", line 490, in send
    raise ConnectionError(err, request=request)
requests.exceptions.ConnectionError: ('Connection aborted.', OSError("(54, 'ECONNRESET')",))
2019-05-12 14:00:03.530665
2019-05-13 14:00:05.318307
2019-05-14 14:08:48.915100
2019-05-15 14:00:05.578624
2019-05-16 14:00:04.699711
2019-05-17 14:00:04.740448
2019-05-18 14:00:03.929341
2019-05-19 17:52:59.292591
2019-05-20 14:00:03.722883
2019-05-21 14:00:03.757171
2019-05-22 14:00:06.423608
2019-05-23 16:17:59.914208
Traceback (most recent call last):
  File "/Library/Frameworks/Python.framework/Versions/3.6/lib/python3.6/site-packages/urllib3/connection.py", line 141, in _new_conn
    (self.host, self.port), self.timeout, **extra_kw)
  File "/Library/Frameworks/Python.framework/Versions/3.6/lib/python3.6/site-packages/urllib3/util/connection.py", line 60, in create_connection
    for res in socket.getaddrinfo(host, port, family, socket.SOCK_STREAM):
  File "/Library/Frameworks/Python.framework/Versions/3.6/lib/python3.6/socket.py", line 745, in getaddrinfo
    for res in _socket.getaddrinfo(host, port, family, type, proto, flags):
socket.gaierror: [Errno 8] nodename nor servname provided, or not known

During handling of the above exception, another exception occurred:

Traceback (most recent call last):
  File "/Library/Frameworks/Python.framework/Versions/3.6/lib/python3.6/site-packages/urllib3/connectionpool.py", line 601, in urlopen
    chunked=chunked)
  File "/Library/Frameworks/Python.framework/Versions/3.6/lib/python3.6/site-packages/urllib3/connectionpool.py", line 346, in _make_request
    self._validate_conn(conn)
  File "/Library/Frameworks/Python.framework/Versions/3.6/lib/python3.6/site-packages/urllib3/connectionpool.py", line 850, in _validate_conn
    conn.connect()
  File "/Library/Frameworks/Python.framework/Versions/3.6/lib/python3.6/site-packages/urllib3/connection.py", line 284, in connect
    conn = self._new_conn()
  File "/Library/Frameworks/Python.framework/Versions/3.6/lib/python3.6/site-packages/urllib3/connection.py", line 150, in _new_conn
    self, "Failed to establish a new connection: %s" % e)
urllib3.exceptions.NewConnectionError: <urllib3.connection.VerifiedHTTPSConnection object at 0x10f15f898>: Failed to establish a new connection: [Errno 8] nodename nor servname provided, or not known

During handling of the above exception, another exception occurred:

Traceback (most recent call last):
  File "/Library/Frameworks/Python.framework/Versions/3.6/lib/python3.6/site-packages/requests/adapters.py", line 440, in send
    timeout=timeout
  File "/Library/Frameworks/Python.framework/Versions/3.6/lib/python3.6/site-packages/urllib3/connectionpool.py", line 639, in urlopen
    _stacktrace=sys.exc_info()[2])
  File "/Library/Frameworks/Python.framework/Versions/3.6/lib/python3.6/site-packages/urllib3/util/retry.py", line 388, in increment
    raise MaxRetryError(_pool, url, error or ResponseError(cause))
urllib3.exceptions.MaxRetryError: HTTPSConnectionPool(host='api.dropboxapi.com', port=443): Max retries exceeded with url: /2/users/get_current_account (Caused by NewConnectionError('<urllib3.connection.VerifiedHTTPSConnection object at 0x10f15f898>: Failed to establish a new connection: [Errno 8] nodename nor servname provided, or not known',))

During handling of the above exception, another exception occurred:

Traceback (most recent call last):
  File "/Users/hepting/Sites/dhhepting.github.io/script/sharemedia.py", line 53, in <module>
    dbx.users_get_current_account()
  File "/Library/Frameworks/Python.framework/Versions/3.6/lib/python3.6/site-packages/dropbox/base.py", line 4301, in users_get_current_account
    None,
  File "/Library/Frameworks/Python.framework/Versions/3.6/lib/python3.6/site-packages/dropbox/dropbox.py", line 272, in request
    timeout=timeout)
  File "/Library/Frameworks/Python.framework/Versions/3.6/lib/python3.6/site-packages/dropbox/dropbox.py", line 363, in request_json_string_with_retry
    timeout=timeout)
  File "/Library/Frameworks/Python.framework/Versions/3.6/lib/python3.6/site-packages/dropbox/dropbox.py", line 447, in request_json_string
    timeout=timeout,
  File "/Library/Frameworks/Python.framework/Versions/3.6/lib/python3.6/site-packages/requests/sessions.py", line 555, in post
    return self.request('POST', url, data=data, json=json, **kwargs)
  File "/Library/Frameworks/Python.framework/Versions/3.6/lib/python3.6/site-packages/requests/sessions.py", line 508, in request
    resp = self.send(prep, **send_kwargs)
  File "/Library/Frameworks/Python.framework/Versions/3.6/lib/python3.6/site-packages/requests/sessions.py", line 618, in send
    r = adapter.send(request, **kwargs)
  File "/Library/Frameworks/Python.framework/Versions/3.6/lib/python3.6/site-packages/requests/adapters.py", line 508, in send
    raise ConnectionError(e, request=request)
requests.exceptions.ConnectionError: HTTPSConnectionPool(host='api.dropboxapi.com', port=443): Max retries exceeded with url: /2/users/get_current_account (Caused by NewConnectionError('<urllib3.connection.VerifiedHTTPSConnection object at 0x10f15f898>: Failed to establish a new connection: [Errno 8] nodename nor servname provided, or not known',))
2019-05-24 14:00:08.135137
2019-05-26 07:12:07.029653
Traceback (most recent call last):
  File "/Library/Frameworks/Python.framework/Versions/3.6/lib/python3.6/site-packages/urllib3/connectionpool.py", line 601, in urlopen
    chunked=chunked)
  File "/Library/Frameworks/Python.framework/Versions/3.6/lib/python3.6/site-packages/urllib3/connectionpool.py", line 387, in _make_request
    six.raise_from(e, None)
  File "<string>", line 2, in raise_from
  File "/Library/Frameworks/Python.framework/Versions/3.6/lib/python3.6/site-packages/urllib3/connectionpool.py", line 383, in _make_request
    httplib_response = conn.getresponse()
  File "/Library/Frameworks/Python.framework/Versions/3.6/lib/python3.6/http/client.py", line 1331, in getresponse
    response.begin()
  File "/Library/Frameworks/Python.framework/Versions/3.6/lib/python3.6/http/client.py", line 297, in begin
    version, status, reason = self._read_status()
  File "/Library/Frameworks/Python.framework/Versions/3.6/lib/python3.6/http/client.py", line 258, in _read_status
    line = str(self.fp.readline(_MAXLINE + 1), "iso-8859-1")
  File "/Library/Frameworks/Python.framework/Versions/3.6/lib/python3.6/socket.py", line 586, in readinto
    return self._sock.recv_into(b)
  File "/Library/Frameworks/Python.framework/Versions/3.6/lib/python3.6/site-packages/urllib3/contrib/pyopenssl.py", line 296, in recv_into
    return self.recv_into(*args, **kwargs)
  File "/Library/Frameworks/Python.framework/Versions/3.6/lib/python3.6/site-packages/urllib3/contrib/pyopenssl.py", line 285, in recv_into
    raise SocketError(str(e))
OSError: (54, 'ECONNRESET')

During handling of the above exception, another exception occurred:

Traceback (most recent call last):
  File "/Library/Frameworks/Python.framework/Versions/3.6/lib/python3.6/site-packages/requests/adapters.py", line 440, in send
    timeout=timeout
  File "/Library/Frameworks/Python.framework/Versions/3.6/lib/python3.6/site-packages/urllib3/connectionpool.py", line 639, in urlopen
    _stacktrace=sys.exc_info()[2])
  File "/Library/Frameworks/Python.framework/Versions/3.6/lib/python3.6/site-packages/urllib3/util/retry.py", line 357, in increment
    raise six.reraise(type(error), error, _stacktrace)
  File "/Library/Frameworks/Python.framework/Versions/3.6/lib/python3.6/site-packages/urllib3/packages/six.py", line 685, in reraise
    raise value.with_traceback(tb)
  File "/Library/Frameworks/Python.framework/Versions/3.6/lib/python3.6/site-packages/urllib3/connectionpool.py", line 601, in urlopen
    chunked=chunked)
  File "/Library/Frameworks/Python.framework/Versions/3.6/lib/python3.6/site-packages/urllib3/connectionpool.py", line 387, in _make_request
    six.raise_from(e, None)
  File "<string>", line 2, in raise_from
  File "/Library/Frameworks/Python.framework/Versions/3.6/lib/python3.6/site-packages/urllib3/connectionpool.py", line 383, in _make_request
    httplib_response = conn.getresponse()
  File "/Library/Frameworks/Python.framework/Versions/3.6/lib/python3.6/http/client.py", line 1331, in getresponse
    response.begin()
  File "/Library/Frameworks/Python.framework/Versions/3.6/lib/python3.6/http/client.py", line 297, in begin
    version, status, reason = self._read_status()
  File "/Library/Frameworks/Python.framework/Versions/3.6/lib/python3.6/http/client.py", line 258, in _read_status
    line = str(self.fp.readline(_MAXLINE + 1), "iso-8859-1")
  File "/Library/Frameworks/Python.framework/Versions/3.6/lib/python3.6/socket.py", line 586, in readinto
    return self._sock.recv_into(b)
  File "/Library/Frameworks/Python.framework/Versions/3.6/lib/python3.6/site-packages/urllib3/contrib/pyopenssl.py", line 296, in recv_into
    return self.recv_into(*args, **kwargs)
  File "/Library/Frameworks/Python.framework/Versions/3.6/lib/python3.6/site-packages/urllib3/contrib/pyopenssl.py", line 285, in recv_into
    raise SocketError(str(e))
urllib3.exceptions.ProtocolError: ('Connection aborted.', OSError("(54, 'ECONNRESET')",))

During handling of the above exception, another exception occurred:

Traceback (most recent call last):
  File "/Users/hepting/Sites/dhhepting.github.io/script/sharemedia.py", line 71, in <module>
    share = dbx.sharing_create_shared_link(dbp)
  File "/Library/Frameworks/Python.framework/Versions/3.6/lib/python3.6/site-packages/dropbox/base.py", line 3095, in sharing_create_shared_link
    None,
  File "/Library/Frameworks/Python.framework/Versions/3.6/lib/python3.6/site-packages/dropbox/dropbox.py", line 272, in request
    timeout=timeout)
  File "/Library/Frameworks/Python.framework/Versions/3.6/lib/python3.6/site-packages/dropbox/dropbox.py", line 363, in request_json_string_with_retry
    timeout=timeout)
  File "/Library/Frameworks/Python.framework/Versions/3.6/lib/python3.6/site-packages/dropbox/dropbox.py", line 447, in request_json_string
    timeout=timeout,
  File "/Library/Frameworks/Python.framework/Versions/3.6/lib/python3.6/site-packages/requests/sessions.py", line 555, in post
    return self.request('POST', url, data=data, json=json, **kwargs)
  File "/Library/Frameworks/Python.framework/Versions/3.6/lib/python3.6/site-packages/requests/sessions.py", line 508, in request
    resp = self.send(prep, **send_kwargs)
  File "/Library/Frameworks/Python.framework/Versions/3.6/lib/python3.6/site-packages/requests/sessions.py", line 618, in send
    r = adapter.send(request, **kwargs)
  File "/Library/Frameworks/Python.framework/Versions/3.6/lib/python3.6/site-packages/requests/adapters.py", line 490, in send
    raise ConnectionError(err, request=request)
requests.exceptions.ConnectionError: ('Connection aborted.', OSError("(54, 'ECONNRESET')",))
2019-05-27 00:00:07.627388
2019-05-27 14:00:05.456411
2019-05-28 14:02:52.172107
2019-05-29 10:38:13.721853
2019-05-29 11:52:40.834888
2019-05-29 14:00:02.705933
2019-05-30 14:00:05.646319
2019-05-31 15:05:06.299689
2019-06-01 14:00:05.852517
2019-06-01 21:06:09.390387
2019-06-02 14:16:47.971746
2019-06-02 21:28:11.256458
2019-06-03 14:30:06.284477
Traceback (most recent call last):
  File "/Library/Frameworks/Python.framework/Versions/3.6/lib/python3.6/site-packages/urllib3/connection.py", line 141, in _new_conn
    (self.host, self.port), self.timeout, **extra_kw)
  File "/Library/Frameworks/Python.framework/Versions/3.6/lib/python3.6/site-packages/urllib3/util/connection.py", line 60, in create_connection
    for res in socket.getaddrinfo(host, port, family, socket.SOCK_STREAM):
  File "/Library/Frameworks/Python.framework/Versions/3.6/lib/python3.6/socket.py", line 745, in getaddrinfo
    for res in _socket.getaddrinfo(host, port, family, type, proto, flags):
socket.gaierror: [Errno 8] nodename nor servname provided, or not known

During handling of the above exception, another exception occurred:

Traceback (most recent call last):
  File "/Library/Frameworks/Python.framework/Versions/3.6/lib/python3.6/site-packages/urllib3/connectionpool.py", line 601, in urlopen
    chunked=chunked)
  File "/Library/Frameworks/Python.framework/Versions/3.6/lib/python3.6/site-packages/urllib3/connectionpool.py", line 346, in _make_request
    self._validate_conn(conn)
  File "/Library/Frameworks/Python.framework/Versions/3.6/lib/python3.6/site-packages/urllib3/connectionpool.py", line 850, in _validate_conn
    conn.connect()
  File "/Library/Frameworks/Python.framework/Versions/3.6/lib/python3.6/site-packages/urllib3/connection.py", line 284, in connect
    conn = self._new_conn()
  File "/Library/Frameworks/Python.framework/Versions/3.6/lib/python3.6/site-packages/urllib3/connection.py", line 150, in _new_conn
    self, "Failed to establish a new connection: %s" % e)
urllib3.exceptions.NewConnectionError: <urllib3.connection.VerifiedHTTPSConnection object at 0x10f36f710>: Failed to establish a new connection: [Errno 8] nodename nor servname provided, or not known

During handling of the above exception, another exception occurred:

Traceback (most recent call last):
  File "/Library/Frameworks/Python.framework/Versions/3.6/lib/python3.6/site-packages/requests/adapters.py", line 440, in send
    timeout=timeout
  File "/Library/Frameworks/Python.framework/Versions/3.6/lib/python3.6/site-packages/urllib3/connectionpool.py", line 639, in urlopen
    _stacktrace=sys.exc_info()[2])
  File "/Library/Frameworks/Python.framework/Versions/3.6/lib/python3.6/site-packages/urllib3/util/retry.py", line 388, in increment
    raise MaxRetryError(_pool, url, error or ResponseError(cause))
urllib3.exceptions.MaxRetryError: HTTPSConnectionPool(host='api.dropboxapi.com', port=443): Max retries exceeded with url: /2/users/get_current_account (Caused by NewConnectionError('<urllib3.connection.VerifiedHTTPSConnection object at 0x10f36f710>: Failed to establish a new connection: [Errno 8] nodename nor servname provided, or not known',))

During handling of the above exception, another exception occurred:

Traceback (most recent call last):
  File "/Users/hepting/Sites/dhhepting.github.io/script/sharemedia.py", line 53, in <module>
    dbx.users_get_current_account()
  File "/Library/Frameworks/Python.framework/Versions/3.6/lib/python3.6/site-packages/dropbox/base.py", line 4301, in users_get_current_account
    None,
  File "/Library/Frameworks/Python.framework/Versions/3.6/lib/python3.6/site-packages/dropbox/dropbox.py", line 272, in request
    timeout=timeout)
  File "/Library/Frameworks/Python.framework/Versions/3.6/lib/python3.6/site-packages/dropbox/dropbox.py", line 363, in request_json_string_with_retry
    timeout=timeout)
  File "/Library/Frameworks/Python.framework/Versions/3.6/lib/python3.6/site-packages/dropbox/dropbox.py", line 447, in request_json_string
    timeout=timeout,
  File "/Library/Frameworks/Python.framework/Versions/3.6/lib/python3.6/site-packages/requests/sessions.py", line 555, in post
    return self.request('POST', url, data=data, json=json, **kwargs)
  File "/Library/Frameworks/Python.framework/Versions/3.6/lib/python3.6/site-packages/requests/sessions.py", line 508, in request
    resp = self.send(prep, **send_kwargs)
  File "/Library/Frameworks/Python.framework/Versions/3.6/lib/python3.6/site-packages/requests/sessions.py", line 618, in send
    r = adapter.send(request, **kwargs)
  File "/Library/Frameworks/Python.framework/Versions/3.6/lib/python3.6/site-packages/requests/adapters.py", line 508, in send
    raise ConnectionError(e, request=request)
requests.exceptions.ConnectionError: HTTPSConnectionPool(host='api.dropboxapi.com', port=443): Max retries exceeded with url: /2/users/get_current_account (Caused by NewConnectionError('<urllib3.connection.VerifiedHTTPSConnection object at 0x10f36f710>: Failed to establish a new connection: [Errno 8] nodename nor servname provided, or not known',))
2019-06-04 14:00:03.700748
2019-06-05 14:00:03.687447
2019-06-06 21:00:23.010626
Traceback (most recent call last):
  File "/Library/Frameworks/Python.framework/Versions/3.6/lib/python3.6/site-packages/urllib3/connection.py", line 141, in _new_conn
    (self.host, self.port), self.timeout, **extra_kw)
  File "/Library/Frameworks/Python.framework/Versions/3.6/lib/python3.6/site-packages/urllib3/util/connection.py", line 60, in create_connection
    for res in socket.getaddrinfo(host, port, family, socket.SOCK_STREAM):
  File "/Library/Frameworks/Python.framework/Versions/3.6/lib/python3.6/socket.py", line 745, in getaddrinfo
    for res in _socket.getaddrinfo(host, port, family, type, proto, flags):
socket.gaierror: [Errno 8] nodename nor servname provided, or not known

During handling of the above exception, another exception occurred:

Traceback (most recent call last):
  File "/Library/Frameworks/Python.framework/Versions/3.6/lib/python3.6/site-packages/urllib3/connectionpool.py", line 601, in urlopen
    chunked=chunked)
  File "/Library/Frameworks/Python.framework/Versions/3.6/lib/python3.6/site-packages/urllib3/connectionpool.py", line 346, in _make_request
    self._validate_conn(conn)
  File "/Library/Frameworks/Python.framework/Versions/3.6/lib/python3.6/site-packages/urllib3/connectionpool.py", line 850, in _validate_conn
    conn.connect()
  File "/Library/Frameworks/Python.framework/Versions/3.6/lib/python3.6/site-packages/urllib3/connection.py", line 284, in connect
    conn = self._new_conn()
  File "/Library/Frameworks/Python.framework/Versions/3.6/lib/python3.6/site-packages/urllib3/connection.py", line 150, in _new_conn
    self, "Failed to establish a new connection: %s" % e)
urllib3.exceptions.NewConnectionError: <urllib3.connection.VerifiedHTTPSConnection object at 0x10f36c390>: Failed to establish a new connection: [Errno 8] nodename nor servname provided, or not known

During handling of the above exception, another exception occurred:

Traceback (most recent call last):
  File "/Library/Frameworks/Python.framework/Versions/3.6/lib/python3.6/site-packages/requests/adapters.py", line 440, in send
    timeout=timeout
  File "/Library/Frameworks/Python.framework/Versions/3.6/lib/python3.6/site-packages/urllib3/connectionpool.py", line 639, in urlopen
    _stacktrace=sys.exc_info()[2])
  File "/Library/Frameworks/Python.framework/Versions/3.6/lib/python3.6/site-packages/urllib3/util/retry.py", line 388, in increment
    raise MaxRetryError(_pool, url, error or ResponseError(cause))
urllib3.exceptions.MaxRetryError: HTTPSConnectionPool(host='api.dropboxapi.com', port=443): Max retries exceeded with url: /2/users/get_current_account (Caused by NewConnectionError('<urllib3.connection.VerifiedHTTPSConnection object at 0x10f36c390>: Failed to establish a new connection: [Errno 8] nodename nor servname provided, or not known',))

During handling of the above exception, another exception occurred:

Traceback (most recent call last):
  File "/Users/hepting/Sites/dhhepting.github.io/script/sharemedia.py", line 53, in <module>
    dbx.users_get_current_account()
  File "/Library/Frameworks/Python.framework/Versions/3.6/lib/python3.6/site-packages/dropbox/base.py", line 4301, in users_get_current_account
    None,
  File "/Library/Frameworks/Python.framework/Versions/3.6/lib/python3.6/site-packages/dropbox/dropbox.py", line 272, in request
    timeout=timeout)
  File "/Library/Frameworks/Python.framework/Versions/3.6/lib/python3.6/site-packages/dropbox/dropbox.py", line 363, in request_json_string_with_retry
    timeout=timeout)
  File "/Library/Frameworks/Python.framework/Versions/3.6/lib/python3.6/site-packages/dropbox/dropbox.py", line 447, in request_json_string
    timeout=timeout,
  File "/Library/Frameworks/Python.framework/Versions/3.6/lib/python3.6/site-packages/requests/sessions.py", line 555, in post
    return self.request('POST', url, data=data, json=json, **kwargs)
  File "/Library/Frameworks/Python.framework/Versions/3.6/lib/python3.6/site-packages/requests/sessions.py", line 508, in request
    resp = self.send(prep, **send_kwargs)
  File "/Library/Frameworks/Python.framework/Versions/3.6/lib/python3.6/site-packages/requests/sessions.py", line 618, in send
    r = adapter.send(request, **kwargs)
  File "/Library/Frameworks/Python.framework/Versions/3.6/lib/python3.6/site-packages/requests/adapters.py", line 508, in send
    raise ConnectionError(e, request=request)
requests.exceptions.ConnectionError: HTTPSConnectionPool(host='api.dropboxapi.com', port=443): Max retries exceeded with url: /2/users/get_current_account (Caused by NewConnectionError('<urllib3.connection.VerifiedHTTPSConnection object at 0x10f36c390>: Failed to establish a new connection: [Errno 8] nodename nor servname provided, or not known',))
2019-06-07 14:00:03.890122
2019-06-08 16:55:57.135074
2019-06-09 15:00:22.649754
2019-06-10 14:00:03.541436
2019-07-25 14:25:35.824015
Traceback (most recent call last):
  File "/Library/Frameworks/Python.framework/Versions/3.6/lib/python3.6/site-packages/urllib3/connection.py", line 141, in _new_conn
    (self.host, self.port), self.timeout, **extra_kw)
  File "/Library/Frameworks/Python.framework/Versions/3.6/lib/python3.6/site-packages/urllib3/util/connection.py", line 60, in create_connection
    for res in socket.getaddrinfo(host, port, family, socket.SOCK_STREAM):
  File "/Library/Frameworks/Python.framework/Versions/3.6/lib/python3.6/socket.py", line 745, in getaddrinfo
    for res in _socket.getaddrinfo(host, port, family, type, proto, flags):
socket.gaierror: [Errno 8] nodename nor servname provided, or not known

During handling of the above exception, another exception occurred:

Traceback (most recent call last):
  File "/Library/Frameworks/Python.framework/Versions/3.6/lib/python3.6/site-packages/urllib3/connectionpool.py", line 601, in urlopen
    chunked=chunked)
  File "/Library/Frameworks/Python.framework/Versions/3.6/lib/python3.6/site-packages/urllib3/connectionpool.py", line 346, in _make_request
    self._validate_conn(conn)
  File "/Library/Frameworks/Python.framework/Versions/3.6/lib/python3.6/site-packages/urllib3/connectionpool.py", line 850, in _validate_conn
    conn.connect()
  File "/Library/Frameworks/Python.framework/Versions/3.6/lib/python3.6/site-packages/urllib3/connection.py", line 284, in connect
    conn = self._new_conn()
  File "/Library/Frameworks/Python.framework/Versions/3.6/lib/python3.6/site-packages/urllib3/connection.py", line 150, in _new_conn
    self, "Failed to establish a new connection: %s" % e)
urllib3.exceptions.NewConnectionError: <urllib3.connection.VerifiedHTTPSConnection object at 0x10f389320>: Failed to establish a new connection: [Errno 8] nodename nor servname provided, or not known

During handling of the above exception, another exception occurred:

Traceback (most recent call last):
  File "/Library/Frameworks/Python.framework/Versions/3.6/lib/python3.6/site-packages/requests/adapters.py", line 440, in send
    timeout=timeout
  File "/Library/Frameworks/Python.framework/Versions/3.6/lib/python3.6/site-packages/urllib3/connectionpool.py", line 639, in urlopen
    _stacktrace=sys.exc_info()[2])
  File "/Library/Frameworks/Python.framework/Versions/3.6/lib/python3.6/site-packages/urllib3/util/retry.py", line 388, in increment
    raise MaxRetryError(_pool, url, error or ResponseError(cause))
urllib3.exceptions.MaxRetryError: HTTPSConnectionPool(host='api.dropboxapi.com', port=443): Max retries exceeded with url: /2/users/get_current_account (Caused by NewConnectionError('<urllib3.connection.VerifiedHTTPSConnection object at 0x10f389320>: Failed to establish a new connection: [Errno 8] nodename nor servname provided, or not known',))

During handling of the above exception, another exception occurred:

Traceback (most recent call last):
  File "/Users/hepting/Sites/dhhepting.github.io/script/sharemedia.py", line 53, in <module>
    dbx.users_get_current_account()
  File "/Library/Frameworks/Python.framework/Versions/3.6/lib/python3.6/site-packages/dropbox/base.py", line 4301, in users_get_current_account
    None,
  File "/Library/Frameworks/Python.framework/Versions/3.6/lib/python3.6/site-packages/dropbox/dropbox.py", line 272, in request
    timeout=timeout)
  File "/Library/Frameworks/Python.framework/Versions/3.6/lib/python3.6/site-packages/dropbox/dropbox.py", line 363, in request_json_string_with_retry
    timeout=timeout)
  File "/Library/Frameworks/Python.framework/Versions/3.6/lib/python3.6/site-packages/dropbox/dropbox.py", line 447, in request_json_string
    timeout=timeout,
  File "/Library/Frameworks/Python.framework/Versions/3.6/lib/python3.6/site-packages/requests/sessions.py", line 555, in post
    return self.request('POST', url, data=data, json=json, **kwargs)
  File "/Library/Frameworks/Python.framework/Versions/3.6/lib/python3.6/site-packages/requests/sessions.py", line 508, in request
    resp = self.send(prep, **send_kwargs)
  File "/Library/Frameworks/Python.framework/Versions/3.6/lib/python3.6/site-packages/requests/sessions.py", line 618, in send
    r = adapter.send(request, **kwargs)
  File "/Library/Frameworks/Python.framework/Versions/3.6/lib/python3.6/site-packages/requests/adapters.py", line 508, in send
    raise ConnectionError(e, request=request)
requests.exceptions.ConnectionError: HTTPSConnectionPool(host='api.dropboxapi.com', port=443): Max retries exceeded with url: /2/users/get_current_account (Caused by NewConnectionError('<urllib3.connection.VerifiedHTTPSConnection object at 0x10f389320>: Failed to establish a new connection: [Errno 8] nodename nor servname provided, or not known',))
2019-07-26 14:00:04.080374
2019-07-27 15:40:26.248614
2019-07-28 15:45:25.517910
2019-07-29 14:58:11.944159
2019-07-30 14:00:03.315500
2019-07-31 14:00:03.558681
2019-08-01 14:01:19.773886
2019-08-02 14:35:33.547668
2019-08-03 18:21:31.489668
2019-08-04 19:59:37.409334
Traceback (most recent call last):
  File "/Library/Frameworks/Python.framework/Versions/3.6/lib/python3.6/site-packages/urllib3/connection.py", line 141, in _new_conn
    (self.host, self.port), self.timeout, **extra_kw)
  File "/Library/Frameworks/Python.framework/Versions/3.6/lib/python3.6/site-packages/urllib3/util/connection.py", line 60, in create_connection
    for res in socket.getaddrinfo(host, port, family, socket.SOCK_STREAM):
  File "/Library/Frameworks/Python.framework/Versions/3.6/lib/python3.6/socket.py", line 745, in getaddrinfo
    for res in _socket.getaddrinfo(host, port, family, type, proto, flags):
socket.gaierror: [Errno 8] nodename nor servname provided, or not known

During handling of the above exception, another exception occurred:

Traceback (most recent call last):
  File "/Library/Frameworks/Python.framework/Versions/3.6/lib/python3.6/site-packages/urllib3/connectionpool.py", line 601, in urlopen
    chunked=chunked)
  File "/Library/Frameworks/Python.framework/Versions/3.6/lib/python3.6/site-packages/urllib3/connectionpool.py", line 346, in _make_request
    self._validate_conn(conn)
  File "/Library/Frameworks/Python.framework/Versions/3.6/lib/python3.6/site-packages/urllib3/connectionpool.py", line 850, in _validate_conn
    conn.connect()
  File "/Library/Frameworks/Python.framework/Versions/3.6/lib/python3.6/site-packages/urllib3/connection.py", line 284, in connect
    conn = self._new_conn()
  File "/Library/Frameworks/Python.framework/Versions/3.6/lib/python3.6/site-packages/urllib3/connection.py", line 150, in _new_conn
    self, "Failed to establish a new connection: %s" % e)
urllib3.exceptions.NewConnectionError: <urllib3.connection.VerifiedHTTPSConnection object at 0x10f392d68>: Failed to establish a new connection: [Errno 8] nodename nor servname provided, or not known

During handling of the above exception, another exception occurred:

Traceback (most recent call last):
  File "/Library/Frameworks/Python.framework/Versions/3.6/lib/python3.6/site-packages/requests/adapters.py", line 440, in send
    timeout=timeout
  File "/Library/Frameworks/Python.framework/Versions/3.6/lib/python3.6/site-packages/urllib3/connectionpool.py", line 639, in urlopen
    _stacktrace=sys.exc_info()[2])
  File "/Library/Frameworks/Python.framework/Versions/3.6/lib/python3.6/site-packages/urllib3/util/retry.py", line 388, in increment
    raise MaxRetryError(_pool, url, error or ResponseError(cause))
urllib3.exceptions.MaxRetryError: HTTPSConnectionPool(host='api.dropboxapi.com', port=443): Max retries exceeded with url: /2/users/get_current_account (Caused by NewConnectionError('<urllib3.connection.VerifiedHTTPSConnection object at 0x10f392d68>: Failed to establish a new connection: [Errno 8] nodename nor servname provided, or not known',))

During handling of the above exception, another exception occurred:

Traceback (most recent call last):
  File "/Users/hepting/Sites/dhhepting.github.io/script/sharemedia.py", line 53, in <module>
    dbx.users_get_current_account()
  File "/Library/Frameworks/Python.framework/Versions/3.6/lib/python3.6/site-packages/dropbox/base.py", line 4301, in users_get_current_account
    None,
  File "/Library/Frameworks/Python.framework/Versions/3.6/lib/python3.6/site-packages/dropbox/dropbox.py", line 272, in request
    timeout=timeout)
  File "/Library/Frameworks/Python.framework/Versions/3.6/lib/python3.6/site-packages/dropbox/dropbox.py", line 363, in request_json_string_with_retry
    timeout=timeout)
  File "/Library/Frameworks/Python.framework/Versions/3.6/lib/python3.6/site-packages/dropbox/dropbox.py", line 447, in request_json_string
    timeout=timeout,
  File "/Library/Frameworks/Python.framework/Versions/3.6/lib/python3.6/site-packages/requests/sessions.py", line 555, in post
    return self.request('POST', url, data=data, json=json, **kwargs)
  File "/Library/Frameworks/Python.framework/Versions/3.6/lib/python3.6/site-packages/requests/sessions.py", line 508, in request
    resp = self.send(prep, **send_kwargs)
  File "/Library/Frameworks/Python.framework/Versions/3.6/lib/python3.6/site-packages/requests/sessions.py", line 618, in send
    r = adapter.send(request, **kwargs)
  File "/Library/Frameworks/Python.framework/Versions/3.6/lib/python3.6/site-packages/requests/adapters.py", line 508, in send
    raise ConnectionError(e, request=request)
requests.exceptions.ConnectionError: HTTPSConnectionPool(host='api.dropboxapi.com', port=443): Max retries exceeded with url: /2/users/get_current_account (Caused by NewConnectionError('<urllib3.connection.VerifiedHTTPSConnection object at 0x10f392d68>: Failed to establish a new connection: [Errno 8] nodename nor servname provided, or not known',))
2019-08-05 17:15:03.992714
Traceback (most recent call last):
  File "/Library/Frameworks/Python.framework/Versions/3.6/lib/python3.6/site-packages/urllib3/connection.py", line 141, in _new_conn
    (self.host, self.port), self.timeout, **extra_kw)
  File "/Library/Frameworks/Python.framework/Versions/3.6/lib/python3.6/site-packages/urllib3/util/connection.py", line 60, in create_connection
    for res in socket.getaddrinfo(host, port, family, socket.SOCK_STREAM):
  File "/Library/Frameworks/Python.framework/Versions/3.6/lib/python3.6/socket.py", line 745, in getaddrinfo
    for res in _socket.getaddrinfo(host, port, family, type, proto, flags):
socket.gaierror: [Errno 8] nodename nor servname provided, or not known

During handling of the above exception, another exception occurred:

Traceback (most recent call last):
  File "/Library/Frameworks/Python.framework/Versions/3.6/lib/python3.6/site-packages/urllib3/connectionpool.py", line 601, in urlopen
    chunked=chunked)
  File "/Library/Frameworks/Python.framework/Versions/3.6/lib/python3.6/site-packages/urllib3/connectionpool.py", line 346, in _make_request
    self._validate_conn(conn)
  File "/Library/Frameworks/Python.framework/Versions/3.6/lib/python3.6/site-packages/urllib3/connectionpool.py", line 850, in _validate_conn
    conn.connect()
  File "/Library/Frameworks/Python.framework/Versions/3.6/lib/python3.6/site-packages/urllib3/connection.py", line 284, in connect
    conn = self._new_conn()
  File "/Library/Frameworks/Python.framework/Versions/3.6/lib/python3.6/site-packages/urllib3/connection.py", line 150, in _new_conn
    self, "Failed to establish a new connection: %s" % e)
urllib3.exceptions.NewConnectionError: <urllib3.connection.VerifiedHTTPSConnection object at 0x10f392d68>: Failed to establish a new connection: [Errno 8] nodename nor servname provided, or not known

During handling of the above exception, another exception occurred:

Traceback (most recent call last):
  File "/Library/Frameworks/Python.framework/Versions/3.6/lib/python3.6/site-packages/requests/adapters.py", line 440, in send
    timeout=timeout
  File "/Library/Frameworks/Python.framework/Versions/3.6/lib/python3.6/site-packages/urllib3/connectionpool.py", line 639, in urlopen
    _stacktrace=sys.exc_info()[2])
  File "/Library/Frameworks/Python.framework/Versions/3.6/lib/python3.6/site-packages/urllib3/util/retry.py", line 388, in increment
    raise MaxRetryError(_pool, url, error or ResponseError(cause))
urllib3.exceptions.MaxRetryError: HTTPSConnectionPool(host='api.dropboxapi.com', port=443): Max retries exceeded with url: /2/users/get_current_account (Caused by NewConnectionError('<urllib3.connection.VerifiedHTTPSConnection object at 0x10f392d68>: Failed to establish a new connection: [Errno 8] nodename nor servname provided, or not known',))

During handling of the above exception, another exception occurred:

Traceback (most recent call last):
  File "/Users/hepting/Sites/dhhepting.github.io/script/sharemedia.py", line 53, in <module>
    dbx.users_get_current_account()
  File "/Library/Frameworks/Python.framework/Versions/3.6/lib/python3.6/site-packages/dropbox/base.py", line 4301, in users_get_current_account
    None,
  File "/Library/Frameworks/Python.framework/Versions/3.6/lib/python3.6/site-packages/dropbox/dropbox.py", line 272, in request
    timeout=timeout)
  File "/Library/Frameworks/Python.framework/Versions/3.6/lib/python3.6/site-packages/dropbox/dropbox.py", line 363, in request_json_string_with_retry
    timeout=timeout)
  File "/Library/Frameworks/Python.framework/Versions/3.6/lib/python3.6/site-packages/dropbox/dropbox.py", line 447, in request_json_string
    timeout=timeout,
  File "/Library/Frameworks/Python.framework/Versions/3.6/lib/python3.6/site-packages/requests/sessions.py", line 555, in post
    return self.request('POST', url, data=data, json=json, **kwargs)
  File "/Library/Frameworks/Python.framework/Versions/3.6/lib/python3.6/site-packages/requests/sessions.py", line 508, in request
    resp = self.send(prep, **send_kwargs)
  File "/Library/Frameworks/Python.framework/Versions/3.6/lib/python3.6/site-packages/requests/sessions.py", line 618, in send
    r = adapter.send(request, **kwargs)
  File "/Library/Frameworks/Python.framework/Versions/3.6/lib/python3.6/site-packages/requests/adapters.py", line 508, in send
    raise ConnectionError(e, request=request)
requests.exceptions.ConnectionError: HTTPSConnectionPool(host='api.dropboxapi.com', port=443): Max retries exceeded with url: /2/users/get_current_account (Caused by NewConnectionError('<urllib3.connection.VerifiedHTTPSConnection object at 0x10f392d68>: Failed to establish a new connection: [Errno 8] nodename nor servname provided, or not known',))
2019-08-06 23:59:11.444010
Traceback (most recent call last):
  File "/Library/Frameworks/Python.framework/Versions/3.6/lib/python3.6/site-packages/urllib3/connection.py", line 141, in _new_conn
    (self.host, self.port), self.timeout, **extra_kw)
  File "/Library/Frameworks/Python.framework/Versions/3.6/lib/python3.6/site-packages/urllib3/util/connection.py", line 60, in create_connection
    for res in socket.getaddrinfo(host, port, family, socket.SOCK_STREAM):
  File "/Library/Frameworks/Python.framework/Versions/3.6/lib/python3.6/socket.py", line 745, in getaddrinfo
    for res in _socket.getaddrinfo(host, port, family, type, proto, flags):
socket.gaierror: [Errno 8] nodename nor servname provided, or not known

During handling of the above exception, another exception occurred:

Traceback (most recent call last):
  File "/Library/Frameworks/Python.framework/Versions/3.6/lib/python3.6/site-packages/urllib3/connectionpool.py", line 601, in urlopen
    chunked=chunked)
  File "/Library/Frameworks/Python.framework/Versions/3.6/lib/python3.6/site-packages/urllib3/connectionpool.py", line 346, in _make_request
    self._validate_conn(conn)
  File "/Library/Frameworks/Python.framework/Versions/3.6/lib/python3.6/site-packages/urllib3/connectionpool.py", line 850, in _validate_conn
    conn.connect()
  File "/Library/Frameworks/Python.framework/Versions/3.6/lib/python3.6/site-packages/urllib3/connection.py", line 284, in connect
    conn = self._new_conn()
  File "/Library/Frameworks/Python.framework/Versions/3.6/lib/python3.6/site-packages/urllib3/connection.py", line 150, in _new_conn
    self, "Failed to establish a new connection: %s" % e)
urllib3.exceptions.NewConnectionError: <urllib3.connection.VerifiedHTTPSConnection object at 0x10f492320>: Failed to establish a new connection: [Errno 8] nodename nor servname provided, or not known

During handling of the above exception, another exception occurred:

Traceback (most recent call last):
  File "/Library/Frameworks/Python.framework/Versions/3.6/lib/python3.6/site-packages/requests/adapters.py", line 440, in send
    timeout=timeout
  File "/Library/Frameworks/Python.framework/Versions/3.6/lib/python3.6/site-packages/urllib3/connectionpool.py", line 639, in urlopen
    _stacktrace=sys.exc_info()[2])
  File "/Library/Frameworks/Python.framework/Versions/3.6/lib/python3.6/site-packages/urllib3/util/retry.py", line 388, in increment
    raise MaxRetryError(_pool, url, error or ResponseError(cause))
urllib3.exceptions.MaxRetryError: HTTPSConnectionPool(host='api.dropboxapi.com', port=443): Max retries exceeded with url: /2/users/get_current_account (Caused by NewConnectionError('<urllib3.connection.VerifiedHTTPSConnection object at 0x10f492320>: Failed to establish a new connection: [Errno 8] nodename nor servname provided, or not known',))

During handling of the above exception, another exception occurred:

Traceback (most recent call last):
  File "/Users/hepting/Sites/dhhepting.github.io/script/sharemedia.py", line 53, in <module>
    dbx.users_get_current_account()
  File "/Library/Frameworks/Python.framework/Versions/3.6/lib/python3.6/site-packages/dropbox/base.py", line 4301, in users_get_current_account
    None,
  File "/Library/Frameworks/Python.framework/Versions/3.6/lib/python3.6/site-packages/dropbox/dropbox.py", line 272, in request
    timeout=timeout)
  File "/Library/Frameworks/Python.framework/Versions/3.6/lib/python3.6/site-packages/dropbox/dropbox.py", line 363, in request_json_string_with_retry
    timeout=timeout)
  File "/Library/Frameworks/Python.framework/Versions/3.6/lib/python3.6/site-packages/dropbox/dropbox.py", line 447, in request_json_string
    timeout=timeout,
  File "/Library/Frameworks/Python.framework/Versions/3.6/lib/python3.6/site-packages/requests/sessions.py", line 555, in post
    return self.request('POST', url, data=data, json=json, **kwargs)
  File "/Library/Frameworks/Python.framework/Versions/3.6/lib/python3.6/site-packages/requests/sessions.py", line 508, in request
    resp = self.send(prep, **send_kwargs)
  File "/Library/Frameworks/Python.framework/Versions/3.6/lib/python3.6/site-packages/requests/sessions.py", line 618, in send
    r = adapter.send(request, **kwargs)
  File "/Library/Frameworks/Python.framework/Versions/3.6/lib/python3.6/site-packages/requests/adapters.py", line 508, in send
    raise ConnectionError(e, request=request)
requests.exceptions.ConnectionError: HTTPSConnectionPool(host='api.dropboxapi.com', port=443): Max retries exceeded with url: /2/users/get_current_account (Caused by NewConnectionError('<urllib3.connection.VerifiedHTTPSConnection object at 0x10f492320>: Failed to establish a new connection: [Errno 8] nodename nor servname provided, or not known',))
2019-08-08 10:21:51.869027
Traceback (most recent call last):
  File "/Library/Frameworks/Python.framework/Versions/3.6/lib/python3.6/site-packages/urllib3/connection.py", line 141, in _new_conn
    (self.host, self.port), self.timeout, **extra_kw)
  File "/Library/Frameworks/Python.framework/Versions/3.6/lib/python3.6/site-packages/urllib3/util/connection.py", line 60, in create_connection
    for res in socket.getaddrinfo(host, port, family, socket.SOCK_STREAM):
  File "/Library/Frameworks/Python.framework/Versions/3.6/lib/python3.6/socket.py", line 745, in getaddrinfo
    for res in _socket.getaddrinfo(host, port, family, type, proto, flags):
socket.gaierror: [Errno 8] nodename nor servname provided, or not known

During handling of the above exception, another exception occurred:

Traceback (most recent call last):
  File "/Library/Frameworks/Python.framework/Versions/3.6/lib/python3.6/site-packages/urllib3/connectionpool.py", line 601, in urlopen
    chunked=chunked)
  File "/Library/Frameworks/Python.framework/Versions/3.6/lib/python3.6/site-packages/urllib3/connectionpool.py", line 346, in _make_request
    self._validate_conn(conn)
  File "/Library/Frameworks/Python.framework/Versions/3.6/lib/python3.6/site-packages/urllib3/connectionpool.py", line 850, in _validate_conn
    conn.connect()
  File "/Library/Frameworks/Python.framework/Versions/3.6/lib/python3.6/site-packages/urllib3/connection.py", line 284, in connect
    conn = self._new_conn()
  File "/Library/Frameworks/Python.framework/Versions/3.6/lib/python3.6/site-packages/urllib3/connection.py", line 150, in _new_conn
    self, "Failed to establish a new connection: %s" % e)
urllib3.exceptions.NewConnectionError: <urllib3.connection.VerifiedHTTPSConnection object at 0x10f492d68>: Failed to establish a new connection: [Errno 8] nodename nor servname provided, or not known

During handling of the above exception, another exception occurred:

Traceback (most recent call last):
  File "/Library/Frameworks/Python.framework/Versions/3.6/lib/python3.6/site-packages/requests/adapters.py", line 440, in send
    timeout=timeout
  File "/Library/Frameworks/Python.framework/Versions/3.6/lib/python3.6/site-packages/urllib3/connectionpool.py", line 639, in urlopen
    _stacktrace=sys.exc_info()[2])
  File "/Library/Frameworks/Python.framework/Versions/3.6/lib/python3.6/site-packages/urllib3/util/retry.py", line 388, in increment
    raise MaxRetryError(_pool, url, error or ResponseError(cause))
urllib3.exceptions.MaxRetryError: HTTPSConnectionPool(host='api.dropboxapi.com', port=443): Max retries exceeded with url: /2/users/get_current_account (Caused by NewConnectionError('<urllib3.connection.VerifiedHTTPSConnection object at 0x10f492d68>: Failed to establish a new connection: [Errno 8] nodename nor servname provided, or not known',))

During handling of the above exception, another exception occurred:

Traceback (most recent call last):
  File "/Users/hepting/Sites/dhhepting.github.io/script/sharemedia.py", line 53, in <module>
    dbx.users_get_current_account()
  File "/Library/Frameworks/Python.framework/Versions/3.6/lib/python3.6/site-packages/dropbox/base.py", line 4301, in users_get_current_account
    None,
  File "/Library/Frameworks/Python.framework/Versions/3.6/lib/python3.6/site-packages/dropbox/dropbox.py", line 272, in request
    timeout=timeout)
  File "/Library/Frameworks/Python.framework/Versions/3.6/lib/python3.6/site-packages/dropbox/dropbox.py", line 363, in request_json_string_with_retry
    timeout=timeout)
  File "/Library/Frameworks/Python.framework/Versions/3.6/lib/python3.6/site-packages/dropbox/dropbox.py", line 447, in request_json_string
    timeout=timeout,
  File "/Library/Frameworks/Python.framework/Versions/3.6/lib/python3.6/site-packages/requests/sessions.py", line 555, in post
    return self.request('POST', url, data=data, json=json, **kwargs)
  File "/Library/Frameworks/Python.framework/Versions/3.6/lib/python3.6/site-packages/requests/sessions.py", line 508, in request
    resp = self.send(prep, **send_kwargs)
  File "/Library/Frameworks/Python.framework/Versions/3.6/lib/python3.6/site-packages/requests/sessions.py", line 618, in send
    r = adapter.send(request, **kwargs)
  File "/Library/Frameworks/Python.framework/Versions/3.6/lib/python3.6/site-packages/requests/adapters.py", line 508, in send
    raise ConnectionError(e, request=request)
requests.exceptions.ConnectionError: HTTPSConnectionPool(host='api.dropboxapi.com', port=443): Max retries exceeded with url: /2/users/get_current_account (Caused by NewConnectionError('<urllib3.connection.VerifiedHTTPSConnection object at 0x10f492d68>: Failed to establish a new connection: [Errno 8] nodename nor servname provided, or not known',))
2019-08-09 08:22:16.687668
Traceback (most recent call last):
  File "/Library/Frameworks/Python.framework/Versions/3.6/lib/python3.6/site-packages/urllib3/connection.py", line 141, in _new_conn
    (self.host, self.port), self.timeout, **extra_kw)
  File "/Library/Frameworks/Python.framework/Versions/3.6/lib/python3.6/site-packages/urllib3/util/connection.py", line 60, in create_connection
    for res in socket.getaddrinfo(host, port, family, socket.SOCK_STREAM):
  File "/Library/Frameworks/Python.framework/Versions/3.6/lib/python3.6/socket.py", line 745, in getaddrinfo
    for res in _socket.getaddrinfo(host, port, family, type, proto, flags):
socket.gaierror: [Errno 8] nodename nor servname provided, or not known

During handling of the above exception, another exception occurred:

Traceback (most recent call last):
  File "/Library/Frameworks/Python.framework/Versions/3.6/lib/python3.6/site-packages/urllib3/connectionpool.py", line 601, in urlopen
    chunked=chunked)
  File "/Library/Frameworks/Python.framework/Versions/3.6/lib/python3.6/site-packages/urllib3/connectionpool.py", line 346, in _make_request
    self._validate_conn(conn)
  File "/Library/Frameworks/Python.framework/Versions/3.6/lib/python3.6/site-packages/urllib3/connectionpool.py", line 850, in _validate_conn
    conn.connect()
  File "/Library/Frameworks/Python.framework/Versions/3.6/lib/python3.6/site-packages/urllib3/connection.py", line 284, in connect
    conn = self._new_conn()
  File "/Library/Frameworks/Python.framework/Versions/3.6/lib/python3.6/site-packages/urllib3/connection.py", line 150, in _new_conn
    self, "Failed to establish a new connection: %s" % e)
urllib3.exceptions.NewConnectionError: <urllib3.connection.VerifiedHTTPSConnection object at 0x10f3a7320>: Failed to establish a new connection: [Errno 8] nodename nor servname provided, or not known

During handling of the above exception, another exception occurred:

Traceback (most recent call last):
  File "/Library/Frameworks/Python.framework/Versions/3.6/lib/python3.6/site-packages/requests/adapters.py", line 440, in send
    timeout=timeout
  File "/Library/Frameworks/Python.framework/Versions/3.6/lib/python3.6/site-packages/urllib3/connectionpool.py", line 639, in urlopen
    _stacktrace=sys.exc_info()[2])
  File "/Library/Frameworks/Python.framework/Versions/3.6/lib/python3.6/site-packages/urllib3/util/retry.py", line 388, in increment
    raise MaxRetryError(_pool, url, error or ResponseError(cause))
urllib3.exceptions.MaxRetryError: HTTPSConnectionPool(host='api.dropboxapi.com', port=443): Max retries exceeded with url: /2/users/get_current_account (Caused by NewConnectionError('<urllib3.connection.VerifiedHTTPSConnection object at 0x10f3a7320>: Failed to establish a new connection: [Errno 8] nodename nor servname provided, or not known',))

During handling of the above exception, another exception occurred:

Traceback (most recent call last):
  File "/Users/hepting/Sites/dhhepting.github.io/script/sharemedia.py", line 53, in <module>
    dbx.users_get_current_account()
  File "/Library/Frameworks/Python.framework/Versions/3.6/lib/python3.6/site-packages/dropbox/base.py", line 4301, in users_get_current_account
    None,
  File "/Library/Frameworks/Python.framework/Versions/3.6/lib/python3.6/site-packages/dropbox/dropbox.py", line 272, in request
    timeout=timeout)
  File "/Library/Frameworks/Python.framework/Versions/3.6/lib/python3.6/site-packages/dropbox/dropbox.py", line 363, in request_json_string_with_retry
    timeout=timeout)
  File "/Library/Frameworks/Python.framework/Versions/3.6/lib/python3.6/site-packages/dropbox/dropbox.py", line 447, in request_json_string
    timeout=timeout,
  File "/Library/Frameworks/Python.framework/Versions/3.6/lib/python3.6/site-packages/requests/sessions.py", line 555, in post
    return self.request('POST', url, data=data, json=json, **kwargs)
  File "/Library/Frameworks/Python.framework/Versions/3.6/lib/python3.6/site-packages/requests/sessions.py", line 508, in request
    resp = self.send(prep, **send_kwargs)
  File "/Library/Frameworks/Python.framework/Versions/3.6/lib/python3.6/site-packages/requests/sessions.py", line 618, in send
    r = adapter.send(request, **kwargs)
  File "/Library/Frameworks/Python.framework/Versions/3.6/lib/python3.6/site-packages/requests/adapters.py", line 508, in send
    raise ConnectionError(e, request=request)
requests.exceptions.ConnectionError: HTTPSConnectionPool(host='api.dropboxapi.com', port=443): Max retries exceeded with url: /2/users/get_current_account (Caused by NewConnectionError('<urllib3.connection.VerifiedHTTPSConnection object at 0x10f3a7320>: Failed to establish a new connection: [Errno 8] nodename nor servname provided, or not known',))
2019-08-10 11:20:37.630523
2019-08-11 23:59:20.424070
2019-08-12 15:09:21.407377
2019-08-14 10:31:59.061561
2019-08-14 14:00:08.514730
2019-08-15 15:40:04.580798
2019-08-16 15:30:04.958442
2019-08-17 14:26:57.844393
2019-08-18 17:15:21.156395
Traceback (most recent call last):
  File "/Library/Frameworks/Python.framework/Versions/3.6/lib/python3.6/site-packages/urllib3/connection.py", line 141, in _new_conn
    (self.host, self.port), self.timeout, **extra_kw)
  File "/Library/Frameworks/Python.framework/Versions/3.6/lib/python3.6/site-packages/urllib3/util/connection.py", line 60, in create_connection
    for res in socket.getaddrinfo(host, port, family, socket.SOCK_STREAM):
  File "/Library/Frameworks/Python.framework/Versions/3.6/lib/python3.6/socket.py", line 745, in getaddrinfo
    for res in _socket.getaddrinfo(host, port, family, type, proto, flags):
socket.gaierror: [Errno 8] nodename nor servname provided, or not known

During handling of the above exception, another exception occurred:

Traceback (most recent call last):
  File "/Library/Frameworks/Python.framework/Versions/3.6/lib/python3.6/site-packages/urllib3/connectionpool.py", line 601, in urlopen
    chunked=chunked)
  File "/Library/Frameworks/Python.framework/Versions/3.6/lib/python3.6/site-packages/urllib3/connectionpool.py", line 346, in _make_request
    self._validate_conn(conn)
  File "/Library/Frameworks/Python.framework/Versions/3.6/lib/python3.6/site-packages/urllib3/connectionpool.py", line 850, in _validate_conn
    conn.connect()
  File "/Library/Frameworks/Python.framework/Versions/3.6/lib/python3.6/site-packages/urllib3/connection.py", line 284, in connect
    conn = self._new_conn()
  File "/Library/Frameworks/Python.framework/Versions/3.6/lib/python3.6/site-packages/urllib3/connection.py", line 150, in _new_conn
    self, "Failed to establish a new connection: %s" % e)
urllib3.exceptions.NewConnectionError: <urllib3.connection.VerifiedHTTPSConnection object at 0x10f292ba8>: Failed to establish a new connection: [Errno 8] nodename nor servname provided, or not known

During handling of the above exception, another exception occurred:

Traceback (most recent call last):
  File "/Library/Frameworks/Python.framework/Versions/3.6/lib/python3.6/site-packages/requests/adapters.py", line 440, in send
    timeout=timeout
  File "/Library/Frameworks/Python.framework/Versions/3.6/lib/python3.6/site-packages/urllib3/connectionpool.py", line 639, in urlopen
    _stacktrace=sys.exc_info()[2])
  File "/Library/Frameworks/Python.framework/Versions/3.6/lib/python3.6/site-packages/urllib3/util/retry.py", line 388, in increment
    raise MaxRetryError(_pool, url, error or ResponseError(cause))
urllib3.exceptions.MaxRetryError: HTTPSConnectionPool(host='api.dropboxapi.com', port=443): Max retries exceeded with url: /2/users/get_current_account (Caused by NewConnectionError('<urllib3.connection.VerifiedHTTPSConnection object at 0x10f292ba8>: Failed to establish a new connection: [Errno 8] nodename nor servname provided, or not known',))

During handling of the above exception, another exception occurred:

Traceback (most recent call last):
  File "/Users/hepting/Sites/dhhepting.github.io/script/sharemedia.py", line 53, in <module>
    dbx.users_get_current_account()
  File "/Library/Frameworks/Python.framework/Versions/3.6/lib/python3.6/site-packages/dropbox/base.py", line 4301, in users_get_current_account
    None,
  File "/Library/Frameworks/Python.framework/Versions/3.6/lib/python3.6/site-packages/dropbox/dropbox.py", line 272, in request
    timeout=timeout)
  File "/Library/Frameworks/Python.framework/Versions/3.6/lib/python3.6/site-packages/dropbox/dropbox.py", line 363, in request_json_string_with_retry
    timeout=timeout)
  File "/Library/Frameworks/Python.framework/Versions/3.6/lib/python3.6/site-packages/dropbox/dropbox.py", line 447, in request_json_string
    timeout=timeout,
  File "/Library/Frameworks/Python.framework/Versions/3.6/lib/python3.6/site-packages/requests/sessions.py", line 555, in post
    return self.request('POST', url, data=data, json=json, **kwargs)
  File "/Library/Frameworks/Python.framework/Versions/3.6/lib/python3.6/site-packages/requests/sessions.py", line 508, in request
    resp = self.send(prep, **send_kwargs)
  File "/Library/Frameworks/Python.framework/Versions/3.6/lib/python3.6/site-packages/requests/sessions.py", line 618, in send
    r = adapter.send(request, **kwargs)
  File "/Library/Frameworks/Python.framework/Versions/3.6/lib/python3.6/site-packages/requests/adapters.py", line 508, in send
    raise ConnectionError(e, request=request)
requests.exceptions.ConnectionError: HTTPSConnectionPool(host='api.dropboxapi.com', port=443): Max retries exceeded with url: /2/users/get_current_account (Caused by NewConnectionError('<urllib3.connection.VerifiedHTTPSConnection object at 0x10f292ba8>: Failed to establish a new connection: [Errno 8] nodename nor servname provided, or not known',))
2019-08-19 19:48:42.688592
Traceback (most recent call last):
  File "/Library/Frameworks/Python.framework/Versions/3.6/lib/python3.6/site-packages/urllib3/connection.py", line 141, in _new_conn
    (self.host, self.port), self.timeout, **extra_kw)
  File "/Library/Frameworks/Python.framework/Versions/3.6/lib/python3.6/site-packages/urllib3/util/connection.py", line 60, in create_connection
    for res in socket.getaddrinfo(host, port, family, socket.SOCK_STREAM):
  File "/Library/Frameworks/Python.framework/Versions/3.6/lib/python3.6/socket.py", line 745, in getaddrinfo
    for res in _socket.getaddrinfo(host, port, family, type, proto, flags):
socket.gaierror: [Errno 8] nodename nor servname provided, or not known

During handling of the above exception, another exception occurred:

Traceback (most recent call last):
  File "/Library/Frameworks/Python.framework/Versions/3.6/lib/python3.6/site-packages/urllib3/connectionpool.py", line 601, in urlopen
    chunked=chunked)
  File "/Library/Frameworks/Python.framework/Versions/3.6/lib/python3.6/site-packages/urllib3/connectionpool.py", line 346, in _make_request
    self._validate_conn(conn)
  File "/Library/Frameworks/Python.framework/Versions/3.6/lib/python3.6/site-packages/urllib3/connectionpool.py", line 850, in _validate_conn
    conn.connect()
  File "/Library/Frameworks/Python.framework/Versions/3.6/lib/python3.6/site-packages/urllib3/connection.py", line 284, in connect
    conn = self._new_conn()
  File "/Library/Frameworks/Python.framework/Versions/3.6/lib/python3.6/site-packages/urllib3/connection.py", line 150, in _new_conn
    self, "Failed to establish a new connection: %s" % e)
urllib3.exceptions.NewConnectionError: <urllib3.connection.VerifiedHTTPSConnection object at 0x10f471048>: Failed to establish a new connection: [Errno 8] nodename nor servname provided, or not known

During handling of the above exception, another exception occurred:

Traceback (most recent call last):
  File "/Library/Frameworks/Python.framework/Versions/3.6/lib/python3.6/site-packages/requests/adapters.py", line 440, in send
    timeout=timeout
  File "/Library/Frameworks/Python.framework/Versions/3.6/lib/python3.6/site-packages/urllib3/connectionpool.py", line 639, in urlopen
    _stacktrace=sys.exc_info()[2])
  File "/Library/Frameworks/Python.framework/Versions/3.6/lib/python3.6/site-packages/urllib3/util/retry.py", line 388, in increment
    raise MaxRetryError(_pool, url, error or ResponseError(cause))
urllib3.exceptions.MaxRetryError: HTTPSConnectionPool(host='api.dropboxapi.com', port=443): Max retries exceeded with url: /2/users/get_current_account (Caused by NewConnectionError('<urllib3.connection.VerifiedHTTPSConnection object at 0x10f471048>: Failed to establish a new connection: [Errno 8] nodename nor servname provided, or not known',))

During handling of the above exception, another exception occurred:

Traceback (most recent call last):
  File "/Users/hepting/Sites/dhhepting.github.io/script/sharemedia.py", line 53, in <module>
    dbx.users_get_current_account()
  File "/Library/Frameworks/Python.framework/Versions/3.6/lib/python3.6/site-packages/dropbox/base.py", line 4301, in users_get_current_account
    None,
  File "/Library/Frameworks/Python.framework/Versions/3.6/lib/python3.6/site-packages/dropbox/dropbox.py", line 272, in request
    timeout=timeout)
  File "/Library/Frameworks/Python.framework/Versions/3.6/lib/python3.6/site-packages/dropbox/dropbox.py", line 363, in request_json_string_with_retry
    timeout=timeout)
  File "/Library/Frameworks/Python.framework/Versions/3.6/lib/python3.6/site-packages/dropbox/dropbox.py", line 447, in request_json_string
    timeout=timeout,
  File "/Library/Frameworks/Python.framework/Versions/3.6/lib/python3.6/site-packages/requests/sessions.py", line 555, in post
    return self.request('POST', url, data=data, json=json, **kwargs)
  File "/Library/Frameworks/Python.framework/Versions/3.6/lib/python3.6/site-packages/requests/sessions.py", line 508, in request
    resp = self.send(prep, **send_kwargs)
  File "/Library/Frameworks/Python.framework/Versions/3.6/lib/python3.6/site-packages/requests/sessions.py", line 618, in send
    r = adapter.send(request, **kwargs)
  File "/Library/Frameworks/Python.framework/Versions/3.6/lib/python3.6/site-packages/requests/adapters.py", line 508, in send
    raise ConnectionError(e, request=request)
requests.exceptions.ConnectionError: HTTPSConnectionPool(host='api.dropboxapi.com', port=443): Max retries exceeded with url: /2/users/get_current_account (Caused by NewConnectionError('<urllib3.connection.VerifiedHTTPSConnection object at 0x10f471048>: Failed to establish a new connection: [Errno 8] nodename nor servname provided, or not known',))
2019-08-20 14:00:04.690359
Traceback (most recent call last):
  File "/Library/Frameworks/Python.framework/Versions/3.6/lib/python3.6/site-packages/urllib3/connection.py", line 141, in _new_conn
    (self.host, self.port), self.timeout, **extra_kw)
  File "/Library/Frameworks/Python.framework/Versions/3.6/lib/python3.6/site-packages/urllib3/util/connection.py", line 60, in create_connection
    for res in socket.getaddrinfo(host, port, family, socket.SOCK_STREAM):
  File "/Library/Frameworks/Python.framework/Versions/3.6/lib/python3.6/socket.py", line 745, in getaddrinfo
    for res in _socket.getaddrinfo(host, port, family, type, proto, flags):
socket.gaierror: [Errno 8] nodename nor servname provided, or not known

During handling of the above exception, another exception occurred:

Traceback (most recent call last):
  File "/Library/Frameworks/Python.framework/Versions/3.6/lib/python3.6/site-packages/urllib3/connectionpool.py", line 601, in urlopen
    chunked=chunked)
  File "/Library/Frameworks/Python.framework/Versions/3.6/lib/python3.6/site-packages/urllib3/connectionpool.py", line 346, in _make_request
    self._validate_conn(conn)
  File "/Library/Frameworks/Python.framework/Versions/3.6/lib/python3.6/site-packages/urllib3/connectionpool.py", line 850, in _validate_conn
    conn.connect()
  File "/Library/Frameworks/Python.framework/Versions/3.6/lib/python3.6/site-packages/urllib3/connection.py", line 284, in connect
    conn = self._new_conn()
  File "/Library/Frameworks/Python.framework/Versions/3.6/lib/python3.6/site-packages/urllib3/connection.py", line 150, in _new_conn
    self, "Failed to establish a new connection: %s" % e)
urllib3.exceptions.NewConnectionError: <urllib3.connection.VerifiedHTTPSConnection object at 0x10f471630>: Failed to establish a new connection: [Errno 8] nodename nor servname provided, or not known

During handling of the above exception, another exception occurred:

Traceback (most recent call last):
  File "/Library/Frameworks/Python.framework/Versions/3.6/lib/python3.6/site-packages/requests/adapters.py", line 440, in send
    timeout=timeout
  File "/Library/Frameworks/Python.framework/Versions/3.6/lib/python3.6/site-packages/urllib3/connectionpool.py", line 639, in urlopen
    _stacktrace=sys.exc_info()[2])
  File "/Library/Frameworks/Python.framework/Versions/3.6/lib/python3.6/site-packages/urllib3/util/retry.py", line 388, in increment
    raise MaxRetryError(_pool, url, error or ResponseError(cause))
urllib3.exceptions.MaxRetryError: HTTPSConnectionPool(host='api.dropboxapi.com', port=443): Max retries exceeded with url: /2/users/get_current_account (Caused by NewConnectionError('<urllib3.connection.VerifiedHTTPSConnection object at 0x10f471630>: Failed to establish a new connection: [Errno 8] nodename nor servname provided, or not known',))

During handling of the above exception, another exception occurred:

Traceback (most recent call last):
  File "/Users/hepting/Sites/dhhepting.github.io/script/sharemedia.py", line 53, in <module>
    dbx.users_get_current_account()
  File "/Library/Frameworks/Python.framework/Versions/3.6/lib/python3.6/site-packages/dropbox/base.py", line 4301, in users_get_current_account
    None,
  File "/Library/Frameworks/Python.framework/Versions/3.6/lib/python3.6/site-packages/dropbox/dropbox.py", line 272, in request
    timeout=timeout)
  File "/Library/Frameworks/Python.framework/Versions/3.6/lib/python3.6/site-packages/dropbox/dropbox.py", line 363, in request_json_string_with_retry
    timeout=timeout)
  File "/Library/Frameworks/Python.framework/Versions/3.6/lib/python3.6/site-packages/dropbox/dropbox.py", line 447, in request_json_string
    timeout=timeout,
  File "/Library/Frameworks/Python.framework/Versions/3.6/lib/python3.6/site-packages/requests/sessions.py", line 555, in post
    return self.request('POST', url, data=data, json=json, **kwargs)
  File "/Library/Frameworks/Python.framework/Versions/3.6/lib/python3.6/site-packages/requests/sessions.py", line 508, in request
    resp = self.send(prep, **send_kwargs)
  File "/Library/Frameworks/Python.framework/Versions/3.6/lib/python3.6/site-packages/requests/sessions.py", line 618, in send
    r = adapter.send(request, **kwargs)
  File "/Library/Frameworks/Python.framework/Versions/3.6/lib/python3.6/site-packages/requests/adapters.py", line 508, in send
    raise ConnectionError(e, request=request)
requests.exceptions.ConnectionError: HTTPSConnectionPool(host='api.dropboxapi.com', port=443): Max retries exceeded with url: /2/users/get_current_account (Caused by NewConnectionError('<urllib3.connection.VerifiedHTTPSConnection object at 0x10f471630>: Failed to establish a new connection: [Errno 8] nodename nor servname provided, or not known',))
2019-08-21 23:59:06.365697
Traceback (most recent call last):
  File "/Library/Frameworks/Python.framework/Versions/3.6/lib/python3.6/site-packages/urllib3/connection.py", line 141, in _new_conn
    (self.host, self.port), self.timeout, **extra_kw)
  File "/Library/Frameworks/Python.framework/Versions/3.6/lib/python3.6/site-packages/urllib3/util/connection.py", line 60, in create_connection
    for res in socket.getaddrinfo(host, port, family, socket.SOCK_STREAM):
  File "/Library/Frameworks/Python.framework/Versions/3.6/lib/python3.6/socket.py", line 745, in getaddrinfo
    for res in _socket.getaddrinfo(host, port, family, type, proto, flags):
socket.gaierror: [Errno 8] nodename nor servname provided, or not known

During handling of the above exception, another exception occurred:

Traceback (most recent call last):
  File "/Library/Frameworks/Python.framework/Versions/3.6/lib/python3.6/site-packages/urllib3/connectionpool.py", line 601, in urlopen
    chunked=chunked)
  File "/Library/Frameworks/Python.framework/Versions/3.6/lib/python3.6/site-packages/urllib3/connectionpool.py", line 346, in _make_request
    self._validate_conn(conn)
  File "/Library/Frameworks/Python.framework/Versions/3.6/lib/python3.6/site-packages/urllib3/connectionpool.py", line 850, in _validate_conn
    conn.connect()
  File "/Library/Frameworks/Python.framework/Versions/3.6/lib/python3.6/site-packages/urllib3/connection.py", line 284, in connect
    conn = self._new_conn()
  File "/Library/Frameworks/Python.framework/Versions/3.6/lib/python3.6/site-packages/urllib3/connection.py", line 150, in _new_conn
    self, "Failed to establish a new connection: %s" % e)
urllib3.exceptions.NewConnectionError: <urllib3.connection.VerifiedHTTPSConnection object at 0x10f484048>: Failed to establish a new connection: [Errno 8] nodename nor servname provided, or not known

During handling of the above exception, another exception occurred:

Traceback (most recent call last):
  File "/Library/Frameworks/Python.framework/Versions/3.6/lib/python3.6/site-packages/requests/adapters.py", line 440, in send
    timeout=timeout
  File "/Library/Frameworks/Python.framework/Versions/3.6/lib/python3.6/site-packages/urllib3/connectionpool.py", line 639, in urlopen
    _stacktrace=sys.exc_info()[2])
  File "/Library/Frameworks/Python.framework/Versions/3.6/lib/python3.6/site-packages/urllib3/util/retry.py", line 388, in increment
    raise MaxRetryError(_pool, url, error or ResponseError(cause))
urllib3.exceptions.MaxRetryError: HTTPSConnectionPool(host='api.dropboxapi.com', port=443): Max retries exceeded with url: /2/users/get_current_account (Caused by NewConnectionError('<urllib3.connection.VerifiedHTTPSConnection object at 0x10f484048>: Failed to establish a new connection: [Errno 8] nodename nor servname provided, or not known',))

During handling of the above exception, another exception occurred:

Traceback (most recent call last):
  File "/Users/hepting/Sites/dhhepting.github.io/script/sharemedia.py", line 53, in <module>
    dbx.users_get_current_account()
  File "/Library/Frameworks/Python.framework/Versions/3.6/lib/python3.6/site-packages/dropbox/base.py", line 4301, in users_get_current_account
    None,
  File "/Library/Frameworks/Python.framework/Versions/3.6/lib/python3.6/site-packages/dropbox/dropbox.py", line 272, in request
    timeout=timeout)
  File "/Library/Frameworks/Python.framework/Versions/3.6/lib/python3.6/site-packages/dropbox/dropbox.py", line 363, in request_json_string_with_retry
    timeout=timeout)
  File "/Library/Frameworks/Python.framework/Versions/3.6/lib/python3.6/site-packages/dropbox/dropbox.py", line 447, in request_json_string
    timeout=timeout,
  File "/Library/Frameworks/Python.framework/Versions/3.6/lib/python3.6/site-packages/requests/sessions.py", line 555, in post
    return self.request('POST', url, data=data, json=json, **kwargs)
  File "/Library/Frameworks/Python.framework/Versions/3.6/lib/python3.6/site-packages/requests/sessions.py", line 508, in request
    resp = self.send(prep, **send_kwargs)
  File "/Library/Frameworks/Python.framework/Versions/3.6/lib/python3.6/site-packages/requests/sessions.py", line 618, in send
    r = adapter.send(request, **kwargs)
  File "/Library/Frameworks/Python.framework/Versions/3.6/lib/python3.6/site-packages/requests/adapters.py", line 508, in send
    raise ConnectionError(e, request=request)
requests.exceptions.ConnectionError: HTTPSConnectionPool(host='api.dropboxapi.com', port=443): Max retries exceeded with url: /2/users/get_current_account (Caused by NewConnectionError('<urllib3.connection.VerifiedHTTPSConnection object at 0x10f484048>: Failed to establish a new connection: [Errno 8] nodename nor servname provided, or not known',))
2019-08-22 23:18:03.677227
2019-08-23 14:00:03.874781
2019-08-24 14:11:21.108586
2019-08-25 23:03:16.646762
2019-08-26 13:33:37.005008
2019-08-26 14:00:03.890587
2019-08-27 14:00:04.326676
2019-08-28 10:44:42.801960
2019-08-28 14:00:06.659052
2019-08-29 14:17:33.540929
2019-09-01 01:24:35.488068
2019-09-02 02:46:32.440464
2019-09-02 22:29:15.667433
2019-09-03 15:37:58.858766
2019-09-04 14:00:07.210116
2019-09-05 14:38:40.066284
2019-09-06 14:00:08.930327
2019-09-07 14:30:25.402626
2019-09-08 16:30:55.939487
2019-09-09 14:00:11.628370
2019-09-10 14:00:15.058204
2019-09-10 14:54:54.480652
2019-09-10 14:56:48.563332
2019-09-10 15:00:04.288492
2019-09-10 15:21:13.717576
2019-09-10 15:21:23.917645
2019-09-10 17:36:27.385979
2019-09-10 17:38:02.516834
2019-09-11 15:00:04.985050
2019-09-12 15:00:04.656694
2019-09-12 15:08:27.339722
2019-09-12 15:09:33.867506
2019-09-12 15:41:14.963113
2019-09-12 15:42:07.840134
2019-09-12 15:42:22.125603
2019-09-12 15:42:46.233919
2019-09-12 15:43:08.766433
2019-09-12 17:52:46.716926
2019-09-12 17:53:33.733169
2019-09-13 15:00:08.574918
2019-09-15 01:45:03.562861
Traceback (most recent call last):
  File "/Library/Frameworks/Python.framework/Versions/3.6/lib/python3.6/site-packages/urllib3/connection.py", line 141, in _new_conn
    (self.host, self.port), self.timeout, **extra_kw)
  File "/Library/Frameworks/Python.framework/Versions/3.6/lib/python3.6/site-packages/urllib3/util/connection.py", line 60, in create_connection
    for res in socket.getaddrinfo(host, port, family, socket.SOCK_STREAM):
  File "/Library/Frameworks/Python.framework/Versions/3.6/lib/python3.6/socket.py", line 745, in getaddrinfo
    for res in _socket.getaddrinfo(host, port, family, type, proto, flags):
socket.gaierror: [Errno 8] nodename nor servname provided, or not known

During handling of the above exception, another exception occurred:

Traceback (most recent call last):
  File "/Library/Frameworks/Python.framework/Versions/3.6/lib/python3.6/site-packages/urllib3/connectionpool.py", line 601, in urlopen
    chunked=chunked)
  File "/Library/Frameworks/Python.framework/Versions/3.6/lib/python3.6/site-packages/urllib3/connectionpool.py", line 346, in _make_request
    self._validate_conn(conn)
  File "/Library/Frameworks/Python.framework/Versions/3.6/lib/python3.6/site-packages/urllib3/connectionpool.py", line 850, in _validate_conn
    conn.connect()
  File "/Library/Frameworks/Python.framework/Versions/3.6/lib/python3.6/site-packages/urllib3/connection.py", line 284, in connect
    conn = self._new_conn()
  File "/Library/Frameworks/Python.framework/Versions/3.6/lib/python3.6/site-packages/urllib3/connection.py", line 150, in _new_conn
    self, "Failed to establish a new connection: %s" % e)
urllib3.exceptions.NewConnectionError: <urllib3.connection.VerifiedHTTPSConnection object at 0x10f525320>: Failed to establish a new connection: [Errno 8] nodename nor servname provided, or not known

During handling of the above exception, another exception occurred:

Traceback (most recent call last):
  File "/Library/Frameworks/Python.framework/Versions/3.6/lib/python3.6/site-packages/requests/adapters.py", line 440, in send
    timeout=timeout
  File "/Library/Frameworks/Python.framework/Versions/3.6/lib/python3.6/site-packages/urllib3/connectionpool.py", line 639, in urlopen
    _stacktrace=sys.exc_info()[2])
  File "/Library/Frameworks/Python.framework/Versions/3.6/lib/python3.6/site-packages/urllib3/util/retry.py", line 388, in increment
    raise MaxRetryError(_pool, url, error or ResponseError(cause))
urllib3.exceptions.MaxRetryError: HTTPSConnectionPool(host='api.dropboxapi.com', port=443): Max retries exceeded with url: /2/users/get_current_account (Caused by NewConnectionError('<urllib3.connection.VerifiedHTTPSConnection object at 0x10f525320>: Failed to establish a new connection: [Errno 8] nodename nor servname provided, or not known',))

During handling of the above exception, another exception occurred:

Traceback (most recent call last):
  File "/Users/hepting/Sites/dhhepting.github.io/script/sharemedia.py", line 53, in <module>
    dbx.users_get_current_account()
  File "/Library/Frameworks/Python.framework/Versions/3.6/lib/python3.6/site-packages/dropbox/base.py", line 4301, in users_get_current_account
    None,
  File "/Library/Frameworks/Python.framework/Versions/3.6/lib/python3.6/site-packages/dropbox/dropbox.py", line 272, in request
    timeout=timeout)
  File "/Library/Frameworks/Python.framework/Versions/3.6/lib/python3.6/site-packages/dropbox/dropbox.py", line 363, in request_json_string_with_retry
    timeout=timeout)
  File "/Library/Frameworks/Python.framework/Versions/3.6/lib/python3.6/site-packages/dropbox/dropbox.py", line 447, in request_json_string
    timeout=timeout,
  File "/Library/Frameworks/Python.framework/Versions/3.6/lib/python3.6/site-packages/requests/sessions.py", line 555, in post
    return self.request('POST', url, data=data, json=json, **kwargs)
  File "/Library/Frameworks/Python.framework/Versions/3.6/lib/python3.6/site-packages/requests/sessions.py", line 508, in request
    resp = self.send(prep, **send_kwargs)
  File "/Library/Frameworks/Python.framework/Versions/3.6/lib/python3.6/site-packages/requests/sessions.py", line 618, in send
    r = adapter.send(request, **kwargs)
  File "/Library/Frameworks/Python.framework/Versions/3.6/lib/python3.6/site-packages/requests/adapters.py", line 508, in send
    raise ConnectionError(e, request=request)
requests.exceptions.ConnectionError: HTTPSConnectionPool(host='api.dropboxapi.com', port=443): Max retries exceeded with url: /2/users/get_current_account (Caused by NewConnectionError('<urllib3.connection.VerifiedHTTPSConnection object at 0x10f525320>: Failed to establish a new connection: [Errno 8] nodename nor servname provided, or not known',))
2019-09-15 19:33:05.148151
Traceback (most recent call last):
  File "/Library/Frameworks/Python.framework/Versions/3.6/lib/python3.6/site-packages/urllib3/connection.py", line 141, in _new_conn
    (self.host, self.port), self.timeout, **extra_kw)
  File "/Library/Frameworks/Python.framework/Versions/3.6/lib/python3.6/site-packages/urllib3/util/connection.py", line 60, in create_connection
    for res in socket.getaddrinfo(host, port, family, socket.SOCK_STREAM):
  File "/Library/Frameworks/Python.framework/Versions/3.6/lib/python3.6/socket.py", line 745, in getaddrinfo
    for res in _socket.getaddrinfo(host, port, family, type, proto, flags):
socket.gaierror: [Errno 8] nodename nor servname provided, or not known

During handling of the above exception, another exception occurred:

Traceback (most recent call last):
  File "/Library/Frameworks/Python.framework/Versions/3.6/lib/python3.6/site-packages/urllib3/connectionpool.py", line 601, in urlopen
    chunked=chunked)
  File "/Library/Frameworks/Python.framework/Versions/3.6/lib/python3.6/site-packages/urllib3/connectionpool.py", line 346, in _make_request
    self._validate_conn(conn)
  File "/Library/Frameworks/Python.framework/Versions/3.6/lib/python3.6/site-packages/urllib3/connectionpool.py", line 850, in _validate_conn
    conn.connect()
  File "/Library/Frameworks/Python.framework/Versions/3.6/lib/python3.6/site-packages/urllib3/connection.py", line 284, in connect
    conn = self._new_conn()
  File "/Library/Frameworks/Python.framework/Versions/3.6/lib/python3.6/site-packages/urllib3/connection.py", line 150, in _new_conn
    self, "Failed to establish a new connection: %s" % e)
urllib3.exceptions.NewConnectionError: <urllib3.connection.VerifiedHTTPSConnection object at 0x10f433320>: Failed to establish a new connection: [Errno 8] nodename nor servname provided, or not known

During handling of the above exception, another exception occurred:

Traceback (most recent call last):
  File "/Library/Frameworks/Python.framework/Versions/3.6/lib/python3.6/site-packages/requests/adapters.py", line 440, in send
    timeout=timeout
  File "/Library/Frameworks/Python.framework/Versions/3.6/lib/python3.6/site-packages/urllib3/connectionpool.py", line 639, in urlopen
    _stacktrace=sys.exc_info()[2])
  File "/Library/Frameworks/Python.framework/Versions/3.6/lib/python3.6/site-packages/urllib3/util/retry.py", line 388, in increment
    raise MaxRetryError(_pool, url, error or ResponseError(cause))
urllib3.exceptions.MaxRetryError: HTTPSConnectionPool(host='api.dropboxapi.com', port=443): Max retries exceeded with url: /2/users/get_current_account (Caused by NewConnectionError('<urllib3.connection.VerifiedHTTPSConnection object at 0x10f433320>: Failed to establish a new connection: [Errno 8] nodename nor servname provided, or not known',))

During handling of the above exception, another exception occurred:

Traceback (most recent call last):
  File "/Users/hepting/Sites/dhhepting.github.io/script/sharemedia.py", line 53, in <module>
    dbx.users_get_current_account()
  File "/Library/Frameworks/Python.framework/Versions/3.6/lib/python3.6/site-packages/dropbox/base.py", line 4301, in users_get_current_account
    None,
  File "/Library/Frameworks/Python.framework/Versions/3.6/lib/python3.6/site-packages/dropbox/dropbox.py", line 272, in request
    timeout=timeout)
  File "/Library/Frameworks/Python.framework/Versions/3.6/lib/python3.6/site-packages/dropbox/dropbox.py", line 363, in request_json_string_with_retry
    timeout=timeout)
  File "/Library/Frameworks/Python.framework/Versions/3.6/lib/python3.6/site-packages/dropbox/dropbox.py", line 447, in request_json_string
    timeout=timeout,
  File "/Library/Frameworks/Python.framework/Versions/3.6/lib/python3.6/site-packages/requests/sessions.py", line 555, in post
    return self.request('POST', url, data=data, json=json, **kwargs)
  File "/Library/Frameworks/Python.framework/Versions/3.6/lib/python3.6/site-packages/requests/sessions.py", line 508, in request
    resp = self.send(prep, **send_kwargs)
  File "/Library/Frameworks/Python.framework/Versions/3.6/lib/python3.6/site-packages/requests/sessions.py", line 618, in send
    r = adapter.send(request, **kwargs)
  File "/Library/Frameworks/Python.framework/Versions/3.6/lib/python3.6/site-packages/requests/adapters.py", line 508, in send
    raise ConnectionError(e, request=request)
requests.exceptions.ConnectionError: HTTPSConnectionPool(host='api.dropboxapi.com', port=443): Max retries exceeded with url: /2/users/get_current_account (Caused by NewConnectionError('<urllib3.connection.VerifiedHTTPSConnection object at 0x10f433320>: Failed to establish a new connection: [Errno 8] nodename nor servname provided, or not known',))
2019-09-16 15:00:10.309674
2019-09-17 15:07:58.780237
Traceback (most recent call last):
  File "/Library/Frameworks/Python.framework/Versions/3.6/lib/python3.6/site-packages/urllib3/connection.py", line 141, in _new_conn
    (self.host, self.port), self.timeout, **extra_kw)
  File "/Library/Frameworks/Python.framework/Versions/3.6/lib/python3.6/site-packages/urllib3/util/connection.py", line 60, in create_connection
    for res in socket.getaddrinfo(host, port, family, socket.SOCK_STREAM):
  File "/Library/Frameworks/Python.framework/Versions/3.6/lib/python3.6/socket.py", line 745, in getaddrinfo
    for res in _socket.getaddrinfo(host, port, family, type, proto, flags):
socket.gaierror: [Errno 8] nodename nor servname provided, or not known

During handling of the above exception, another exception occurred:

Traceback (most recent call last):
  File "/Library/Frameworks/Python.framework/Versions/3.6/lib/python3.6/site-packages/urllib3/connectionpool.py", line 601, in urlopen
    chunked=chunked)
  File "/Library/Frameworks/Python.framework/Versions/3.6/lib/python3.6/site-packages/urllib3/connectionpool.py", line 346, in _make_request
    self._validate_conn(conn)
  File "/Library/Frameworks/Python.framework/Versions/3.6/lib/python3.6/site-packages/urllib3/connectionpool.py", line 850, in _validate_conn
    conn.connect()
  File "/Library/Frameworks/Python.framework/Versions/3.6/lib/python3.6/site-packages/urllib3/connection.py", line 284, in connect
    conn = self._new_conn()
  File "/Library/Frameworks/Python.framework/Versions/3.6/lib/python3.6/site-packages/urllib3/connection.py", line 150, in _new_conn
    self, "Failed to establish a new connection: %s" % e)
urllib3.exceptions.NewConnectionError: <urllib3.connection.VerifiedHTTPSConnection object at 0x10f520320>: Failed to establish a new connection: [Errno 8] nodename nor servname provided, or not known

During handling of the above exception, another exception occurred:

Traceback (most recent call last):
  File "/Library/Frameworks/Python.framework/Versions/3.6/lib/python3.6/site-packages/requests/adapters.py", line 440, in send
    timeout=timeout
  File "/Library/Frameworks/Python.framework/Versions/3.6/lib/python3.6/site-packages/urllib3/connectionpool.py", line 639, in urlopen
    _stacktrace=sys.exc_info()[2])
  File "/Library/Frameworks/Python.framework/Versions/3.6/lib/python3.6/site-packages/urllib3/util/retry.py", line 388, in increment
    raise MaxRetryError(_pool, url, error or ResponseError(cause))
urllib3.exceptions.MaxRetryError: HTTPSConnectionPool(host='api.dropboxapi.com', port=443): Max retries exceeded with url: /2/users/get_current_account (Caused by NewConnectionError('<urllib3.connection.VerifiedHTTPSConnection object at 0x10f520320>: Failed to establish a new connection: [Errno 8] nodename nor servname provided, or not known',))

During handling of the above exception, another exception occurred:

Traceback (most recent call last):
  File "/Users/hepting/Sites/dhhepting.github.io/script/sharemedia.py", line 53, in <module>
    dbx.users_get_current_account()
  File "/Library/Frameworks/Python.framework/Versions/3.6/lib/python3.6/site-packages/dropbox/base.py", line 4301, in users_get_current_account
    None,
  File "/Library/Frameworks/Python.framework/Versions/3.6/lib/python3.6/site-packages/dropbox/dropbox.py", line 272, in request
    timeout=timeout)
  File "/Library/Frameworks/Python.framework/Versions/3.6/lib/python3.6/site-packages/dropbox/dropbox.py", line 363, in request_json_string_with_retry
    timeout=timeout)
  File "/Library/Frameworks/Python.framework/Versions/3.6/lib/python3.6/site-packages/dropbox/dropbox.py", line 447, in request_json_string
    timeout=timeout,
  File "/Library/Frameworks/Python.framework/Versions/3.6/lib/python3.6/site-packages/requests/sessions.py", line 555, in post
    return self.request('POST', url, data=data, json=json, **kwargs)
  File "/Library/Frameworks/Python.framework/Versions/3.6/lib/python3.6/site-packages/requests/sessions.py", line 508, in request
    resp = self.send(prep, **send_kwargs)
  File "/Library/Frameworks/Python.framework/Versions/3.6/lib/python3.6/site-packages/requests/sessions.py", line 618, in send
    r = adapter.send(request, **kwargs)
  File "/Library/Frameworks/Python.framework/Versions/3.6/lib/python3.6/site-packages/requests/adapters.py", line 508, in send
    raise ConnectionError(e, request=request)
requests.exceptions.ConnectionError: HTTPSConnectionPool(host='api.dropboxapi.com', port=443): Max retries exceeded with url: /2/users/get_current_account (Caused by NewConnectionError('<urllib3.connection.VerifiedHTTPSConnection object at 0x10f520320>: Failed to establish a new connection: [Errno 8] nodename nor servname provided, or not known',))
2019-09-17 17:35:47.241998
2019-09-17 17:39:34.406543
2019-09-18 15:00:03.143914
2019-09-19 15:00:04.387928
2019-09-19 15:45:56.824219
2019-09-19 17:56:15.501578
Traceback (most recent call last):
  File "/Library/Frameworks/Python.framework/Versions/3.6/lib/python3.6/site-packages/urllib3/connection.py", line 141, in _new_conn
    (self.host, self.port), self.timeout, **extra_kw)
  File "/Library/Frameworks/Python.framework/Versions/3.6/lib/python3.6/site-packages/urllib3/util/connection.py", line 60, in create_connection
    for res in socket.getaddrinfo(host, port, family, socket.SOCK_STREAM):
  File "/Library/Frameworks/Python.framework/Versions/3.6/lib/python3.6/socket.py", line 745, in getaddrinfo
    for res in _socket.getaddrinfo(host, port, family, type, proto, flags):
socket.gaierror: [Errno 8] nodename nor servname provided, or not known

During handling of the above exception, another exception occurred:

Traceback (most recent call last):
  File "/Library/Frameworks/Python.framework/Versions/3.6/lib/python3.6/site-packages/urllib3/connectionpool.py", line 601, in urlopen
    chunked=chunked)
  File "/Library/Frameworks/Python.framework/Versions/3.6/lib/python3.6/site-packages/urllib3/connectionpool.py", line 346, in _make_request
    self._validate_conn(conn)
  File "/Library/Frameworks/Python.framework/Versions/3.6/lib/python3.6/site-packages/urllib3/connectionpool.py", line 850, in _validate_conn
    conn.connect()
  File "/Library/Frameworks/Python.framework/Versions/3.6/lib/python3.6/site-packages/urllib3/connection.py", line 284, in connect
    conn = self._new_conn()
  File "/Library/Frameworks/Python.framework/Versions/3.6/lib/python3.6/site-packages/urllib3/connection.py", line 150, in _new_conn
    self, "Failed to establish a new connection: %s" % e)
urllib3.exceptions.NewConnectionError: <urllib3.connection.VerifiedHTTPSConnection object at 0x10f420d68>: Failed to establish a new connection: [Errno 8] nodename nor servname provided, or not known

During handling of the above exception, another exception occurred:

Traceback (most recent call last):
  File "/Library/Frameworks/Python.framework/Versions/3.6/lib/python3.6/site-packages/requests/adapters.py", line 440, in send
    timeout=timeout
  File "/Library/Frameworks/Python.framework/Versions/3.6/lib/python3.6/site-packages/urllib3/connectionpool.py", line 639, in urlopen
    _stacktrace=sys.exc_info()[2])
  File "/Library/Frameworks/Python.framework/Versions/3.6/lib/python3.6/site-packages/urllib3/util/retry.py", line 388, in increment
    raise MaxRetryError(_pool, url, error or ResponseError(cause))
urllib3.exceptions.MaxRetryError: HTTPSConnectionPool(host='api.dropboxapi.com', port=443): Max retries exceeded with url: /2/users/get_current_account (Caused by NewConnectionError('<urllib3.connection.VerifiedHTTPSConnection object at 0x10f420d68>: Failed to establish a new connection: [Errno 8] nodename nor servname provided, or not known',))

During handling of the above exception, another exception occurred:

Traceback (most recent call last):
  File "/Users/hepting/Sites/dhhepting.github.io/script/sharemedia.py", line 53, in <module>
    dbx.users_get_current_account()
  File "/Library/Frameworks/Python.framework/Versions/3.6/lib/python3.6/site-packages/dropbox/base.py", line 4301, in users_get_current_account
    None,
  File "/Library/Frameworks/Python.framework/Versions/3.6/lib/python3.6/site-packages/dropbox/dropbox.py", line 272, in request
    timeout=timeout)
  File "/Library/Frameworks/Python.framework/Versions/3.6/lib/python3.6/site-packages/dropbox/dropbox.py", line 363, in request_json_string_with_retry
    timeout=timeout)
  File "/Library/Frameworks/Python.framework/Versions/3.6/lib/python3.6/site-packages/dropbox/dropbox.py", line 447, in request_json_string
    timeout=timeout,
  File "/Library/Frameworks/Python.framework/Versions/3.6/lib/python3.6/site-packages/requests/sessions.py", line 555, in post
    return self.request('POST', url, data=data, json=json, **kwargs)
  File "/Library/Frameworks/Python.framework/Versions/3.6/lib/python3.6/site-packages/requests/sessions.py", line 508, in request
    resp = self.send(prep, **send_kwargs)
  File "/Library/Frameworks/Python.framework/Versions/3.6/lib/python3.6/site-packages/requests/sessions.py", line 618, in send
    r = adapter.send(request, **kwargs)
  File "/Library/Frameworks/Python.framework/Versions/3.6/lib/python3.6/site-packages/requests/adapters.py", line 508, in send
    raise ConnectionError(e, request=request)
requests.exceptions.ConnectionError: HTTPSConnectionPool(host='api.dropboxapi.com', port=443): Max retries exceeded with url: /2/users/get_current_account (Caused by NewConnectionError('<urllib3.connection.VerifiedHTTPSConnection object at 0x10f420d68>: Failed to establish a new connection: [Errno 8] nodename nor servname provided, or not known',))
2019-09-19 17:58:09.717123
Traceback (most recent call last):
  File "/Library/Frameworks/Python.framework/Versions/3.6/lib/python3.6/site-packages/urllib3/connection.py", line 141, in _new_conn
    (self.host, self.port), self.timeout, **extra_kw)
  File "/Library/Frameworks/Python.framework/Versions/3.6/lib/python3.6/site-packages/urllib3/util/connection.py", line 60, in create_connection
    for res in socket.getaddrinfo(host, port, family, socket.SOCK_STREAM):
  File "/Library/Frameworks/Python.framework/Versions/3.6/lib/python3.6/socket.py", line 745, in getaddrinfo
    for res in _socket.getaddrinfo(host, port, family, type, proto, flags):
socket.gaierror: [Errno 8] nodename nor servname provided, or not known

During handling of the above exception, another exception occurred:

Traceback (most recent call last):
  File "/Library/Frameworks/Python.framework/Versions/3.6/lib/python3.6/site-packages/urllib3/connectionpool.py", line 601, in urlopen
    chunked=chunked)
  File "/Library/Frameworks/Python.framework/Versions/3.6/lib/python3.6/site-packages/urllib3/connectionpool.py", line 346, in _make_request
    self._validate_conn(conn)
  File "/Library/Frameworks/Python.framework/Versions/3.6/lib/python3.6/site-packages/urllib3/connectionpool.py", line 850, in _validate_conn
    conn.connect()
  File "/Library/Frameworks/Python.framework/Versions/3.6/lib/python3.6/site-packages/urllib3/connection.py", line 284, in connect
    conn = self._new_conn()
  File "/Library/Frameworks/Python.framework/Versions/3.6/lib/python3.6/site-packages/urllib3/connection.py", line 150, in _new_conn
    self, "Failed to establish a new connection: %s" % e)
urllib3.exceptions.NewConnectionError: <urllib3.connection.VerifiedHTTPSConnection object at 0x10f531be0>: Failed to establish a new connection: [Errno 8] nodename nor servname provided, or not known

During handling of the above exception, another exception occurred:

Traceback (most recent call last):
  File "/Library/Frameworks/Python.framework/Versions/3.6/lib/python3.6/site-packages/requests/adapters.py", line 440, in send
    timeout=timeout
  File "/Library/Frameworks/Python.framework/Versions/3.6/lib/python3.6/site-packages/urllib3/connectionpool.py", line 639, in urlopen
    _stacktrace=sys.exc_info()[2])
  File "/Library/Frameworks/Python.framework/Versions/3.6/lib/python3.6/site-packages/urllib3/util/retry.py", line 388, in increment
    raise MaxRetryError(_pool, url, error or ResponseError(cause))
urllib3.exceptions.MaxRetryError: HTTPSConnectionPool(host='api.dropboxapi.com', port=443): Max retries exceeded with url: /2/users/get_current_account (Caused by NewConnectionError('<urllib3.connection.VerifiedHTTPSConnection object at 0x10f531be0>: Failed to establish a new connection: [Errno 8] nodename nor servname provided, or not known',))

During handling of the above exception, another exception occurred:

Traceback (most recent call last):
  File "/Users/hepting/Sites/dhhepting.github.io/script/sharemedia.py", line 53, in <module>
    dbx.users_get_current_account()
  File "/Library/Frameworks/Python.framework/Versions/3.6/lib/python3.6/site-packages/dropbox/base.py", line 4301, in users_get_current_account
    None,
  File "/Library/Frameworks/Python.framework/Versions/3.6/lib/python3.6/site-packages/dropbox/dropbox.py", line 272, in request
    timeout=timeout)
  File "/Library/Frameworks/Python.framework/Versions/3.6/lib/python3.6/site-packages/dropbox/dropbox.py", line 363, in request_json_string_with_retry
    timeout=timeout)
  File "/Library/Frameworks/Python.framework/Versions/3.6/lib/python3.6/site-packages/dropbox/dropbox.py", line 447, in request_json_string
    timeout=timeout,
  File "/Library/Frameworks/Python.framework/Versions/3.6/lib/python3.6/site-packages/requests/sessions.py", line 555, in post
    return self.request('POST', url, data=data, json=json, **kwargs)
  File "/Library/Frameworks/Python.framework/Versions/3.6/lib/python3.6/site-packages/requests/sessions.py", line 508, in request
    resp = self.send(prep, **send_kwargs)
  File "/Library/Frameworks/Python.framework/Versions/3.6/lib/python3.6/site-packages/requests/sessions.py", line 618, in send
    r = adapter.send(request, **kwargs)
  File "/Library/Frameworks/Python.framework/Versions/3.6/lib/python3.6/site-packages/requests/adapters.py", line 508, in send
    raise ConnectionError(e, request=request)
requests.exceptions.ConnectionError: HTTPSConnectionPool(host='api.dropboxapi.com', port=443): Max retries exceeded with url: /2/users/get_current_account (Caused by NewConnectionError('<urllib3.connection.VerifiedHTTPSConnection object at 0x10f531be0>: Failed to establish a new connection: [Errno 8] nodename nor servname provided, or not known',))
2019-09-19 22:35:17.955727
2019-09-20 15:00:06.580491
2019-09-26 15:49:05.062057
2019-09-26 18:03:47.671747
2019-09-26 18:10:26.439285
2019-09-26 18:18:34.012607
2019-09-26 18:19:22.571807
2019-09-27 15:00:08.964311
2019-09-28 16:00:47.245202
2019-09-29 16:41:49.335324
2019-09-30 15:00:13.550958
2019-10-01 15:00:08.345073
2019-10-01 17:53:24.529131
2019-10-01 17:55:10.674238
2019-10-01 17:57:19.016834
2019-10-02 15:00:10.899294
2019-10-03 15:00:16.750921
2019-10-04 14:06:35.092806
2019-10-04 14:16:06.366920
2019-10-04 15:00:06.019382
2019-10-05 23:27:45.010158
2019-10-06 15:00:08.351950
2019-10-07 15:00:15.213477
2019-10-08 15:00:06.859631
2019-10-08 18:28:09.492304
2019-10-09 15:00:09.908266
2019-10-10 15:00:14.794692
2019-10-10 17:54:30.100872
2019-10-10 18:00:23.908435
2019-10-10 18:01:29.220702
2019-10-11 15:00:08.201312
2019-10-12 17:11:29.927359
2019-10-13 15:00:23.894357
2019-10-14 15:00:10.556707
2019-10-15 15:00:13.190067
2019-10-16 00:22:05.235334
2019-10-16 15:00:12.837102
